<mujoco model="template">
  <!-- This model has been converted from an OpenSim model. Model conversion by MyoConverter https://github.com/MyoHub/myoconverter. This model is licensed under Apache 2.0. -->
  <!-- Credits from the original OpenSim model. Note! If the following has any license information, it applies to the original OpenSim model. Credits: Katherine R. Saul, Wendy M. Murray, Craig M. Goehler, Melissa Daly, Meghan E. Vidt, Dustin L. Crouch -->
  <!-- Note: inertiagrouprange="0 1" means that groups 0-1 will be used to infer masses/inertias, and groups 2-5 are
  only for visualisation (e.g. wrapping objects) !-->
  <compiler inertiafromgeom="auto" angle="radian" balanceinertia="true" boundmass="0.001" boundinertia="0.001" inertiagrouprange="0 1">
    <lengthrange inttotal="50" useexisting="true"/>
  </compiler>
  <option collision="predefined"/>
  <visual>
    <scale framelength="0.5" framewidth="0.01"/>
  </visual>
  <default>
    <joint limited="true" damping="0.05" armature="0.00001" stiffness="0"/>
    <geom rgba="0.8 0.6 .4 1" margin="0.001"/>
    <site size="0.001"/>
    <tendon width="0.005" rgba=".95 .3 .3 1" limited="false"/>
    <default class="muscle">
      <muscle ctrllimited="true" ctrlrange="0 1" scale="200"/>
    </default>
    <default class="motor">
      <general gainprm="5 0 0 0 0 0 0 0 0 0" ctrllimited="true" ctrlrange="-1 1"/>
    </default>
  </default>
  <option timestep="0.002"/>
  <!-- nuser_jnt=1, the parameter is used to store default value of the joint, and nkey=1 to store keyframe with
   default joint positions set !-->
  <size njmax="1000" nconmax="400" nuser_jnt="1" nkey="1"/>
  <worldbody>
    <camera name="for_testing" pos="-0.8 -0.6 1.5" euler="0.7 -1.0 -0.7"/>
    <!-- The converter script assumes a body named 'ground' exists as a child element of worldbody -->
    <body name="ground" euler="1.571 0 0"/>
    <light directional="true"/>
    <body name="thorax" pos="0 0 0" euler="1.571 0 0">
      <geom name="spine" type="mesh" mesh="spine" rgba="1 1 1 1"/>
      <body name="skull">
        <geom name="skull" type="mesh" mesh="skull" rgba="1 1 1 1"/>
      </body>
      <geom name="thorax_geom_1" type="mesh" mesh="thorax_geom_1_thorax" rgba="1 1 1 1" group="0"/>
      <joint name="t_x" range="-100 100" limited="true" user="0.0" ref="0" axis="1 0 0" type="slide" damping="0" stiffness="0"/>
      <joint name="t_y" range="-100 100" limited="true" user="0.0" ref="0" axis="0 1 0" type="slide" damping="0" stiffness="0"/>
      <joint name="t_z" range="-100 100" limited="true" user="0.0" ref="0" axis="0 0 1" type="slide" damping="0" stiffness="0"/>
      <joint name="r_x" range="-6.283 6.283" limited="true" user="0.0" ref="0" axis="1 0 0" type="hinge" damping="0" stiffness="0"/>
      <joint name="r_y" range="-6.283 6.283" limited="true" user="-1.57079632296891" ref="0" axis="0 1 0" type="hinge" damping="0" stiffness="0"/>
      <joint name="r_z" range="-6.283 6.283" limited="true" user="0.0" ref="0" axis="0 0 1" type="hinge" damping="0" stiffness="0"/>
      <body name="clavicle_r" pos="0.006325 0.00693 0.02547" euler="0 0 0">
        <inertial mass="0.156" pos="-0.011096 0.0063723 0.054168000000000001" fullinertia="0.00024258999999999999 0.00025525999999999999 4.4419999999999998e-05 -1.8980000000000001e-05 -6.9939999999999998e-05 5.3709999999999999e-05"/>
        <geom name="clavicle_r_geom_1" type="mesh" mesh="clavicle_r_geom_1_clavicle" rgba="1 1 1 1" group="0"/>
        <joint name="sternoclavicular_r2_r" range="-1e+05 1e+05" limited="false" user="-0.126711188972822" ref="0" axis="0.0153 0.9893 -0.1451" type="hinge"/>
        <joint name="sternoclavicular_r3_r" range="-1e+05 1e+05" limited="false" user="0.0536688792066323" ref="0" axis="-0.9945 0 -0.105" type="hinge"/>
        <body name="clavphant_r" pos="-0.01433 0.02007 0.1355" euler="0 0 0">
          <inertial mass="0.0001" pos="0 0 0" fullinertia="1 1 1 0 0 0"/>
          <joint name="unrotscap_r3_r" range="-1e+05 1e+05" limited="false" user="-0.0536688792066323" ref="0" axis="-0.9945 0 -0.105" type="hinge"/>
          <joint name="unrotscap_r2_r" range="-1e+05 1e+05" limited="false" user="0.126711188972822" ref="0" axis="0.0153 0.9893 -0.1451" type="hinge"/>
          <body name="scapula_r" pos="0 0 0" euler="0 0 0">
            <inertial mass="0.70396000000000003" pos="-0.054694 -0.035032000000000001 -0.043734000000000002" fullinertia="0.0012428999999999999 0.0011504 0.0013651 0.00044939999999999997 0.00040922000000000002 0.00024110000000000001"/>
            <geom name="scapula_r_geom_1" type="mesh" mesh="scapula_r_geom_1_scapula" rgba="1 1 1 1" group="0"/>
            <joint name="acromioclavicular_r2_r" range="-1e+05 1e+05" limited="false" user="-0.0256564382631524" ref="0" axis="0.1571 0.9473 -0.2793" type="hinge"/>
            <joint name="acromioclavicular_r3_r" range="-1e+05 1e+05" limited="false" user="0.207346309229339" ref="0" axis="-0.7541 0.2976 0.5855" type="hinge"/>
            <joint name="acromioclavicular_r1_r" range="-1e+05 1e+05" limited="false" user="0.0932007389964595" ref="0" axis="0.6377 0.1186 0.7611" type="hinge"/>
            <body name="scapphant_r" pos="-0.00955 -0.034 0.009" euler="0 0 0">
              <inertial mass="0.0001" pos="0 0 0" fullinertia="1 1 1 0 0 0"/>
              <joint name="unrothum_r1_r" range="-1e+05 1e+05" limited="false" user="-0.0932007389964595" ref="0" axis="0.6377 0.1186 0.7611" type="hinge"/>
              <joint name="unrothum_r3_r" range="-1e+05 1e+05" limited="false" user="-0.207346309229339" ref="0" axis="-0.7541 0.2976 0.5855" type="hinge"/>
              <joint name="unrothum_r2_r" range="-1e+05 1e+05" limited="false" user="0.0256564382631524" ref="0" axis="0.1571 0.9473 -0.2793" type="hinge"/>
              <body name="humphant_r" pos="0 0 0" euler="0 0 0">
                <inertial mass="0.0001" pos="0 0 0" fullinertia="1 1 1 0 0 0"/>
                <joint name="elv_angle_r" range="-1.658 2.269" limited="true" user="4.65570314106046e-09" ref="0" axis="0.0048 0.9991 0.0424" type="hinge"/>
                <body name="humphant1_r" pos="0 0 0" euler="0 0 0">
                  <inertial mass="0.0001" pos="0 0 0" fullinertia="1 1 1 0 0 0"/>
                  <joint name="shoulder_elv_r" range="0 3.142" limited="true" user="0.523598780877679" ref="0" axis="-0.9983 0.0023 0.0589" type="hinge"/>
                  <joint name="shoulder1_r2_r" range="-1e+05 1e+05" limited="false" user="-4.65570310990575e-09" ref="0" axis="0.0048 0.9991 0.0424" type="hinge"/>
                  <body name="humerus_r" pos="0 0 0" euler="0 0 0">
                    <inertial mass="1.9975700000000001" pos="0.018064 -0.14014099999999999 -0.012746" fullinertia="0.0122776 0.0025513300000000001 0.0125789 -0.00034740999999999998 -0.00023250000000000001 0.0012293"/>
                    <geom name="humerus_r_geom_1" type="mesh" mesh="humerus_r_geom_1_humerus" rgba="1 1 1 1" group="0"/>
                    <joint name="shoulder_rot_r" range="-1.571 2.094" limited="true" user="-2.21205399850711e-09" ref="0" axis="0.0048 0.9991 0.0424" type="hinge"/>
                    <body name="ulna_r" pos="0.0061 -0.2904 -0.0123" euler="0 0 0">
                      <inertial mass="1.1052999999999999" pos="0.0097178300000000002 -0.095950900000000006 0.024285999999999999" fullinertia="0.0054130899999999997 0.00115318 0.0049436100000000002 0.00031686000000000003 -7.6149999999999994e-05 0.00109169"/>
                      <geom name="ulna_r_geom_1" type="mesh" mesh="ulna_r_geom_1_ulna" rgba="1 1 1 1" group="0"/>
                      <joint name="elbow_flexion_r" range="0 2.269" limited="true" user="1.57079632559557" ref="0" axis="0.0494 0.0366 0.9981" type="hinge"/>
                      <body name="radius_r" pos="0.0004 -0.0115 0.02" euler="0 0 0">
                        <inertial mass="0.23358999999999999" pos="0.0336341 -0.181559 0.015599999999999999" fullinertia="0.00043855000000000001 8.8590000000000004e-05 0.00040257999999999998 3.0139999999999999e-05 -4.2400000000000001e-06 6.4179999999999999e-05"/>
                        <geom name="radius_r_geom_1" type="mesh" mesh="radius_r_geom_1_radius" rgba="1 1 1 1" group="0"/>
                        <joint name="pro_sup_r" range="-1.571 1.571" limited="true" user="-1.99999999326384e-08" ref="0" axis="-0.01716 0.9927 -0.1197" type="hinge"/>
                        <body name="proximal_row_r" pos="0.018 -0.242 0.025" euler="0 0 0">
                          <inertial mass="0.0001" pos="0 0 0" fullinertia="1.0000000000000001e-05 1.0000000000000001e-05 1.0000000000000001e-05 0 0 0"/>
                          <geom name="proximal_row_r_geom_1" type="mesh" mesh="proximal_row_r_geom_1_lunate" rgba="1 1 1 1" group="0"/>
                          <geom name="proximal_row_r_geom_2" type="mesh" mesh="proximal_row_r_geom_2_sdfastSCAPHOIDw" rgba="1 1 1 1" group="0"/>
                          <geom name="proximal_row_r_geom_3" type="mesh" mesh="proximal_row_r_geom_3_sdfastPISIFORMw" rgba="1 1 1 1" group="0"/>
                          <geom name="proximal_row_r_geom_4" type="mesh" mesh="proximal_row_r_geom_4_sdfastTRIQUETRALw" rgba="1 1 1 1" group="0"/>
                          <joint name="deviation_r" range="-0.1745 0.4363" limited="true" user="3.5146665577912017e-09" ref="0" axis="-0.8191 -0.1356 -0.5574" type="hinge"/>
                          <joint name="flexion_r" range="-0.6109 0.6109" limited="true" user="0.0" ref="0" axis="0.9564 -0.2522 0.1471" type="hinge"/>
                          <body name="hand_r" pos="0.003992 -0.01505 0.002327" euler="0 0 0">
                            <inertial mass="0.58189999999999997" pos="-0.0030131400000000001 -0.042499299999999997 -0.0011220500000000001" fullinertia="0.00011 6.0000000000000002e-05 0.00014999999999999999 8.9999999999999996e-07 -1.9999999999999999e-07 1.2e-05"/>
                            <geom name="hand_r_geom_1" type="mesh" mesh="hand_r_geom_1_sdfast_1seg_hand_fr_c_5mc" rgba="1 1 1 1" group="0"/>
                            <geom name="hand_r_geom_2" type="mesh" mesh="hand_r_geom_2_sdfast_1seg_hand_fr_c_4mc" rgba="1 1 1 1" group="0"/>
                            <geom name="hand_r_geom_3" type="mesh" mesh="hand_r_geom_3_sdfast_1seg_hand_fr_c_3mc" rgba="1 1 1 1" group="0"/>
                            <geom name="hand_r_geom_4" type="mesh" mesh="hand_r_geom_4_sdfast_1seg_hand_fr_c_2mc" rgba="1 1 1 1" group="0"/>
                            <geom name="hand_r_geom_5" type="mesh" mesh="hand_r_geom_5_sdfast_1seg_hand_fr_c_trapezium" rgba="1 1 1 1" group="0"/>
                            <geom name="hand_r_geom_6" type="mesh" mesh="hand_r_geom_6_sdfast_1seg_hand_fr_c_trapezoid" rgba="1 1 1 1" group="0"/>
                            <geom name="hand_r_geom_7" type="mesh" mesh="hand_r_geom_7_sdfast_1seg_hand_fr_c_hamate" rgba="1 1 1 1" group="0"/>
                            <geom name="hand_r_geom_8" type="mesh" mesh="hand_r_geom_8_capitate" rgba="1 1 1 1" group="0"/>
                            <geom name="hand_r_geom_9" type="mesh" mesh="hand_r_geom_9_hand_2proxph" rgba="1 1 1 1" group="0"/>
                            <geom name="hand_r_geom_10" type="mesh" mesh="hand_r_geom_10_hand_2midph" rgba="1 1 1 1" group="0"/>
                            <geom name="hand_r_geom_11" type="mesh" mesh="hand_r_geom_11_hand_2distph" rgba="1 1 1 1" group="0"/>
                            <geom name="hand_r_geom_12" type="mesh" mesh="hand_r_geom_12_hand_3proxph" rgba="1 1 1 1" group="0"/>
                            <geom name="hand_r_geom_13" type="mesh" mesh="hand_r_geom_13_hand_3midph" rgba="1 1 1 1" group="0"/>
                            <geom name="hand_r_geom_14" type="mesh" mesh="hand_r_geom_14_hand_3distph" rgba="1 1 1 1" group="0"/>
                            <geom name="hand_r_geom_15" type="mesh" mesh="hand_r_geom_15_hand_4proxph" rgba="1 1 1 1" group="0"/>
                            <geom name="hand_r_geom_16" type="mesh" mesh="hand_r_geom_16_hand_4midph" rgba="1 1 1 1" group="0"/>
                            <geom name="hand_r_geom_17" type="mesh" mesh="hand_r_geom_17_hand_4distph" rgba="1 1 1 1" group="0"/>
                            <geom name="hand_r_geom_18" type="mesh" mesh="hand_r_geom_18_hand_5proxph" rgba="1 1 1 1" group="0"/>
                            <geom name="hand_r_geom_19" type="mesh" mesh="hand_r_geom_19_hand_5midph" rgba="1 1 1 1" group="0"/>
                            <geom name="hand_r_geom_20" type="mesh" mesh="hand_r_geom_20_hand_5distph" rgba="1 1 1 1" group="0"/>
                            <geom name="hand_r_geom_21" type="mesh" mesh="hand_r_geom_21_hand_thumbprox" rgba="1 1 1 1" group="0"/>
                            <geom name="hand_r_geom_22" type="mesh" mesh="hand_r_geom_22_hand_thumbdist" rgba="1 1 1 1" group="0"/>
                            <geom name="hand_r_geom_23" type="mesh" mesh="hand_r_geom_23_hand_1mc" rgba="1 1 1 1" group="0"/>
                            <joint name="wrist_hand_r1_r" range="-1e+05 1e+05" limited="false" user="4.76989745985007e-09" ref="0" axis="0.8991 -0.3491 -0.264" type="hinge"/>
                            <joint name="wrist_hand_r3_r" range="-1e+05 1e+05" limited="false" user="0.0" ref="0" axis="0.9971 0.0107 -0.0751" type="hinge"/>
                          </body>
                        </body>
                      </body>
                    </body>
                  </body>
                </body>
              </body>
            </body>
          </body>
        </body>
      </body>
      <body name="clavicle_l" pos="0.006325 0.00693 -0.02547" euler="0 0 0">
        <inertial mass="0.156" pos="-0.011096 0.0063723 -0.054168000000000001" fullinertia="0.00024258999999999999 0.00025525999999999999 4.4419999999999998e-05 -1.8980000000000001e-05 -6.9939999999999998e-05 5.3709999999999999e-05"/>
        <geom name="clavicle_l_geom_1" type="mesh" mesh="clavicle_l_geom_1_clavicle_mirror" rgba="1 1 1 1" group="0"/>
        <joint name="sternoclavicular_r2_l" range="-1e+05 1e+05" limited="false" user="-0.126711188970192" ref="0" axis="-0.0153 -0.9893 -0.1451" type="hinge"/>
        <joint name="sternoclavicular_r3_l" range="-1e+05 1e+05" limited="false" user="0.0536688792055186" ref="0" axis="0.9945 0 -0.105" type="hinge"/>
        <body name="clavphant_l" pos="-0.01433 0.02007 -0.1355" euler="0 0 0">
          <inertial mass="0.0001" pos="0 0 0" fullinertia="1 1 1 0 0 0"/>
          <joint name="unrotscap_r3_l" range="-1e+05 1e+05" limited="false" user="-0.0536688792055186" ref="0" axis="0.9945 0 -0.105" type="hinge"/>
          <joint name="unrotscap_r2_l" range="-1e+05 1e+05" limited="false" user="0.126711188970192" ref="0" axis="-0.0153 -0.9893 -0.1451" type="hinge"/>
          <body name="scapula_l" pos="0 0 0" euler="0 0 0">
            <inertial mass="0.70396000000000003" pos="-0.054694 -0.035032000000000001 0.043734000000000002" fullinertia="0.0012428999999999999 0.0011504 0.0013651 0.00044939999999999997 0.00040922000000000002 0.00024110000000000001"/>
            <geom name="scapula_l_geom_1" type="mesh" mesh="scapula_l_geom_1_scapula_mirror" rgba="1 1 1 1" group="0"/>
            <joint name="acromioclavicular_r2_l" range="-1e+05 1e+05" limited="false" user="-0.02565643826262" ref="0" axis="-0.1571 -0.9473 -0.2793" type="hinge"/>
            <joint name="acromioclavicular_r3_l" range="-1e+05 1e+05" limited="false" user="0.207346309225036" ref="0" axis="0.7541 -0.2976 0.5855" type="hinge"/>
            <joint name="acromioclavicular_r1_l" range="-1e+05 1e+05" limited="false" user="0.0932007389945255" ref="0" axis="-0.6377 -0.1186 0.7611" type="hinge"/>
            <body name="scapphant_l" pos="-0.00955 -0.034 -0.009" euler="0 0 0">
              <inertial mass="0.0001" pos="0 0 0" fullinertia="1 1 1 0 0 0"/>
              <joint name="unrothum_r1_l" range="-1e+05 1e+05" limited="false" user="-0.0932007389945255" ref="0" axis="-0.6377 -0.1186 0.7611" type="hinge"/>
              <joint name="unrothum_r3_l" range="-1e+05 1e+05" limited="false" user="-0.207346309225036" ref="0" axis="0.7541 -0.2976 0.5855" type="hinge"/>
              <joint name="unrothum_r2_l" range="-1e+05 1e+05" limited="false" user="0.02565643826262" ref="0" axis="-0.1571 -0.9473 -0.2793" type="hinge"/>
              <body name="humphant_l" pos="0 0 0" euler="0 0 0">
                <inertial mass="0.0001" pos="0 0 0" fullinertia="1 1 1 0 0 0"/>
                <joint name="elv_angle_l" range="-1.658 2.269" limited="true" user="3.57241152108492e-09" ref="0" axis="-0.0048 -0.9991 0.0424" type="hinge"/>
                <body name="humphant1_l" pos="0 0 0" euler="0 0 0">
                  <inertial mass="0.0001" pos="0 0 0" fullinertia="1 1 1 0 0 0"/>
                  <joint name="shoulder_elv_l" range="0 3.142" limited="true" user="0.523598780866814" ref="0" axis="0.9983 -0.0023 0.0589" type="hinge"/>
                  <joint name="shoulder1_r2_l" range="-1e+05 1e+05" limited="false" user="-3.57241154683428e-09" ref="0" axis="-0.0048 -0.9991 0.0424" type="hinge"/>
                  <body name="humerus_l" pos="0 0 0" euler="0 0 0">
                    <inertial mass="1.9975700000000001" pos="0.018064 -0.14014099999999999 0.012746" fullinertia="0.0122776 0.0025513300000000001 0.0125789 -0.00034740999999999998 -0.00023250000000000001 0.0012293"/>
                    <geom name="humerus_l_geom_1" type="mesh" mesh="humerus_l_geom_1_humerus_mirror" rgba="1 1 1 1" group="0"/>
                    <joint name="shoulder_rot_l" range="-1.571 2.094" limited="true" user="-2.38097812151041e-09" ref="0" axis="-0.0048 -0.9991 0.0424" type="hinge"/>
                    <body name="ulna_l" pos="0.0061 -0.2904 0.0123" euler="0 0 0">
                      <inertial mass="1.1052999999999999" pos="0.0097178300000000002 -0.095950900000000006 -0.024285999999999999" fullinertia="0.0054130899999999997 0.00115318 0.0049436100000000002 0.00031686000000000003 -7.6149999999999994e-05 0.00109169"/>
                      <geom name="ulna_l_geom_1" type="mesh" mesh="ulna_l_geom_1_ulna_mirror" rgba="1 1 1 1" group="0"/>
                      <joint name="elbow_flexion_l" range="0 2.269" limited="true" user="1.57079632679492" ref="0" axis="-0.0494 -0.0366 0.9981" type="hinge"/>
                      <body name="radius_l" pos="0.0004 -0.0115 -0.02" euler="0 0 0">
                        <inertial mass="0.23358999999999999" pos="0.0336341 -0.181559 -0.015599999999999999" fullinertia="0.00043855000000000001 8.8590000000000004e-05 0.00040257999999999998 3.0139999999999999e-05 -4.2400000000000001e-06 6.4179999999999999e-05"/>
                        <geom name="radius_l_geom_1" type="mesh" mesh="radius_l_geom_1_radius_mirror" rgba="1 1 1 1" group="0"/>
                        <joint name="pro_sup_l" range="-1.571 1.571" limited="true" user="-2e-08" ref="0" axis="0.01716 -0.9927 -0.1197" type="hinge"/>
                        <body name="proximal_row_l" pos="0.018 -0.242 -0.025" euler="0 0 0">
                          <inertial mass="0.0001" pos="0 0 0" fullinertia="1.0000000000000001e-05 1.0000000000000001e-05 1.0000000000000001e-05 0 0 0"/>
                          <geom name="proximal_row_l_geom_1" type="mesh" mesh="proximal_row_l_geom_1_lunate_mirror" rgba="1 1 1 1" group="0"/>
                          <geom name="proximal_row_l_geom_2" type="mesh" mesh="proximal_row_l_geom_2_sdfastSCAPHOIDw_mirror" rgba="1 1 1 1" group="0"/>
                          <geom name="proximal_row_l_geom_3" type="mesh" mesh="proximal_row_l_geom_3_sdfastPISIFORMw_mirror" rgba="1 1 1 1" group="0"/>
                          <geom name="proximal_row_l_geom_4" type="mesh" mesh="proximal_row_l_geom_4_sdfastTRIQUETRALw_mirror" rgba="1 1 1 1" group="0"/>
                          <joint name="deviation_l" range="-0.1745 0.4363" limited="true" user="-5.551115123125783e-17" ref="0" axis="0.8191 0.1356 -0.5574" type="hinge"/>
                          <joint name="flexion_l" range="-0.6109 0.6109" limited="true" user="0.0" ref="0" axis="-0.9564 0.2522 0.1471" type="hinge"/>
                          <body name="hand_l" pos="0.003992 -0.01505 -0.002327" euler="0 0 0">
                            <inertial mass="0.58189999999999997" pos="-0.0030131400000000001 -0.042499299999999997 0.0011220500000000001" fullinertia="0.00011 6.0000000000000002e-05 0.00014999999999999999 8.9999999999999996e-07 -1.9999999999999999e-07 1.2e-05"/>
                            <geom name="hand_l_geom_1" type="mesh" mesh="hand_l_geom_1_sdfast_1seg_hand_fr_c_5mc_mirror" rgba="1 1 1 1" group="0"/>
                            <geom name="hand_l_geom_2" type="mesh" mesh="hand_l_geom_2_sdfast_1seg_hand_fr_c_4mc_mirror" rgba="1 1 1 1" group="0"/>
                            <geom name="hand_l_geom_3" type="mesh" mesh="hand_l_geom_3_sdfast_1seg_hand_fr_c_3mc_mirror" rgba="1 1 1 1" group="0"/>
                            <geom name="hand_l_geom_4" type="mesh" mesh="hand_l_geom_4_sdfast_1seg_hand_fr_c_2mc_mirror" rgba="1 1 1 1" group="0"/>
                            <geom name="hand_l_geom_5" type="mesh" mesh="hand_l_geom_5_sdfast_1seg_hand_fr_c_trapezium_mirror" rgba="1 1 1 1" group="0"/>
                            <geom name="hand_l_geom_6" type="mesh" mesh="hand_l_geom_6_sdfast_1seg_hand_fr_c_trapezoid_mirror" rgba="1 1 1 1" group="0"/>
                            <geom name="hand_l_geom_7" type="mesh" mesh="hand_l_geom_7_sdfast_1seg_hand_fr_c_hamate_mirror" rgba="1 1 1 1" group="0"/>
                            <geom name="hand_l_geom_8" type="mesh" mesh="hand_l_geom_8_capitate_mirror" rgba="1 1 1 1" group="0"/>
                            <geom name="hand_l_geom_9" type="mesh" mesh="hand_l_geom_9_hand_2proxph_mirror" rgba="1 1 1 1" group="0"/>
                            <geom name="hand_l_geom_10" type="mesh" mesh="hand_l_geom_10_hand_2midph_mirror" rgba="1 1 1 1" group="0"/>
                            <geom name="hand_l_geom_11" type="mesh" mesh="hand_l_geom_11_hand_2distph_mirror" rgba="1 1 1 1" group="0"/>
                            <geom name="hand_l_geom_12" type="mesh" mesh="hand_l_geom_12_hand_3proxph_mirror" rgba="1 1 1 1" group="0"/>
                            <geom name="hand_l_geom_13" type="mesh" mesh="hand_l_geom_13_hand_3midph_mirror" rgba="1 1 1 1" group="0"/>
                            <geom name="hand_l_geom_14" type="mesh" mesh="hand_l_geom_14_hand_3distph_mirror" rgba="1 1 1 1" group="0"/>
                            <geom name="hand_l_geom_15" type="mesh" mesh="hand_l_geom_15_hand_4proxph_mirror" rgba="1 1 1 1" group="0"/>
                            <geom name="hand_l_geom_16" type="mesh" mesh="hand_l_geom_16_hand_4midph_mirror" rgba="1 1 1 1" group="0"/>
                            <geom name="hand_l_geom_17" type="mesh" mesh="hand_l_geom_17_hand_4distph_mirror" rgba="1 1 1 1" group="0"/>
                            <geom name="hand_l_geom_18" type="mesh" mesh="hand_l_geom_18_hand_5proxph_mirror" rgba="1 1 1 1" group="0"/>
                            <geom name="hand_l_geom_19" type="mesh" mesh="hand_l_geom_19_hand_5midph_mirror" rgba="1 1 1 1" group="0"/>
                            <geom name="hand_l_geom_20" type="mesh" mesh="hand_l_geom_20_hand_5distph_mirror" rgba="1 1 1 1" group="0"/>
                            <geom name="hand_l_geom_21" type="mesh" mesh="hand_l_geom_21_hand_thumbprox_mirror" rgba="1 1 1 1" group="0"/>
                            <geom name="hand_l_geom_22" type="mesh" mesh="hand_l_geom_22_hand_thumbdist_mirror" rgba="1 1 1 1" group="0"/>
                            <geom name="hand_l_geom_23" type="mesh" mesh="hand_l_geom_23_hand_1mc_mirror" rgba="1 1 1 1" group="0"/>
                            <joint name="wrist_hand_r1_l" range="-1e+05 1e+05" limited="false" user="0.0" ref="0" axis="-0.8991 0.3491 -0.264" type="hinge"/>
                            <joint name="wrist_hand_r3_l" range="-1e+05 1e+05" limited="false" user="0.0" ref="0" axis="-0.9971 -0.0107 -0.0751" type="hinge"/>
                          </body>
                        </body>
                      </body>
                    </body>
                  </body>
                </body>
              </body>
            </body>
          </body>
        </body>
      </body>
    </body>
  </worldbody>
  <asset>
    <texture type="skybox" builtin="gradient" rgb1="1 1 1" rgb2="0.6 0.8 1" width="256" height="256"/>
    <mesh name="skull" file="assets/skull.stl" />
    <mesh name="spine" file="assets/spine.stl" />
    <mesh name="thorax_geom_1_thorax" file="assets/thorax.stl" scale="1 1 1"/>
    <mesh name="clavicle_r_geom_1_clavicle" file="assets/clavicle.stl" scale="1 1 1"/>
    <mesh name="scapula_r_geom_1_scapula" file="assets/scapula.stl" scale="1 1 1"/>
    <mesh name="humerus_r_geom_1_humerus" file="assets/humerus.stl" scale="1 1 1"/>
    <mesh name="ulna_r_geom_1_ulna" file="assets/ulna.stl" scale="1 1 1"/>
    <mesh name="radius_r_geom_1_radius" file="assets/radius.stl" scale="1 1 1"/>
    <mesh name="proximal_row_r_geom_1_lunate" file="assets/lunate.stl" scale="1 1 1"/>
    <mesh name="proximal_row_r_geom_2_sdfastSCAPHOIDw" file="assets/sdfastSCAPHOIDw.stl" scale="1 1 1"/>
    <mesh name="proximal_row_r_geom_3_sdfastPISIFORMw" file="assets/sdfastPISIFORMw.stl" scale="1 1 1"/>
    <mesh name="proximal_row_r_geom_4_sdfastTRIQUETRALw" file="assets/sdfastTRIQUETRALw.stl" scale="1 1 1"/>
    <mesh name="hand_r_geom_1_sdfast_1seg_hand_fr_c_5mc" file="assets/sdfast_1seg_hand_fr_c_5mc.stl" scale="1 1 1"/>
    <mesh name="hand_r_geom_2_sdfast_1seg_hand_fr_c_4mc" file="assets/sdfast_1seg_hand_fr_c_4mc.stl" scale="1 1 1"/>
    <mesh name="hand_r_geom_3_sdfast_1seg_hand_fr_c_3mc" file="assets/sdfast_1seg_hand_fr_c_3mc.stl" scale="1 1 1"/>
    <mesh name="hand_r_geom_4_sdfast_1seg_hand_fr_c_2mc" file="assets/sdfast_1seg_hand_fr_c_2mc.stl" scale="1 1 1"/>
    <mesh name="hand_r_geom_5_sdfast_1seg_hand_fr_c_trapezium" file="assets/sdfast_1seg_hand_fr_c_trapezium.stl" scale="1 1 1"/>
    <mesh name="hand_r_geom_6_sdfast_1seg_hand_fr_c_trapezoid" file="assets/sdfast_1seg_hand_fr_c_trapezoid.stl" scale="1 1 1"/>
    <mesh name="hand_r_geom_7_sdfast_1seg_hand_fr_c_hamate" file="assets/sdfast_1seg_hand_fr_c_hamate.stl" scale="1 1 1"/>
    <mesh name="hand_r_geom_8_capitate" file="assets/capitate.stl" scale="1 1 1"/>
    <mesh name="hand_r_geom_9_hand_2proxph" file="assets/hand_2proxph.stl" scale="1 1 1"/>
    <mesh name="hand_r_geom_10_hand_2midph" file="assets/hand_2midph.stl" scale="1 1 1"/>
    <mesh name="hand_r_geom_11_hand_2distph" file="assets/hand_2distph.stl" scale="1 1 1"/>
    <mesh name="hand_r_geom_12_hand_3proxph" file="assets/hand_3proxph.stl" scale="1 1 1"/>
    <mesh name="hand_r_geom_13_hand_3midph" file="assets/hand_3midph.stl" scale="1 1 1"/>
    <mesh name="hand_r_geom_14_hand_3distph" file="assets/hand_3distph.stl" scale="1 1 1"/>
    <mesh name="hand_r_geom_15_hand_4proxph" file="assets/hand_4proxph.stl" scale="1 1 1"/>
    <mesh name="hand_r_geom_16_hand_4midph" file="assets/hand_4midph.stl" scale="1 1 1"/>
    <mesh name="hand_r_geom_17_hand_4distph" file="assets/hand_4distph.stl" scale="1 1 1"/>
    <mesh name="hand_r_geom_18_hand_5proxph" file="assets/hand_5proxph.stl" scale="1 1 1"/>
    <mesh name="hand_r_geom_19_hand_5midph" file="assets/hand_5midph.stl" scale="1 1 1"/>
    <mesh name="hand_r_geom_20_hand_5distph" file="assets/hand_5distph.stl" scale="1 1 1"/>
    <mesh name="hand_r_geom_21_hand_thumbprox" file="assets/hand_thumbprox.stl" scale="1 1 1"/>
    <mesh name="hand_r_geom_22_hand_thumbdist" file="assets/hand_thumbdist.stl" scale="1 1 1"/>
    <mesh name="hand_r_geom_23_hand_1mc" file="assets/hand_1mc.stl" scale="1 1 1"/>
    <mesh name="clavicle_l_geom_1_clavicle_mirror" file="assets/clavicle_mirror.stl" scale="1 1 1"/>
    <mesh name="scapula_l_geom_1_scapula_mirror" file="assets/scapula_mirror.stl" scale="1 1 1"/>
    <mesh name="humerus_l_geom_1_humerus_mirror" file="assets/humerus_mirror.stl" scale="1 1 1"/>
    <mesh name="ulna_l_geom_1_ulna_mirror" file="assets/ulna_mirror.stl" scale="1 1 1"/>
    <mesh name="radius_l_geom_1_radius_mirror" file="assets/radius_mirror.stl" scale="1 1 1"/>
    <mesh name="proximal_row_l_geom_1_lunate_mirror" file="assets/lunate_mirror.stl" scale="1 1 1"/>
    <mesh name="proximal_row_l_geom_2_sdfastSCAPHOIDw_mirror" file="assets/sdfastSCAPHOIDw_mirror.stl" scale="1 1 1"/>
    <mesh name="proximal_row_l_geom_3_sdfastPISIFORMw_mirror" file="assets/sdfastPISIFORMw_mirror.stl" scale="1 1 1"/>
    <mesh name="proximal_row_l_geom_4_sdfastTRIQUETRALw_mirror" file="assets/sdfastTRIQUETRALw_mirror.stl" scale="1 1 1"/>
    <mesh name="hand_l_geom_1_sdfast_1seg_hand_fr_c_5mc_mirror" file="assets/sdfast_1seg_hand_fr_c_5mc_mirror.stl" scale="1 1 1"/>
    <mesh name="hand_l_geom_2_sdfast_1seg_hand_fr_c_4mc_mirror" file="assets/sdfast_1seg_hand_fr_c_4mc_mirror.stl" scale="1 1 1"/>
    <mesh name="hand_l_geom_3_sdfast_1seg_hand_fr_c_3mc_mirror" file="assets/sdfast_1seg_hand_fr_c_3mc_mirror.stl" scale="1 1 1"/>
    <mesh name="hand_l_geom_4_sdfast_1seg_hand_fr_c_2mc_mirror" file="assets/sdfast_1seg_hand_fr_c_2mc_mirror.stl" scale="1 1 1"/>
    <mesh name="hand_l_geom_5_sdfast_1seg_hand_fr_c_trapezium_mirror" file="assets/sdfast_1seg_hand_fr_c_trapezium_mirror.stl" scale="1 1 1"/>
    <mesh name="hand_l_geom_6_sdfast_1seg_hand_fr_c_trapezoid_mirror" file="assets/sdfast_1seg_hand_fr_c_trapezoid_mirror.stl" scale="1 1 1"/>
    <mesh name="hand_l_geom_7_sdfast_1seg_hand_fr_c_hamate_mirror" file="assets/sdfast_1seg_hand_fr_c_hamate_mirror.stl" scale="1 1 1"/>
    <mesh name="hand_l_geom_8_capitate_mirror" file="assets/capitate_mirror.stl" scale="1 1 1"/>
    <mesh name="hand_l_geom_9_hand_2proxph_mirror" file="assets/hand_2proxph_mirror.stl" scale="1 1 1"/>
    <mesh name="hand_l_geom_10_hand_2midph_mirror" file="assets/hand_2midph_mirror.stl" scale="1 1 1"/>
    <mesh name="hand_l_geom_11_hand_2distph_mirror" file="assets/hand_2distph_mirror.stl" scale="1 1 1"/>
    <mesh name="hand_l_geom_12_hand_3proxph_mirror" file="assets/hand_3proxph_mirror.stl" scale="1 1 1"/>
    <mesh name="hand_l_geom_13_hand_3midph_mirror" file="assets/hand_3midph_mirror.stl" scale="1 1 1"/>
    <mesh name="hand_l_geom_14_hand_3distph_mirror" file="assets/hand_3distph_mirror.stl" scale="1 1 1"/>
    <mesh name="hand_l_geom_15_hand_4proxph_mirror" file="assets/hand_4proxph_mirror.stl" scale="1 1 1"/>
    <mesh name="hand_l_geom_16_hand_4midph_mirror" file="assets/hand_4midph_mirror.stl" scale="1 1 1"/>
    <mesh name="hand_l_geom_17_hand_4distph_mirror" file="assets/hand_4distph_mirror.stl" scale="1 1 1"/>
    <mesh name="hand_l_geom_18_hand_5proxph_mirror" file="assets/hand_5proxph_mirror.stl" scale="1 1 1"/>
    <mesh name="hand_l_geom_19_hand_5midph_mirror" file="assets/hand_5midph_mirror.stl" scale="1 1 1"/>
    <mesh name="hand_l_geom_20_hand_5distph_mirror" file="assets/hand_5distph_mirror.stl" scale="1 1 1"/>
    <mesh name="hand_l_geom_21_hand_thumbprox_mirror" file="assets/hand_thumbprox_mirror.stl" scale="1 1 1"/>
    <mesh name="hand_l_geom_22_hand_thumbdist_mirror" file="assets/hand_thumbdist_mirror.stl" scale="1 1 1"/>
    <mesh name="hand_l_geom_23_hand_1mc_mirror" file="assets/hand_1mc_mirror.stl" scale="1 1 1"/>
  </asset>
  <tendon>
    <!-- Leave this comment here to make 'tendon' element pretty printed !-->
  </tendon>
  <actuator>
    <!-- Leave this comment here to make 'actuator' element pretty printed !-->
    <general name="elv_angle_motor_r" joint="elv_angle_r" class="motor" gainprm="50 0 0 0 0 0 0 0 0 0" />
    <general name="shoulder_elv_motor_r" joint="shoulder_elv_r" class="motor" gainprm="50 0 0 0 0 0 0 0 0 0" />
    <general name="shoulder_rot_motor_r" joint="shoulder_rot_r" class="motor" gainprm="5 0 0 0 0 0 0 0 0 0" />
    <general name="elbow_flexion_motor_r" joint="elbow_flexion_r" class="motor" gainprm="10 0 0 0 0 0 0 0 0 0" />
    <general name="pro_sup_motor_r" joint="pro_sup_r" class="motor" gainprm="2 0 0 0 0 0 0 0 0 0" />
    <general name="deviation_motor_r" joint="deviation_r" class="motor" gainprm="2 0 0 0 0 0 0 0 0 0" />
    <general name="flexion_motor_r" joint="flexion_r" class="motor" gainprm="2 0 0 0 0 0 0 0 0 0" />
    <general name="elv_angle_motor_l" joint="elv_angle_l" class="motor" gainprm="50 0 0 0 0 0 0 0 0 0" />
    <general name="shoulder_elv_motor_l" joint="shoulder_elv_l" class="motor" gainprm="50 0 0 0 0 0 0 0 0 0" />
    <general name="shoulder_rot_motor_l" joint="shoulder_rot_l" class="motor" gainprm="5 0 0 0 0 0 0 0 0 0" />
    <general name="elbow_flexion_motor_l" joint="elbow_flexion_l" class="motor" gainprm="10 0 0 0 0 0 0 0 0 0" />
    <general name="pro_sup_motor_l" joint="pro_sup_l" class="motor" gainprm="2 0 0 0 0 0 0 0 0 0" />
    <general name="deviation_motor_l" joint="deviation_l" class="motor" gainprm="2 0 0 0 0 0 0 0 0 0" />
    <general name="flexion_motor_l" joint="flexion_l" class="motor" gainprm="2 0 0 0 0 0 0 0 0 0" />
  </actuator>
  <equality>
    <!-- Leave this comment here to make 'equality' element pretty printed !-->
    <joint name="sternoclavicular_r2_con_r" joint1="sternoclavicular_r2_r" joint2="shoulder_elv_r" active="true" polycoef="1.11e-16 -0.242 0 0 0" solimp="0.9999 0.9999 0.001 0.5 2"/>
    <joint name="sternoclavicular_r3_con_r" joint1="sternoclavicular_r3_r" joint2="shoulder_elv_r" active="true" polycoef="-8.327e-17 0.1025 0 0 0" solimp="0.9999 0.9999 0.001 0.5 2"/>
    <joint name="unrotscap_r2_con_r" joint1="unrotscap_r2_r" joint2="shoulder_elv_r" active="true" polycoef="-1.11e-16 0.242 0 0 0" solimp="0.9999 0.9999 0.001 0.5 2"/>
    <joint name="unrotscap_r3_con_r" joint1="unrotscap_r3_r" joint2="shoulder_elv_r" active="true" polycoef="8.327e-17 -0.1025 0 0 0" solimp="0.9999 0.9999 0.001 0.5 2"/>
    <joint name="acromioclavicular_r1_con_r" joint1="acromioclavicular_r1_r" joint2="shoulder_elv_r" active="true" polycoef="-8.327e-17 0.178 0 0 0" solimp="0.9999 0.9999 0.001 0.5 2"/>
    <joint name="acromioclavicular_r2_con_r" joint1="acromioclavicular_r2_r" joint2="shoulder_elv_r" active="true" polycoef="2.776e-17 -0.049 0 0 0" solimp="0.9999 0.9999 0.001 0.5 2"/>
    <joint name="acromioclavicular_r3_con_r" joint1="acromioclavicular_r3_r" joint2="shoulder_elv_r" active="true" polycoef="-1.11e-16 0.396 0 0 0" solimp="0.9999 0.9999 0.001 0.5 2"/>
    <joint name="unrothum_r1_con_r" joint1="unrothum_r1_r" joint2="shoulder_elv_r" active="true" polycoef="8.327e-17 -0.178 0 0 0" solimp="0.9999 0.9999 0.001 0.5 2"/>
    <joint name="unrothum_r2_con_r" joint1="unrothum_r2_r" joint2="shoulder_elv_r" active="true" polycoef="-2.776e-17 0.049 0 0 0" solimp="0.9999 0.9999 0.001 0.5 2"/>
    <joint name="unrothum_r3_con_r" joint1="unrothum_r3_r" joint2="shoulder_elv_r" active="true" polycoef="1.11e-16 -0.396 0 0 0" solimp="0.9999 0.9999 0.001 0.5 2"/>
    <joint name="shoulder1_r2_con_r" joint1="shoulder1_r2_r" joint2="elv_angle_r" active="true" polycoef="0 -1 0 0 0" solimp="0.9999 0.9999 0.001 0.5 2"/>
    <joint name="wrist_hand_r1_con_r" joint1="wrist_hand_r1_r" joint2="deviation_r" active="true" polycoef="0 1.357 -0.8185 0 0" solimp="0.9999 0.9999 0.001 0.5 2"/>
    <joint name="wrist_hand_r3_con_r" joint1="wrist_hand_r3_r" joint2="flexion_r" active="true" polycoef="0 1 0 0 0" solimp="0.9999 0.9999 0.001 0.5 2"/>
    <joint name="sternoclavicular_r2_con_l" joint1="sternoclavicular_r2_l" joint2="shoulder_elv_l" active="true" polycoef="1.11e-16 -0.242 0 0 0" solimp="0.9999 0.9999 0.001 0.5 2"/>
    <joint name="sternoclavicular_r3_con_l" joint1="sternoclavicular_r3_l" joint2="shoulder_elv_l" active="true" polycoef="-8.327e-17 0.1025 0 0 0" solimp="0.9999 0.9999 0.001 0.5 2"/>
    <joint name="unrotscap_r2_con_l" joint1="unrotscap_r2_l" joint2="shoulder_elv_l" active="true" polycoef="-1.11e-16 0.242 0 0 0" solimp="0.9999 0.9999 0.001 0.5 2"/>
    <joint name="unrotscap_r3_con_l" joint1="unrotscap_r3_l" joint2="shoulder_elv_l" active="true" polycoef="8.327e-17 -0.1025 0 0 0" solimp="0.9999 0.9999 0.001 0.5 2"/>
    <joint name="acromioclavicular_r1_con" joint1="acromioclavicular_r1_l" joint2="shoulder_elv_l" active="true" polycoef="-8.327e-17 0.178 0 0 0" solimp="0.9999 0.9999 0.001 0.5 2"/>
    <joint name="acromioclavicular_r2_con_l" joint1="acromioclavicular_r2_l" joint2="shoulder_elv_l" active="true" polycoef="2.776e-17 -0.049 0 0 0" solimp="0.9999 0.9999 0.001 0.5 2"/>
    <joint name="acromioclavicular_r3_con_l" joint1="acromioclavicular_r3_l" joint2="shoulder_elv_l" active="true" polycoef="-1.11e-16 0.396 0 0 0" solimp="0.9999 0.9999 0.001 0.5 2"/>
    <joint name="unrothum_r1_con_l" joint1="unrothum_r1_l" joint2="shoulder_elv_l" active="true" polycoef="8.327e-17 -0.178 0 0 0" solimp="0.9999 0.9999 0.001 0.5 2"/>
    <joint name="unrothum_r2_con_l" joint1="unrothum_r2_l" joint2="shoulder_elv_l" active="true" polycoef="-2.776e-17 0.049 0 0 0" solimp="0.9999 0.9999 0.001 0.5 2"/>
    <joint name="unrothum_r3_con_l" joint1="unrothum_r3_l" joint2="shoulder_elv_l" active="true" polycoef="1.11e-16 -0.396 0 0 0" solimp="0.9999 0.9999 0.001 0.5 2"/>
    <joint name="shoulder1_r2_con_l" joint1="shoulder1_r2_l" joint2="elv_angle_l" active="true" polycoef="0 -1 0 0 0" solimp="0.9999 0.9999 0.001 0.5 2"/>
    <joint name="wrist_hand_r1_con_l" joint1="wrist_hand_r1_l" joint2="deviation_l" active="true" polycoef="0 1.357 -0.8185 0 0" solimp="0.9999 0.9999 0.001 0.5 2"/>
    <joint name="wrist_hand_r3_con_l" joint1="wrist_hand_r3_l" joint2="flexion_l" active="true" polycoef="0 1 0 0 0" solimp="0.9999 0.9999 0.001 0.5 2"/>
    <joint name="t_x_locked" active="true" joint1="t_x" polycoef="0.0 0 0 0 0" solimp="0.9999 0.9999 0.001 0.5 2"/>
    <joint name="t_y_locked" active="true" joint1="t_y" polycoef="0.0 0 0 0 0" solimp="0.9999 0.9999 0.001 0.5 2"/>
    <joint name="t_z_locked" active="true" joint1="t_z" polycoef="0.0 0 0 0 0" solimp="0.9999 0.9999 0.001 0.5 2"/>
    <joint name="r_x_locked" active="true" joint1="r_x" polycoef="0.0 0 0 0 0" solimp="0.9999 0.9999 0.001 0.5 2"/>
    <joint name="r_y_locked" active="true" joint1="r_y" polycoef="0.0 0 0 0 0" solimp="0.9999 0.9999 0.001 0.5 2"/>
    <joint name="r_z_locked" active="true" joint1="r_z" polycoef="0.0 0 0 0 0" solimp="0.9999 0.9999 0.001 0.5 2"/>
  </equality>
  <contact>
    <!-- Leave this comment here to make 'contact' element pretty printed !-->
  </contact>
  <keyframe>
    <key name="default-pose" qpos="0 0 0 0 -1.571 0 -0.1267 0.05367 -0.05367 0.1267 -0.02566 0.2073 0.0932 -0.0932 -0.2073 0.02566 4.656e-09 0.5236 -4.656e-09 -2.212e-09 1.571 -2e-08 3.515e-09 0 4.769e-09 0 -0.1267 0.05367 -0.05367 0.1267 -0.02566 0.2073 0.0932 -0.0932 -0.2073 0.02566 3.572e-09 0.5236 -3.572e-09 -2.381e-09 1.571 -2e-08 -5.551e-17 0 -7.533e-17 0"/>
  </keyframe>
</mujoco>
