<mujoco model="MuJoCo Model">
  <compiler angle="radian" autolimits="true"/>
  <size njmax="1000" nconmax="400" nuser_jnt="1"/>
  <visual>
    <global offwidth="1280" offheight="960"/>
  </visual>
  <statistic meansize="0.09479" extent="1.51875" center="-0.040656 0.000115421 0.595402"/>
  <default class="main">
    <joint limited="true" armature="1e-05" damping="0.05"/>
    <geom margin="0.001" rgba="0.8 0.6 0.4 1"/>
    <site size="0.001 0.005 0.005"/>
  </default>
  <asset>
    <texture type="skybox" builtin="gradient" rgb1="1 1 1" rgb2="0.6 0.8 1" width="256" height="1536"/>
    <mesh name="controller-right" file="assets/oculus-quest-1-controller-right.stl"/>
    <mesh name="controller-left" file="assets/oculus-quest-1-controller-left.stl"/>
    <mesh name="headset" file="assets/oculus-quest-1-headset-maybe-correct-scaling.stl"/>
    <mesh name="skull" file="assets/skull.stl"/>
    <mesh name="spine" file="assets/spine.stl"/>
    <mesh name="thorax_geom_1_thorax" file="assets/thorax.stl"/>
    <mesh name="clavicle_r_geom_1_clavicle" file="assets/clavicle.stl"/>
    <mesh name="scapula_r_geom_1_scapula" file="assets/scapula.stl"/>
    <mesh name="humerus_r_geom_1_humerus" file="assets/humerus.stl"/>
    <mesh name="ulna_r_geom_1_ulna" file="assets/ulna.stl"/>
    <mesh name="radius_r_geom_1_radius" file="assets/radius.stl"/>
    <mesh name="proximal_row_r_geom_1_lunate" file="assets/lunate.stl"/>
    <mesh name="proximal_row_r_geom_2_sdfastSCAPHOIDw" file="assets/sdfastSCAPHOIDw.stl"/>
    <mesh name="proximal_row_r_geom_3_sdfastPISIFORMw" file="assets/sdfastPISIFORMw.stl"/>
    <mesh name="proximal_row_r_geom_4_sdfastTRIQUETRALw" file="assets/sdfastTRIQUETRALw.stl"/>
    <mesh name="hand_r_geom_1_sdfast_1seg_hand_fr_c_5mc" file="assets/sdfast_1seg_hand_fr_c_5mc.stl"/>
    <mesh name="hand_r_geom_2_sdfast_1seg_hand_fr_c_4mc" file="assets/sdfast_1seg_hand_fr_c_4mc.stl"/>
    <mesh name="hand_r_geom_3_sdfast_1seg_hand_fr_c_3mc" file="assets/sdfast_1seg_hand_fr_c_3mc.stl"/>
    <mesh name="hand_r_geom_4_sdfast_1seg_hand_fr_c_2mc" file="assets/sdfast_1seg_hand_fr_c_2mc.stl"/>
    <mesh name="hand_r_geom_5_sdfast_1seg_hand_fr_c_trapezium" file="assets/sdfast_1seg_hand_fr_c_trapezium.stl"/>
    <mesh name="hand_r_geom_6_sdfast_1seg_hand_fr_c_trapezoid" file="assets/sdfast_1seg_hand_fr_c_trapezoid.stl"/>
    <mesh name="hand_r_geom_7_sdfast_1seg_hand_fr_c_hamate" file="assets/sdfast_1seg_hand_fr_c_hamate.stl"/>
    <mesh name="hand_r_geom_8_capitate" file="assets/capitate.stl"/>
    <mesh name="hand_r_geom_9_hand_2proxph" file="assets/hand_2proxph.stl"/>
    <mesh name="hand_r_geom_10_hand_2midph" file="assets/hand_2midph.stl"/>
    <mesh name="hand_r_geom_11_hand_2distph" file="assets/hand_2distph.stl"/>
    <mesh name="hand_r_geom_12_hand_3proxph" file="assets/hand_3proxph.stl"/>
    <mesh name="hand_r_geom_13_hand_3midph" file="assets/hand_3midph.stl"/>
    <mesh name="hand_r_geom_14_hand_3distph" file="assets/hand_3distph.stl"/>
    <mesh name="hand_r_geom_15_hand_4proxph" file="assets/hand_4proxph.stl"/>
    <mesh name="hand_r_geom_16_hand_4midph" file="assets/hand_4midph.stl"/>
    <mesh name="hand_r_geom_17_hand_4distph" file="assets/hand_4distph.stl"/>
    <mesh name="hand_r_geom_18_hand_5proxph" file="assets/hand_5proxph.stl"/>
    <mesh name="hand_r_geom_19_hand_5midph" file="assets/hand_5midph.stl"/>
    <mesh name="hand_r_geom_20_hand_5distph" file="assets/hand_5distph.stl"/>
    <mesh name="hand_r_geom_21_hand_thumbprox" file="assets/hand_thumbprox.stl"/>
    <mesh name="hand_r_geom_22_hand_thumbdist" file="assets/hand_thumbdist.stl"/>
    <mesh name="hand_r_geom_23_hand_1mc" file="assets/hand_1mc.stl"/>
    <mesh name="clavicle_l_geom_1_clavicle_mirror" file="assets/clavicle_mirror.stl"/>
    <mesh name="scapula_l_geom_1_scapula_mirror" file="assets/scapula_mirror.stl"/>
    <mesh name="humerus_l_geom_1_humerus_mirror" file="assets/humerus_mirror.stl"/>
    <mesh name="ulna_l_geom_1_ulna_mirror" file="assets/ulna_mirror.stl"/>
    <mesh name="radius_l_geom_1_radius_mirror" file="assets/radius_mirror.stl"/>
    <mesh name="proximal_row_l_geom_1_lunate_mirror" file="assets/lunate_mirror.stl"/>
    <mesh name="proximal_row_l_geom_2_sdfastSCAPHOIDw_mirror" file="assets/sdfastSCAPHOIDw_mirror.stl"/>
    <mesh name="proximal_row_l_geom_3_sdfastPISIFORMw_mirror" file="assets/sdfastPISIFORMw_mirror.stl"/>
    <mesh name="proximal_row_l_geom_4_sdfastTRIQUETRALw_mirror" file="assets/sdfastTRIQUETRALw_mirror.stl"/>
    <mesh name="hand_l_geom_1_sdfast_1seg_hand_fr_c_5mc_mirror" file="assets/sdfast_1seg_hand_fr_c_5mc_mirror.stl"/>
    <mesh name="hand_l_geom_2_sdfast_1seg_hand_fr_c_4mc_mirror" file="assets/sdfast_1seg_hand_fr_c_4mc_mirror.stl"/>
    <mesh name="hand_l_geom_3_sdfast_1seg_hand_fr_c_3mc_mirror" file="assets/sdfast_1seg_hand_fr_c_3mc_mirror.stl"/>
    <mesh name="hand_l_geom_4_sdfast_1seg_hand_fr_c_2mc_mirror" file="assets/sdfast_1seg_hand_fr_c_2mc_mirror.stl"/>
    <mesh name="hand_l_geom_5_sdfast_1seg_hand_fr_c_trapezium_mirror" file="assets/sdfast_1seg_hand_fr_c_trapezium_mirror.stl"/>
    <mesh name="hand_l_geom_6_sdfast_1seg_hand_fr_c_trapezoid_mirror" file="assets/sdfast_1seg_hand_fr_c_trapezoid_mirror.stl"/>
    <mesh name="hand_l_geom_7_sdfast_1seg_hand_fr_c_hamate_mirror" file="assets/sdfast_1seg_hand_fr_c_hamate_mirror.stl"/>
    <mesh name="hand_l_geom_8_capitate_mirror" file="assets/capitate_mirror.stl"/>
    <mesh name="hand_l_geom_9_hand_2proxph_mirror" file="assets/hand_2proxph_mirror.stl"/>
    <mesh name="hand_l_geom_10_hand_2midph_mirror" file="assets/hand_2midph_mirror.stl"/>
    <mesh name="hand_l_geom_11_hand_2distph_mirror" file="assets/hand_2distph_mirror.stl"/>
    <mesh name="hand_l_geom_12_hand_3proxph_mirror" file="assets/hand_3proxph_mirror.stl"/>
    <mesh name="hand_l_geom_13_hand_3midph_mirror" file="assets/hand_3midph_mirror.stl"/>
    <mesh name="hand_l_geom_14_hand_3distph_mirror" file="assets/hand_3distph_mirror.stl"/>
    <mesh name="hand_l_geom_15_hand_4proxph_mirror" file="assets/hand_4proxph_mirror.stl"/>
    <mesh name="hand_l_geom_16_hand_4midph_mirror" file="assets/hand_4midph_mirror.stl"/>
    <mesh name="hand_l_geom_17_hand_4distph_mirror" file="assets/hand_4distph_mirror.stl"/>
    <mesh name="hand_l_geom_18_hand_5proxph_mirror" file="assets/hand_5proxph_mirror.stl"/>
    <mesh name="hand_l_geom_19_hand_5midph_mirror" file="assets/hand_5midph_mirror.stl"/>
    <mesh name="hand_l_geom_20_hand_5distph_mirror" file="assets/hand_5distph_mirror.stl"/>
    <mesh name="hand_l_geom_21_hand_thumbprox_mirror" file="assets/hand_thumbprox_mirror.stl"/>
    <mesh name="hand_l_geom_22_hand_thumbdist_mirror" file="assets/hand_thumbdist_mirror.stl"/>
    <mesh name="hand_l_geom_23_hand_1mc_mirror" file="assets/hand_1mc_mirror.stl"/>
  </asset>
  <worldbody>
    <camera name="for_testing" pos="-1 -0.8 0.5" quat="0.718027 0.437104 -0.31987 -0.437104"/>
    <light name="scene_directional_light" pos="0.9 0.3 2.5" dir="0 0 -1" directional="true" castshadow="false" cutoff="4" exponent="20" diffuse="1 1 1" specular="0 0 0"/>
    <light pos="0 0 0" dir="0 0 -1" directional="true"/>
    <body name="controller-right" pos="0.0562046 -0.188274 0.386689" quat="0.909234 0.213009 0.357627 -0.00486519">
      <joint name="controller-right" limited="false" type="free" armature="0" damping="0"/>
      <geom name="controller-right" type="mesh" mass="0.129" rgba="0.24 0.24 0.24 1" mesh="controller-right"/>
    </body>
    <body name="controller-left" pos="0.0557552 0.188652 0.380375" quat="0.896392 -0.13503 0.404493 0.120972">
      <joint name="controller-left" limited="false" type="free" armature="0" damping="0"/>
      <geom name="controller-left" type="mesh" mass="0.129" rgba="0.24 0.24 0.24 1" mesh="controller-left"/>
    </body>
    <body name="headset" pos="0.10703 -0.00163299 1.19141" quat="1 0.000101837 0 0">
      <joint name="headset" limited="false" type="free" armature="0" damping="0"/>
      <geom name="headset" type="mesh" mass="0.571" rgba="0.24 0.24 0.24 1" mesh="headset"/>
    </body>
    <body name="ground" quat="0.707035 0.707179 0 0"/>
    <body name="thorax" pos="0 0 1" quat="0.707035 0.707179 0 0">
      <joint name="t_x" pos="0 0 0" axis="1 0 0" type="slide" range="-100 100" damping="0"/>
      <joint name="t_y" pos="0 0 0" axis="0 1 0" type="slide" range="-100 100" damping="0"/>
      <joint name="t_z" pos="0 0 0" axis="0 0 1" type="slide" range="-100 100" damping="0"/>
      <joint name="r_x" pos="0 0 0" axis="1 0 0" range="-6.283 6.283" damping="0"/>
      <joint name="r_y" pos="0 0 0" axis="0 1 0" range="-6.283 6.283" damping="0" user="-1.5708"/>
      <joint name="r_z" pos="0 0 0" axis="0 0 1" range="-6.283 6.283" damping="0"/>
      <geom name="spine" type="mesh" rgba="1 1 1 1" mesh="spine"/>
      <geom name="thorax_geom_1" type="mesh" rgba="1 1 1 1" mesh="thorax_geom_1_thorax"/>
      <body name="skull">
        <geom name="skull" type="mesh" rgba="1 1 1 1" mesh="skull"/>
      </body>
      <body name="clavicle_r" pos="0.006325 0.00693 0.02547">
        <inertial pos="-0.011096 0.0063723 0.054168" quat="0.906292 0.0334036 0.164622 -0.387838" mass="0.156" diaginertia="0.001 0.001 0.001"/>
        <joint name="sternoclavicular_r2_r" pos="0 0 0" axis="0.0153 0.989299 -0.1451" limited="false" range="-100000 100000" user="-0.126711"/>
        <joint name="sternoclavicular_r3_r" pos="0 0 0" axis="-0.994473 0 -0.104997" limited="false" range="-100000 100000" user="0.0536689"/>
        <geom name="clavicle_r_geom_1" type="mesh" rgba="1 1 1 1" mesh="clavicle_r_geom_1_clavicle"/>
        <body name="clavphant_r" pos="-0.01433 0.02007 0.1355">
          <inertial pos="0 0 0" mass="0.001" diaginertia="1 1 1"/>
          <joint name="unrotscap_r3_r" pos="0 0 0" axis="-0.994473 0 -0.104997" limited="false" range="-100000 100000" user="-0.0536689"/>
          <joint name="unrotscap_r2_r" pos="0 0 0" axis="0.0153 0.989299 -0.1451" limited="false" range="-100000 100000" user="0.126711"/>
          <body name="scapula_r">
            <inertial pos="-0.054694 -0.035032 -0.043734" quat="0.453021 0.77921 0.0744129 0.426692" mass="0.70396" diaginertia="0.00199576 0.00103993 0.001"/>
            <joint name="acromioclavicular_r2_r" pos="0 0 0" axis="0.157095 0.947269 -0.279291" limited="false" range="-100000 100000" user="-0.0256564"/>
            <joint name="acromioclavicular_r3_r" pos="0 0 0" axis="-0.754084 0.297594 0.585487" limited="false" range="-100000 100000" user="0.207346"/>
            <joint name="acromioclavicular_r1_r" pos="0 0 0" axis="0.6377 0.1186 0.7611" limited="false" range="-100000 100000" user="0.0932007"/>
            <geom name="scapula_r_geom_1" type="mesh" rgba="1 1 1 1" mesh="scapula_r_geom_1_scapula"/>
            <body name="scapphant_r" pos="-0.00955 -0.034 0.009">
              <inertial pos="0 0 0" mass="0.001" diaginertia="1 1 1"/>
              <joint name="unrothum_r1_r" pos="0 0 0" axis="0.6377 0.1186 0.7611" limited="false" range="-100000 100000" user="-0.0932007"/>
              <joint name="unrothum_r3_r" pos="0 0 0" axis="-0.754084 0.297594 0.585487" limited="false" range="-100000 100000" user="-0.207346"/>
              <joint name="unrothum_r2_r" pos="0 0 0" axis="0.157095 0.947269 -0.279291" limited="false" range="-100000 100000" user="0.0256564"/>
              <body name="humphant_r">
                <inertial pos="0 0 0" mass="0.001" diaginertia="1 1 1"/>
                <joint name="elv_angle_r" pos="0 0 0" axis="0.00479995 0.999089 0.0423995" range="-1.658 2.269" user="4.6557e-09"/>
                <body name="humphant1_r">
                  <inertial pos="0 0 0" mass="0.001" diaginertia="1 1 1"/>
                  <joint name="shoulder_elv_r" pos="0 0 0" axis="-0.998261 0.00229991 0.0588977" range="0 3.142" user="0.523599"/>
                  <joint name="shoulder1_r2_r" pos="0 0 0" axis="0.00479995 0.999089 0.0423995" limited="false" range="-100000 100000" user="-4.6557e-09"/>
                  <body name="humerus_r">
                    <inertial pos="0.018064 -0.140141 -0.012746" quat="0.407851 0.343714 -0.567755 0.627034" mass="1.99757" diaginertia="0.0128576 0.0121576 0.00239265"/>
                    <joint name="shoulder_rot_r" pos="0 0 0" axis="0.00479995 0.999089 0.0423995" range="-1.571 2.094" user="-2.21205e-09"/>
                    <geom name="humerus_r_geom_1" type="mesh" rgba="1 1 1 1" mesh="humerus_r_geom_1_humerus"/>
                    <body name="ulna_r" pos="0.0061 -0.2904 -0.0123">
                      <inertial pos="0.00971783 -0.0959509 0.024286" quat="0.792048 0.609078 0.0156735 0.0379256" mass="1.1053" diaginertia="0.00543663 0.00523521 0.001"/>
                      <joint name="elbow_flexion_r" pos="0 0 0" axis="0.0494004 0.0366003 0.998108" range="0 2.269" user="1.5708"/>
                      <geom name="ulna_r_geom_1" type="mesh" rgba="1 1 1 1" mesh="ulna_r_geom_1_ulna"/>
                      <body name="radius_r" pos="0.0004 -0.0115 0.02">
                        <inertial pos="0.0336341 -0.181559 0.0156" quat="0.770264 0.63559 0.0119833 0.0507376" mass="0.23359" diaginertia="0.001 0.001 0.001"/>
                        <joint name="pro_sup_r" pos="0 0 0" axis="-0.0171593 0.992662 -0.119695" range="-1.571 1.571" user="-2e-08"/>
                        <geom name="radius_r_geom_1" type="mesh" rgba="1 1 1 1" mesh="radius_r_geom_1_radius"/>
                        <body name="proximal_row_r" pos="0.018 -0.242 0.025">
                          <inertial pos="0 0 0" mass="0.001" diaginertia="0.001 0.001 0.001"/>
                          <joint name="deviation_r" pos="0 0 0" axis="-0.819097 -0.1356 -0.557398" range="-0.1745 0.4363" user="3.51467e-09"/>
                          <joint name="flexion_r" pos="0 0 0" axis="0.956427 -0.252207 0.147104" range="-0.6109 0.6109"/>
                          <geom name="proximal_row_r_geom_1" type="mesh" rgba="1 1 1 1" mesh="proximal_row_r_geom_1_lunate"/>
                          <geom name="proximal_row_r_geom_2" type="mesh" rgba="1 1 1 1" mesh="proximal_row_r_geom_2_sdfastSCAPHOIDw"/>
                          <geom name="proximal_row_r_geom_3" type="mesh" rgba="1 1 1 1" mesh="proximal_row_r_geom_3_sdfastPISIFORMw"/>
                          <geom name="proximal_row_r_geom_4" type="mesh" rgba="1 1 1 1" mesh="proximal_row_r_geom_4_sdfastTRIQUETRALw"/>
                          <body name="hand_r" pos="0.003992 -0.01505 0.002327">
                            <inertial pos="-0.00301314 -0.0424993 -0.00112205" quat="0.526799 0.470642 -0.462095 0.536141" mass="0.5819" diaginertia="0.001 0.001 0.001"/>
                            <joint name="wrist_hand_r1_r" pos="0 0 0" axis="0.899124 -0.349109 -0.264007" limited="false" range="-100000 100000" user="4.7699e-09"/>
                            <joint name="wrist_hand_r3_r" pos="0 0 0" axis="0.997118 0.0107002 -0.0751014" limited="false" range="-100000 100000"/>
                            <geom name="hand_r_geom_1" type="mesh" rgba="1 1 1 1" mesh="hand_r_geom_1_sdfast_1seg_hand_fr_c_5mc"/>
                            <geom name="hand_r_geom_2" type="mesh" rgba="1 1 1 1" mesh="hand_r_geom_2_sdfast_1seg_hand_fr_c_4mc"/>
                            <geom name="hand_r_geom_3" type="mesh" rgba="1 1 1 1" mesh="hand_r_geom_3_sdfast_1seg_hand_fr_c_3mc"/>
                            <geom name="hand_r_geom_4" type="mesh" rgba="1 1 1 1" mesh="hand_r_geom_4_sdfast_1seg_hand_fr_c_2mc"/>
                            <geom name="hand_r_geom_5" type="mesh" rgba="1 1 1 1" mesh="hand_r_geom_5_sdfast_1seg_hand_fr_c_trapezium"/>
                            <geom name="hand_r_geom_6" type="mesh" rgba="1 1 1 1" mesh="hand_r_geom_6_sdfast_1seg_hand_fr_c_trapezoid"/>
                            <geom name="hand_r_geom_7" type="mesh" rgba="1 1 1 1" mesh="hand_r_geom_7_sdfast_1seg_hand_fr_c_hamate"/>
                            <geom name="hand_r_geom_8" type="mesh" rgba="1 1 1 1" mesh="hand_r_geom_8_capitate"/>
                            <geom name="hand_r_geom_9" type="mesh" rgba="1 1 1 1" mesh="hand_r_geom_9_hand_2proxph"/>
                            <geom name="hand_r_geom_10" type="mesh" rgba="1 1 1 1" mesh="hand_r_geom_10_hand_2midph"/>
                            <geom name="hand_r_geom_11" type="mesh" rgba="1 1 1 1" mesh="hand_r_geom_11_hand_2distph"/>
                            <geom name="hand_r_geom_12" type="mesh" rgba="1 1 1 1" mesh="hand_r_geom_12_hand_3proxph"/>
                            <geom name="hand_r_geom_13" type="mesh" rgba="1 1 1 1" mesh="hand_r_geom_13_hand_3midph"/>
                            <geom name="hand_r_geom_14" type="mesh" rgba="1 1 1 1" mesh="hand_r_geom_14_hand_3distph"/>
                            <geom name="hand_r_geom_15" type="mesh" rgba="1 1 1 1" mesh="hand_r_geom_15_hand_4proxph"/>
                            <geom name="hand_r_geom_16" type="mesh" rgba="1 1 1 1" mesh="hand_r_geom_16_hand_4midph"/>
                            <geom name="hand_r_geom_17" type="mesh" rgba="1 1 1 1" mesh="hand_r_geom_17_hand_4distph"/>
                            <geom name="hand_r_geom_18" type="mesh" rgba="1 1 1 1" mesh="hand_r_geom_18_hand_5proxph"/>
                            <geom name="hand_r_geom_19" type="mesh" rgba="1 1 1 1" mesh="hand_r_geom_19_hand_5midph"/>
                            <geom name="hand_r_geom_20" type="mesh" rgba="1 1 1 1" mesh="hand_r_geom_20_hand_5distph"/>
                            <geom name="hand_r_geom_21" type="mesh" rgba="1 1 1 1" mesh="hand_r_geom_21_hand_thumbprox"/>
                            <geom name="hand_r_geom_22" type="mesh" rgba="1 1 1 1" mesh="hand_r_geom_22_hand_thumbdist"/>
                            <geom name="hand_r_geom_23" type="mesh" rgba="1 1 1 1" mesh="hand_r_geom_23_hand_1mc"/>
                          </body>
                        </body>
                      </body>
                    </body>
                  </body>
                </body>
              </body>
            </body>
          </body>
        </body>
      </body>
      <body name="clavicle_l" pos="0.006325 0.00693 -0.02547">
        <inertial pos="-0.011096 0.0063723 -0.054168" quat="0.906292 0.0334036 0.164622 -0.387838" mass="0.156" diaginertia="0.001 0.001 0.001"/>
        <joint name="sternoclavicular_r2_l" pos="0 0 0" axis="-0.0153 -0.989299 -0.1451" limited="false" range="-100000 100000" user="-0.126711"/>
        <joint name="sternoclavicular_r3_l" pos="0 0 0" axis="0.994473 0 -0.104997" limited="false" range="-100000 100000" user="0.0536689"/>
        <geom name="clavicle_l_geom_1" type="mesh" rgba="1 1 1 1" mesh="clavicle_l_geom_1_clavicle_mirror"/>
        <body name="clavphant_l" pos="-0.01433 0.02007 -0.1355">
          <inertial pos="0 0 0" mass="0.001" diaginertia="1 1 1"/>
          <joint name="unrotscap_r3_l" pos="0 0 0" axis="0.994473 0 -0.104997" limited="false" range="-100000 100000" user="-0.0536689"/>
          <joint name="unrotscap_r2_l" pos="0 0 0" axis="-0.0153 -0.989299 -0.1451" limited="false" range="-100000 100000" user="0.126711"/>
          <body name="scapula_l">
            <inertial pos="-0.054694 -0.035032 0.043734" quat="0.453021 0.77921 0.0744129 0.426692" mass="0.70396" diaginertia="0.00199576 0.00103993 0.001"/>
            <joint name="acromioclavicular_r2_l" pos="0 0 0" axis="-0.157095 -0.947269 -0.279291" limited="false" range="-100000 100000" user="-0.0256564"/>
            <joint name="acromioclavicular_r3_l" pos="0 0 0" axis="0.754084 -0.297594 0.585487" limited="false" range="-100000 100000" user="0.207346"/>
            <joint name="acromioclavicular_r1_l" pos="0 0 0" axis="-0.6377 -0.1186 0.7611" limited="false" range="-100000 100000" user="0.0932007"/>
            <geom name="scapula_l_geom_1" type="mesh" rgba="1 1 1 1" mesh="scapula_l_geom_1_scapula_mirror"/>
            <body name="scapphant_l" pos="-0.00955 -0.034 -0.009">
              <inertial pos="0 0 0" mass="0.001" diaginertia="1 1 1"/>
              <joint name="unrothum_r1_l" pos="0 0 0" axis="-0.6377 -0.1186 0.7611" limited="false" range="-100000 100000" user="-0.0932007"/>
              <joint name="unrothum_r3_l" pos="0 0 0" axis="0.754084 -0.297594 0.585487" limited="false" range="-100000 100000" user="-0.207346"/>
              <joint name="unrothum_r2_l" pos="0 0 0" axis="-0.157095 -0.947269 -0.279291" limited="false" range="-100000 100000" user="0.0256564"/>
              <body name="humphant_l">
                <inertial pos="0 0 0" mass="0.001" diaginertia="1 1 1"/>
                <joint name="elv_angle_l" pos="0 0 0" axis="-0.00479995 -0.999089 0.0423995" range="-1.658 2.269" user="3.57241e-09"/>
                <body name="humphant1_l">
                  <inertial pos="0 0 0" mass="0.001" diaginertia="1 1 1"/>
                  <joint name="shoulder_elv_l" pos="0 0 0" axis="0.998261 -0.00229991 0.0588977" range="0 3.142" user="0.523599"/>
                  <joint name="shoulder1_r2_l" pos="0 0 0" axis="-0.00479995 -0.999089 0.0423995" limited="false" range="-100000 100000" user="-3.57241e-09"/>
                  <body name="humerus_l">
                    <inertial pos="0.018064 -0.140141 0.012746" quat="0.407851 0.343714 -0.567755 0.627034" mass="1.99757" diaginertia="0.0128576 0.0121576 0.00239265"/>
                    <joint name="shoulder_rot_l" pos="0 0 0" axis="-0.00479995 -0.999089 0.0423995" range="-1.571 2.094" user="-2.38098e-09"/>
                    <geom name="humerus_l_geom_1" type="mesh" rgba="1 1 1 1" mesh="humerus_l_geom_1_humerus_mirror"/>
                    <body name="ulna_l" pos="0.0061 -0.2904 0.0123">
                      <inertial pos="0.00971783 -0.0959509 -0.024286" quat="0.792048 0.609078 0.0156735 0.0379256" mass="1.1053" diaginertia="0.00543663 0.00523521 0.001"/>
                      <joint name="elbow_flexion_l" pos="0 0 0" axis="-0.0494004 -0.0366003 0.998108" range="0 2.269" user="1.5708"/>
                      <geom name="ulna_l_geom_1" type="mesh" rgba="1 1 1 1" mesh="ulna_l_geom_1_ulna_mirror"/>
                      <body name="radius_l" pos="0.0004 -0.0115 -0.02">
                        <inertial pos="0.0336341 -0.181559 -0.0156" quat="0.770264 0.63559 0.0119833 0.0507376" mass="0.23359" diaginertia="0.001 0.001 0.001"/>
                        <joint name="pro_sup_l" pos="0 0 0" axis="0.0171593 -0.992662 -0.119695" range="-1.571 1.571" user="-2e-08"/>
                        <geom name="radius_l_geom_1" type="mesh" rgba="1 1 1 1" mesh="radius_l_geom_1_radius_mirror"/>
                        <body name="proximal_row_l" pos="0.018 -0.242 -0.025">
                          <inertial pos="0 0 0" mass="0.001" diaginertia="0.001 0.001 0.001"/>
                          <joint name="deviation_l" pos="0 0 0" axis="0.819097 0.1356 -0.557398" range="-0.1745 0.4363" user="0"/>
                          <joint name="flexion_l" pos="0 0 0" axis="-0.956427 0.252207 0.147104" range="-0.6109 0.6109"/>
                          <geom name="proximal_row_l_geom_1" type="mesh" rgba="1 1 1 1" mesh="proximal_row_l_geom_1_lunate_mirror"/>
                          <geom name="proximal_row_l_geom_2" type="mesh" rgba="1 1 1 1" mesh="proximal_row_l_geom_2_sdfastSCAPHOIDw_mirror"/>
                          <geom name="proximal_row_l_geom_3" type="mesh" rgba="1 1 1 1" mesh="proximal_row_l_geom_3_sdfastPISIFORMw_mirror"/>
                          <geom name="proximal_row_l_geom_4" type="mesh" rgba="1 1 1 1" mesh="proximal_row_l_geom_4_sdfastTRIQUETRALw_mirror"/>
                          <body name="hand_l" pos="0.003992 -0.01505 -0.002327">
                            <inertial pos="-0.00301314 -0.0424993 0.00112205" quat="0.526799 0.470642 -0.462095 0.536141" mass="0.5819" diaginertia="0.001 0.001 0.001"/>
                            <joint name="wrist_hand_r1_l" pos="0 0 0" axis="-0.899124 0.349109 -0.264007" limited="false" range="-100000 100000"/>
                            <joint name="wrist_hand_r3_l" pos="0 0 0" axis="-0.997118 -0.0107002 -0.0751014" limited="false" range="-100000 100000"/>
                            <geom name="hand_l_geom_1" type="mesh" rgba="1 1 1 1" mesh="hand_l_geom_1_sdfast_1seg_hand_fr_c_5mc_mirror"/>
                            <geom name="hand_l_geom_2" type="mesh" rgba="1 1 1 1" mesh="hand_l_geom_2_sdfast_1seg_hand_fr_c_4mc_mirror"/>
                            <geom name="hand_l_geom_3" type="mesh" rgba="1 1 1 1" mesh="hand_l_geom_3_sdfast_1seg_hand_fr_c_3mc_mirror"/>
                            <geom name="hand_l_geom_4" type="mesh" rgba="1 1 1 1" mesh="hand_l_geom_4_sdfast_1seg_hand_fr_c_2mc_mirror"/>
                            <geom name="hand_l_geom_5" type="mesh" rgba="1 1 1 1" mesh="hand_l_geom_5_sdfast_1seg_hand_fr_c_trapezium_mirror"/>
                            <geom name="hand_l_geom_6" type="mesh" rgba="1 1 1 1" mesh="hand_l_geom_6_sdfast_1seg_hand_fr_c_trapezoid_mirror"/>
                            <geom name="hand_l_geom_7" type="mesh" rgba="1 1 1 1" mesh="hand_l_geom_7_sdfast_1seg_hand_fr_c_hamate_mirror"/>
                            <geom name="hand_l_geom_8" type="mesh" rgba="1 1 1 1" mesh="hand_l_geom_8_capitate_mirror"/>
                            <geom name="hand_l_geom_9" type="mesh" rgba="1 1 1 1" mesh="hand_l_geom_9_hand_2proxph_mirror"/>
                            <geom name="hand_l_geom_10" type="mesh" rgba="1 1 1 1" mesh="hand_l_geom_10_hand_2midph_mirror"/>
                            <geom name="hand_l_geom_11" type="mesh" rgba="1 1 1 1" mesh="hand_l_geom_11_hand_2distph_mirror"/>
                            <geom name="hand_l_geom_12" type="mesh" rgba="1 1 1 1" mesh="hand_l_geom_12_hand_3proxph_mirror"/>
                            <geom name="hand_l_geom_13" type="mesh" rgba="1 1 1 1" mesh="hand_l_geom_13_hand_3midph_mirror"/>
                            <geom name="hand_l_geom_14" type="mesh" rgba="1 1 1 1" mesh="hand_l_geom_14_hand_3distph_mirror"/>
                            <geom name="hand_l_geom_15" type="mesh" rgba="1 1 1 1" mesh="hand_l_geom_15_hand_4proxph_mirror"/>
                            <geom name="hand_l_geom_16" type="mesh" rgba="1 1 1 1" mesh="hand_l_geom_16_hand_4midph_mirror"/>
                            <geom name="hand_l_geom_17" type="mesh" rgba="1 1 1 1" mesh="hand_l_geom_17_hand_4distph_mirror"/>
                            <geom name="hand_l_geom_18" type="mesh" rgba="1 1 1 1" mesh="hand_l_geom_18_hand_5proxph_mirror"/>
                            <geom name="hand_l_geom_19" type="mesh" rgba="1 1 1 1" mesh="hand_l_geom_19_hand_5midph_mirror"/>
                            <geom name="hand_l_geom_20" type="mesh" rgba="1 1 1 1" mesh="hand_l_geom_20_hand_5distph_mirror"/>
                            <geom name="hand_l_geom_21" type="mesh" rgba="1 1 1 1" mesh="hand_l_geom_21_hand_thumbprox_mirror"/>
                            <geom name="hand_l_geom_22" type="mesh" rgba="1 1 1 1" mesh="hand_l_geom_22_hand_thumbdist_mirror"/>
                            <geom name="hand_l_geom_23" type="mesh" rgba="1 1 1 1" mesh="hand_l_geom_23_hand_1mc_mirror"/>
                          </body>
                        </body>
                      </body>
                    </body>
                  </body>
                </body>
              </body>
            </body>
          </body>
        </body>
      </body>
    </body>
  </worldbody>
  <contact>
    <pair geom1="controller-right" geom2="controller-left" name="controllers"/>
    <pair geom1="controller-right" geom2="headset" name="headset-controller-right"/>
    <pair geom1="controller-left" geom2="headset" name="headset-controller-left"/>
    <exclude body1="controller-right" body2="hand_r"/>
    <exclude body1="controller-left" body2="hand_l"/>
    <exclude body1="headset" body2="skull"/>
  </contact>
  <equality>
    <weld name="controller-right-weld" body1="controller-right" body2="hand_r" anchor="0 0 0" torquescale="1" relpose="-0.066941 -0.00423279 0.00806701 0.793495 0.492387 -0.249414 0.256346"/>
    <weld name="controller-left-weld" body1="controller-left" body2="hand_l" anchor="0 0 0" torquescale="1" relpose="-0.0677774 0.0222477 0.00873933 0.53829 0.72938 -0.371539 0.200518"/>
    <weld name="headset-weld" body1="headset" body2="skull" anchor="0 0 0" torquescale="1" relpose="-0.10703 0.001594 -0.19141 0.707107 0.707107 0 0"/>
    <joint name="sternoclavicular_r2_con_r" joint1="sternoclavicular_r2_r" joint2="shoulder_elv_r" polycoef="0 -0.242 0 0 0" solimp="0.9999 0.9999 0.001 0.5 2"/>
    <joint name="sternoclavicular_r3_con_r" joint1="sternoclavicular_r3_r" joint2="shoulder_elv_r" polycoef="0 0.1025 0 0 0" solimp="0.9999 0.9999 0.001 0.5 2"/>
    <joint name="unrotscap_r2_con_r" joint1="unrotscap_r2_r" joint2="shoulder_elv_r" polycoef="0 0.242 0 0 0" solimp="0.9999 0.9999 0.001 0.5 2"/>
    <joint name="unrotscap_r3_con_r" joint1="unrotscap_r3_r" joint2="shoulder_elv_r" polycoef="0 -0.1025 0 0 0" solimp="0.9999 0.9999 0.001 0.5 2"/>
    <joint name="acromioclavicular_r1_con_r" joint1="acromioclavicular_r1_r" joint2="shoulder_elv_r" polycoef="0 0.178 0 0 0" solimp="0.9999 0.9999 0.001 0.5 2"/>
    <joint name="acromioclavicular_r2_con_r" joint1="acromioclavicular_r2_r" joint2="shoulder_elv_r" polycoef="0 -0.049 0 0 0" solimp="0.9999 0.9999 0.001 0.5 2"/>
    <joint name="acromioclavicular_r3_con_r" joint1="acromioclavicular_r3_r" joint2="shoulder_elv_r" polycoef="0 0.396 0 0 0" solimp="0.9999 0.9999 0.001 0.5 2"/>
    <joint name="unrothum_r1_con_r" joint1="unrothum_r1_r" joint2="shoulder_elv_r" polycoef="0 -0.178 0 0 0" solimp="0.9999 0.9999 0.001 0.5 2"/>
    <joint name="unrothum_r2_con_r" joint1="unrothum_r2_r" joint2="shoulder_elv_r" polycoef="0 0.049 0 0 0" solimp="0.9999 0.9999 0.001 0.5 2"/>
    <joint name="unrothum_r3_con_r" joint1="unrothum_r3_r" joint2="shoulder_elv_r" polycoef="0 -0.396 0 0 0" solimp="0.9999 0.9999 0.001 0.5 2"/>
    <joint name="shoulder1_r2_con_r" joint1="shoulder1_r2_r" joint2="elv_angle_r" polycoef="0 -1 0 0 0" solimp="0.9999 0.9999 0.001 0.5 2"/>
    <joint name="wrist_hand_r1_con_r" joint1="wrist_hand_r1_r" joint2="deviation_r" polycoef="0 1.357 -0.8185 0 0" solimp="0.9999 0.9999 0.001 0.5 2"/>
    <joint name="wrist_hand_r3_con_r" joint1="wrist_hand_r3_r" joint2="flexion_r" polycoef="0 1 0 0 0" solimp="0.9999 0.9999 0.001 0.5 2"/>
    <joint name="sternoclavicular_r2_con_l" joint1="sternoclavicular_r2_l" joint2="shoulder_elv_l" polycoef="0 -0.242 0 0 0" solimp="0.9999 0.9999 0.001 0.5 2"/>
    <joint name="sternoclavicular_r3_con_l" joint1="sternoclavicular_r3_l" joint2="shoulder_elv_l" polycoef="0 0.1025 0 0 0" solimp="0.9999 0.9999 0.001 0.5 2"/>
    <joint name="unrotscap_r2_con_l" joint1="unrotscap_r2_l" joint2="shoulder_elv_l" polycoef="0 0.242 0 0 0" solimp="0.9999 0.9999 0.001 0.5 2"/>
    <joint name="unrotscap_r3_con_l" joint1="unrotscap_r3_l" joint2="shoulder_elv_l" polycoef="0 -0.1025 0 0 0" solimp="0.9999 0.9999 0.001 0.5 2"/>
    <joint name="acromioclavicular_r1_con" joint1="acromioclavicular_r1_l" joint2="shoulder_elv_l" polycoef="0 0.178 0 0 0" solimp="0.9999 0.9999 0.001 0.5 2"/>
    <joint name="acromioclavicular_r2_con_l" joint1="acromioclavicular_r2_l" joint2="shoulder_elv_l" polycoef="0 -0.049 0 0 0" solimp="0.9999 0.9999 0.001 0.5 2"/>
    <joint name="acromioclavicular_r3_con_l" joint1="acromioclavicular_r3_l" joint2="shoulder_elv_l" polycoef="0 0.396 0 0 0" solimp="0.9999 0.9999 0.001 0.5 2"/>
    <joint name="unrothum_r1_con_l" joint1="unrothum_r1_l" joint2="shoulder_elv_l" polycoef="0 -0.178 0 0 0" solimp="0.9999 0.9999 0.001 0.5 2"/>
    <joint name="unrothum_r2_con_l" joint1="unrothum_r2_l" joint2="shoulder_elv_l" polycoef="0 0.049 0 0 0" solimp="0.9999 0.9999 0.001 0.5 2"/>
    <joint name="unrothum_r3_con_l" joint1="unrothum_r3_l" joint2="shoulder_elv_l" polycoef="0 -0.396 0 0 0" solimp="0.9999 0.9999 0.001 0.5 2"/>
    <joint name="shoulder1_r2_con_l" joint1="shoulder1_r2_l" joint2="elv_angle_l" polycoef="0 -1 0 0 0" solimp="0.9999 0.9999 0.001 0.5 2"/>
    <joint name="wrist_hand_r1_con_l" joint1="wrist_hand_r1_l" joint2="deviation_l" polycoef="0 1.357 -0.8185 0 0" solimp="0.9999 0.9999 0.001 0.5 2"/>
    <joint name="wrist_hand_r3_con_l" joint1="wrist_hand_r3_l" joint2="flexion_l" polycoef="0 1 0 0 0" solimp="0.9999 0.9999 0.001 0.5 2"/>
    <joint name="t_x_locked" joint1="t_x" polycoef="0 0 0 0 0" solimp="0.9999 0.9999 0.001 0.5 2"/>
    <joint name="t_y_locked" joint1="t_y" polycoef="0 0 0 0 0" solimp="0.9999 0.9999 0.001 0.5 2"/>
    <joint name="t_z_locked" joint1="t_z" polycoef="0 0 0 0 0" solimp="0.9999 0.9999 0.001 0.5 2"/>
    <joint name="r_x_locked" joint1="r_x" polycoef="0 0 0 0 0" solimp="0.9999 0.9999 0.001 0.5 2"/>
    <joint name="r_y_locked" joint1="r_y" polycoef="0 0 0 0 0" solimp="0.9999 0.9999 0.001 0.5 2"/>
    <joint name="r_z_locked" joint1="r_z" polycoef="0 0 0 0 0" solimp="0.9999 0.9999 0.001 0.5 2"/>
  </equality>
  <actuator>
    <general name="elv_angle_motor_r" joint="elv_angle_r" ctrlrange="-1.658 2.269" biastype="affine" gainprm="100 0 0 0 0 0 0 0 0 0" biasprm="0 -100 -30 0 0 0 0 0 0 0"/>
    <general name="shoulder_elv_motor_r" joint="shoulder_elv_r" ctrlrange="0 3.14" biastype="affine" gainprm="100 0 0 0 0 0 0 0 0 0" biasprm="0 -100 -20 0 0 0 0 0 0 0"/>
    <general name="shoulder_rot_motor_r" joint="shoulder_rot_r" ctrlrange="-1.571 2.094" biastype="affine" gainprm="20 0 0 0 0 0 0 0 0 0" biasprm="0 -20 -2 0 0 0 0 0 0 0"/>
    <general name="elbow_flexion_motor_r" joint="elbow_flexion_r" ctrlrange="0 2.269" biastype="affine" gainprm="20 0 0 0 0 0 0 0 0 0" biasprm="0 -20 -2 0 0 0 0 0 0 0"/>
    <general name="pro_sup_motor_r" joint="pro_sup_r" ctrlrange="-1.571 1.571" biastype="affine" gainprm="20 0 0 0 0 0 0 0 0 0" biasprm="0 -20 -1 0 0 0 0 0 0 0"/>
    <general name="deviation_motor_r" joint="deviation_r" ctrlrange="-0.1745 0.4363" biastype="affine" gainprm="10 0 0 0 0 0 0 0 0 0" biasprm="0 -10 -0.5 0 0 0 0 0 0 0"/>
    <general name="flexion_motor_r" joint="flexion_r" ctrlrange="-0.6109 0.6109" biastype="affine" gainprm="10 0 0 0 0 0 0 0 0 0" biasprm="0 -10 -0.5 0 0 0 0 0 0 0"/>
    <general name="elv_angle_motor_l" joint="elv_angle_l" ctrlrange="-1.658 2.269" biastype="affine" gainprm="100 0 0 0 0 0 0 0 0 0" biasprm="0 -100 -30 0 0 0 0 0 0 0"/>
    <general name="shoulder_elv_motor_l" joint="shoulder_elv_l" ctrlrange="0 3.14" biastype="affine" gainprm="100 0 0 0 0 0 0 0 0 0" biasprm="0 -100 -20 0 0 0 0 0 0 0"/>
    <general name="shoulder_rot_motor_l" joint="shoulder_rot_l" ctrlrange="-1.571 2.094" biastype="affine" gainprm="20 0 0 0 0 0 0 0 0 0" biasprm="0 -20 -2 0 0 0 0 0 0 0"/>
    <general name="elbow_flexion_motor_l" joint="elbow_flexion_l" ctrlrange="0 2.269" biastype="affine" gainprm="20 0 0 0 0 0 0 0 0 0" biasprm="0 -20 -2 0 0 0 0 0 0 0"/>
    <general name="pro_sup_motor_l" joint="pro_sup_l" ctrlrange="-1.571 1.571" biastype="affine" gainprm="20 0 0 0 0 0 0 0 0 0" biasprm="0 -20 -1 0 0 0 0 0 0 0"/>
    <general name="deviation_motor_l" joint="deviation_l" ctrlrange="-0.1745 0.4363" biastype="affine" gainprm="10 0 0 0 0 0 0 0 0 0" biasprm="0 -10 -0.5 0 0 0 0 0 0 0"/>
    <general name="flexion_motor_l" joint="flexion_l" ctrlrange="-0.6109 0.6109" biastype="affine" gainprm="10 0 0 0 0 0 0 0 0 0" biasprm="0 -10 -0.5 0 0 0 0 0 0 0"/>
  </actuator>
</mujoco>
