<?xml version="1.0"?>
<mujoco>    
    <asset>
        <texture type="skybox" builtin="gradient" rgb1="1 1 1" rgb2="0.6 0.8 1" width="256" height="256" />
        <!-- The referenced .stl files were self-created using OpenSCAD. -->
        <mesh name="chassis" file="assets/car/chassis.stl" />
        <mesh name="steering_rack" file="assets/car/steering_rack.stl" />
        <mesh name="steering_gear" file="assets/car/gear.stl" />
        <mesh name="suspension_part1" file="assets/car/suspension_part1.stl" />
        <mesh name="suspension_part2" file="assets/car/suspension_part2.stl" />
        
        <material name="matcont_body" rgba="0.749 0.749 0.749 1" reflectance="0" shininess="0" />
        <material name="matte_rubber" rgba="0 0 0 1" specular="0" />

        <!-- The referenced .stl files were self-created using OpenSCAD. -->
        <mesh name="controller_body" file="assets/gamepad/controller_body.stl" />
        <mesh name="d_pad" file="assets/gamepad/d_pad.stl" />
        <mesh name="thumb_stick" file="assets/gamepad/thumb_stick.stl" />
        <mesh name="button" file="assets/gamepad/game_action_button.stl" />
    </asset>

    <worldbody>
        <light name="scene_directional_light" directional="true" castshadow="false" cutoff="4" exponent="20" diffuse="1 1 1" specular="0 0 0" pos=".9 .3 2.5" />
        <body name="ground_body">
            <geom name="ground" type="plane" pos="0 0 0" size="10 10 1" rgba=" .25 .26 .25 1" />
        </body>
        <body name="target">
            <geom name="target" type="box" pos="0.0 0.0 0.0" size="0.5 0.3 0.5" rgba=" 0 .9 0 0.5" gap="100" margin = "-100"/>
        </body>
        
        <body name="target-plane">
            <geom name="target-plane" type="box" size="0.005 0.3 0.3" rgba="0.1 0.8 0.1 0.0" contype = "0" conaffinity="0"/>
        </body>

        <camera name="scene_complete" pos="-2 -2 2" mode="targetbody" target="ground_body"/>
        <camera name="gamepad" pos="-0.1 0 0.6" mode="targetbody" target="gamepad"/>

        <body pos="1 0 0.065" name="car" euler="0 0 -1.57">
            <camera name="car_third_person" fovy="80" pos="0 -0.5 0.4" euler="1 0 0" />
            <geom type="mesh" mesh="chassis" pos="0 0.2 0" mass="1" rgba="1 0 0 0.4"/>
            <!-- <body name="steering-motor" pos="0 0.14 0.001"> -->
                <!-- <geom type="box" mass="1" size="0.008 0.02 0.006" rgba="0 0 0 1"/> -->
                <!-- <body name="steering-motor-axle" pos="0 0.02 0"> -->
                    <!-- <geom type="cylinder" mass="1" size="0.0025 0.015" euler="1.57 0 0" rgba="0.4 0.4 0.4 1"/> -->
                <!-- </body> -->
            <!-- </body> -->
            <body pos="0 -0.12 -0.03" name="axis-back">
                <geom type="cylinder" mass="1" size="0.015 0.12" euler="1.57 1.57 0" rgba="0.6 0.6 0.6 1"/>
                <body pos="0.105 0 0" name="wheel1">
                    <geom name="wheel1" type="cylinder" mass="1" size="0.035 0.01" euler="1.57 1.57 0" rgba="0 0 0 1" friction="3 1 0.5"/>
                </body>
                <body pos="-0.105 0 0" name="wheel2">
                    <geom name="wheel2" type="cylinder" mass="1" size="0.035 0.01" euler="1.57 1.57 0" rgba="0 0 0 1" friction="3 1 0.5"/>
                </body>
                <joint type="hinge" name="axis-back:rot-x" axis="1 0 0" limited="false" stiffness="0" damping="0.1" />
            </body>
            <!-- <body pos="0 0.175 0.001" name="steering_gear" euler="0 0.16 0"> -->
                <!-- <geom type="mesh" mesh="steering_gear" rgba="0.749 0.749 0.749 1" /> -->
                <!-- <joint type="hinge" name="steering_gear:rot-y" axis="0 1 0" limited="false" damping="0.1" /> -->
            <!-- </body> -->
            <!-- <body pos="0.08 0.135 -0.03" name="wheel3-suspension1"> -->
                <!-- <geom type="mesh" mesh="suspension_part1" rgba="0.749 0.749 0.749 1" /> -->
                <!-- <body pos="0.036 0.01 0" name="wheel3-suspension2"> -->
                    <!-- <joint type="hinge" name="wheel3-suspension_part1:rot-z" pos="-0.023 -0.005 0" axis="0 0 1" limited="true" range="-0.2 0.2" damping="0.8" /> -->
                    <!-- <geom type="mesh" mesh="suspension_part2" rgba="0.749 0.749 0.749 1" /> -->
                    <!-- <body pos="0.01 -0.005 0.005" name="wheel3"> -->
                        <!-- <geom name="wheel3" type="cylinder"  mass="1" size="0.035 0.008" euler="1.57 1.57 0" rgba="0 0 0 1" friction="3 1 0.5"/> -->
                        <!-- <joint type="hinge" name="wheel3:rot-x" axis="1 0 0" limited="false" damping="0.1" /> -->
                    <!-- </body> -->
                    <!-- <body pos="-0.116 0.03 0.01" name="steering_rack"> -->
                        <!-- <joint type="hinge" name="steering_rack:rot1-z" pos="0.091 -0.005 0" axis="0 0 1" limited="false" damping="0.8" /> -->
                        <!-- <geom type="mesh" mesh="steering_rack" rgba="0.749 0.749 0.749 1" /> -->
                    <!-- </body> -->
                <!-- </body> -->
            <!-- </body> -->
            <!-- <body pos="-0.08 0.135 -0.02" euler="3.14 0 3.14" name="wheel4-suspension1"> -->
                <!-- <geom type="mesh" mesh="suspension_part1" rgba="0.749 0.749 0.749 1" /> -->
                <!-- <body pos="0.036 0.01 0" name="wheel4-suspension2"> -->
                    <!-- <joint type="hinge" name="wheel4-suspension_part1:rot-z" pos="-0.023 -0.005 0" axis="0 0 1" limited="false" damping="0.8" /> -->
                    <!-- <geom type="mesh" mesh="suspension_part2" rgba="0.749 0.749 0.749 1" /> -->
                    <!-- <body pos="0.01 -0.005 0.005" name="wheel4"> -->
                        <!-- <geom name="wheel4" type="cylinder" mass="1" size="0.035 0.008" euler="1.57 1.57 0" rgba="0 0 0 1" friction="3 1 0.5"/> -->
                        <!-- <joint type="hinge" name="wheel4:rot-x" axis="1 0 0" limited="false" damping="0.1" /> -->
                    <!-- </body> -->
                <!-- </body> -->
            <!-- </body> -->
			<body pos="0 0.14 -0.03" name="axis-front">
                <geom type="cylinder" mass="1" size="0.015 0.12" euler="1.57 1.57 0" rgba="0.6 0.6 0.6 1"/>
                <body pos="0.105 0 0" name="wheel3">
                    <geom name="wheel3" type="cylinder" mass="1" size="0.035 0.01" euler="1.57 1.57 0" rgba="0 0 0 1" friction="3 1 0.5"/>
                </body>
                <body pos="-0.105 0 0" name="wheel4">
                    <geom name="wheel4" type="cylinder" mass="1" size="0.035 0.01" euler="1.57 1.57 0" rgba="0 0 0 1" friction="3 1 0.5"/>
                </body>
                <joint type="hinge" name="axis-front:rot-x" axis="1 0 0" limited="false" stiffness="0" damping="0.1" />
            </body>
			<!-- <body pos="0.126 0.14 -0.025" name="wheel3"> -->
				<!-- <geom name="wheel3" type="cylinder"  mass="1" size="0.035 0.008" euler="1.57 1.57 0" rgba="0 0 0 1" friction="3 1 0.5"/> -->
				<!-- <joint type="hinge" name="wheel3:rot-x" axis="1 0 0" limited="false" damping="0.1" /> -->
			<!-- </body> -->
			<!-- <body pos="-0.034 0.14 -0.015" name="wheel4"> -->
				<!-- <geom name="wheel4" type="cylinder" mass="1" size="0.035 0.008" euler="1.57 1.57 0" rgba="0 0 0 1" friction="3 1 0.5"/> -->
				<!-- <joint type="hinge" name="wheel4:rot-x" axis="1 0 0" limited="false" damping="0.1" /> -->
			<!-- </body> -->
            <!-- <joint damping="0" stiffness="0" armature="0" limited="false" type="free" name="car"></joint> -->
			<joint damping="0" stiffness="0" armature="0" springdamper="0 0" name="car" limited="true" type="slide" axis="0 1 0" range="-0.5 6.5"></joint>
			<!-- <joint damping="0" limited="false" type="hinge" axis="1 0 0" range="-0.5 8.5"></joint> -->
			<!-- <joint damping="0" limited="true" type="slide" axis="1 0 0" range="-0.5 8.5"></joint> -->
			<!-- <joint damping="0" limited="true" type="slide" axis="0 0 1" range="-0.5 8.5"></joint> -->
        </body>
        
         <body name="gamepad" pos="0.4 -0.15 0.5" euler="0 -0.79 -1.57">
			<camera name="controller_front" pos="0 0.2 0.5" euler="-1 0 3.14"/>
			<camera name="controller_top" pos="0 0 0.5" />
			<camera name="controller_back" pos="0 0 0.5" euler="1 0 0" />
            <!-- This extra body is needed, because the buttons can not collide with "controller-base". -->
            <body name="sensor-wrapper" pos="0 0 0.025">
                <!-- The geometries are needed due to the way the "touch" sensors are working. 
                They sense any collision within their sites volume. -->
                <site name="button-1-contact-point" type="sphere" size="0.0015" pos="0.1275 0.01 0.0175" />
                <geom type="sphere" size="0.001" pos="0.1275 0.01 0.0175" />
                <site name="button-2-contact-point" type="sphere" size="0.0015" pos="0.14375 -0.0025 0.0175" />
                <geom type="sphere" size="0.001" pos="0.14375 -0.0025 0.0175" />
                <site name="button-3-contact-point" type="sphere" size="0.0015" pos="0.14186332 0.022052262 0.0175" />
                <geom type="sphere" size="0.001" pos="0.14186332 0.022052262 0.0175" />
                <site name="button-4-contact-point" type="sphere" size="0.0015" pos="0.15811333 0.009552263 0.0175" />
                <geom type="sphere" size="0.001" pos="0.15811333 0.009552263 0.0175" />

                <site name="d_pad-contact-1" type="sphere" size="0.0015" pos="-0.004 -0.010624999 0.014374999" />
                <geom type="sphere" size="0.001" pos="-0.004 -0.010624999 0.014374999" />
                <site name="d_pad-contact-2" type="sphere" size="0.0015" pos="0.013374999 0.00675 0.014374999" />
                <geom type="sphere" size="0.001" pos="0.013374999 0.00675 0.014374999" />
                <site name="d_pad-contact-3" type="sphere" size="0.0015" pos="-0.004 0.024125 0.014374999" />
                <geom type="sphere" size="0.001" pos="-0.004 0.024125 0.014374999" />
                <site name="d_pad-contact-4" type="sphere" size="0.0015" pos="-0.021375 0.00675 0.014374999" />
                <geom type="sphere" size="0.001" pos="-0.021375 0.00675 0.014374999" />
            </body>

            <body name="controller-base" pos="0 0 0.025">
                <geom type="mesh" mesh="controller_body" rgba="0.749 0.749 0.749 1" />
            </body>
            <body name="d-pad" pos="-0.004 0.00675 0.0442">
                <geom type="mesh" mesh="d_pad" mass="1" rgba="0 0 0 1" />
                <joint type="hinge" name="d_pad:rot-x" axis="1 0 0" limited="true" range="-5 5" damping="10" springref="0" stiffness="500" />
                <joint type="hinge" name="d_pad:rot-y" axis="0 1 0" limited="true" range="-5 5" damping="10" springref="0" stiffness="500" />
            </body>
			<!-- <geom name="thumb-stick-1-virtual" pos="0.0275 -0.0225 0.089375" type="sphere" size="0.005" mass="0.0005" rgba="1 0 0 0" contype="0" conaffinity="0"/> -->
            <body name="thumb-stick-1" pos="0.0275 -0.0225 0.039375">
				<geom name="thumb-stick-1-virtual" pos="0 0 0.08" type="cylinder" size="0.0125 0.001" mass="0.0005" rgba="1 0 0 0" contype="0" conaffinity="0"/>
                <geom name="thumb-stick-1" type="mesh" mesh="thumb_stick" mass="0.0005" rgba="0 0 0 1" friction="0.84"/>
                <joint type="hinge" name="thumb-stick-1:rot-x" axis="1 0 0" limited="true" range="-0.349 0.349" damping="0.5" springref="0" stiffness="1" />
                <!-- <joint type="hinge" name="thumb-stick-1:rot-y" axis="0 1 0" limited="true" range="-20 20" damping="0.5" springref="0" stiffness="1" /> -->
            </body>
            <body name="thumb-stick-2" pos="0.112500004 -0.0225 0.039375">
                <geom name="thumb-stick-2" type="mesh" mesh="thumb_stick" mass="0.0005" rgba="0 0 0 1" friction="0.84"/>
                <joint type="hinge" name="thumb-stick-2:rot-x" axis="1 0 0" limited="true" range="-0.349 0.349" damping="0.5" springref="0" stiffness="0.5" />
                <!-- <joint type="hinge" name="thumb-stick-2:rot-y" axis="0 1 0" limited="true" range="-20 20" damping="0.5" springref="0" stiffness="0.5" /> -->
            </body>
            <body name="control-buttons">
                <body name="button-1" pos="0.1275 0.01 0.05">
                    <geom type="mesh" mesh="button" mass="0.0005" rgba="0 1 0 1" />
                    <joint axis="0 0 1" name="button-1:slide-z" type="slide" limited="true" range="-0.0045 0" springref="0" stiffness="0.5" damping="0.5" />
                </body>
                <body name="button-2" pos="0.14375 -0.0025 0.05">
                    <geom type="mesh" mesh="button" mass="0.0005" rgba="1 1 0 1" />
                    <joint axis="0 0 1" name="button-2:slide-z" type="slide" limited="true" range="-0.0045 0" springref="0" stiffness="0.5" damping="0.5" />
                </body>
                <body name="button-3" pos="0.14186332 0.022052262 0.05">
                    <geom type="mesh" mesh="button" mass="0.0005" rgba="0 0 1 1" />
                    <joint axis="0 0 1" name="button-3:slide-z" type="slide" limited="true" range="-0.0045 0" springref="0" stiffness="0.5" damping="0.5" />
                </body>
                <body name="button-4" pos="0.15811333 0.009552263 0.05">
                    <geom type="mesh" mesh="button" mass="0.0005" rgba="1 0 0 1" />
                    <joint axis="0 0 1" name="button-4:slide-z" type="slide" limited="true" range="-0.0045 0" springref="0" stiffness="0.5" damping="0.5" />
                </body>
            </body>
        </body>
    </worldbody>

	<equality>
		<!-- INFO: "hand_2distph" geometry needs to be included in human body model. -->
		<distance  name="fingertip_to_joystick" geom1="hand_2distph" geom2="thumb-stick-1-virtual" active="false" />
	</equality>

    <contact>
        <!-- Prevent individual controller parts from colliding. -->
        <exclude body1="car" body2="axis-back"></exclude>

        <exclude body1="axis-back" body2="wheel1"></exclude>
        <exclude body1="axis-back" body2="wheel2"></exclude>

        <exclude body1="car" body2="axis-front"></exclude>
		
		<exclude body1="axis-front" body2="wheel3"></exclude>
        <exclude body1="axis-front" body2="wheel4"></exclude>

        <!-- <exclude body1="steering_rack" body2="wheel4-suspension2"></exclude> -->
        
        <!-- Prevent individual controller parts from colliding. -->
        <exclude body1="button-1" body2="controller-base"></exclude>
		<exclude body1="button-2" body2="controller-base"></exclude>
		<exclude body1="button-3" body2="controller-base"></exclude>
        <exclude body1="button-4" body2="controller-base"></exclude>

        <exclude body1="thumb-stick-1" body2="controller-base"></exclude>
        <exclude body1="thumb-stick-2" body2="controller-base"></exclude>
        <exclude body1="d-pad" body2="controller-base"></exclude>
        
        <pair geom1="wheel1" geom2="target" margin="100" gap="200"/>
        <pair geom1="wheel2" geom2="target" margin="100" gap="200"/>
        <pair geom1="wheel3" geom2="target" margin="100" gap="200"/>
        <pair geom1="wheel4" geom2="target" margin="100" gap="200"/>
		
		<pair geom1="wheel1" geom2="ground" />
		<pair geom1="wheel2" geom2="ground" />
		<pair geom1="wheel3" geom2="ground" />
		<pair geom1="wheel4" geom2="ground" />
    </contact>
    
    <!-- <equality> -->
        <!-- <joint joint1="wheel3-suspension_part1:rot-z" joint2="wheel4-suspension_part1:rot-z" polycoef="0 -1 0 0 0"></joint> -->
        <!-- <joint joint1="wheel3-suspension_part1:rot-z" joint2="steering_rack:rot1-z" polycoef="0 -1 0 0 0"></joint> -->
    <!-- </equality> -->

    <!-- <sensor> -->
        <!-- <jointpos name="thumb-stick-1-x" joint="thumb-stick-1:rot-x" /> -->
        <!-- <jointpos name="thumb-stick-1-y" joint="thumb-stick-1:rot-y" /> -->
        <!-- <jointpos name="thumb-stick-2-x" joint="thumb-stick-2:rot-x" /> -->
        <!-- <jointpos name="thumb-stick-2-y" joint="thumb-stick-2:rot-y" /> -->

        <!-- <touch name="button1-sensor" site="button-1-contact-point" /> -->
        <!-- <touch name="button2-sensor" site="button-2-contact-point" /> -->
        <!-- <touch name="button3-sensor" site="button-3-contact-point" /> -->
        <!-- <touch name="button4-sensor" site="button-4-contact-point" /> -->

        <!-- <touch name="dpad-contact1" site="d_pad-contact-1" /> -->
        <!-- <touch name="dpad-contact2" site="d_pad-contact-2" /> -->
        <!-- <touch name="dpad-contact3" site="d_pad-contact-3" /> -->
        <!-- <touch name="dpad-contact4" site="d_pad-contact-4" /> -->
    <!-- </sensor> -->
    
    

</mujoco>