<mujoco model="MoBL_ARMS_Upper_Limb_Model_OpenSim">
    <compiler angle="radian" />
    <option gravity="0 -9.80665 0" collision="predefined" />
    <size njmax="1000" nconmax="400" nuser_jnt="1" />
    <visual>
        <scale framelength="0.1" framewidth="0.01" />
    </visual>
    <default class="main">
        <joint limited="true" stiffness="2" armature="0.1" damping="0.5" />
        <geom margin="0.001" rgba="0.8 0.6 0.4 1" />
        <site size="0.001 0.005 0.005" />
        <tendon rgba="0.95 0.3 0.3 1" />
        <default class="muscle">
            <general ctrllimited="true" ctrlrange="0 1" dyntype="muscle" gaintype="muscle" biastype="muscle" dynprm="0.01 0.04 0 0 0 0 0 0 0 0" gainprm="0.75 1.05 -1 2000 0.5 1.6 1.5 1.3 1.2 0" biasprm="0.75 1.05 -1 2000 0.5 1.6 1.5 1.3 1.2 0" />
        </default>
        <default class="motor">
            <general gainprm="5 0 0 0 0 0 0 0 0 0" />
        </default>
        <default class="oculomotor">
            <general gainprm="1.01 0 0 0 0 0 0 0 0 0" />
        </default>
        <default class="WrapCylinder">
            <geom rgba="0.8 0.5 0.4 0" />
        </default>
        <default class="WrapSphere">
            <geom rgba="0.8 0.5 0.4 0" />
        </default>
        <default class="WrapEllipsoid">
            <geom rgba="0.8 0.5 0.4 0" />
        </default>
        <default class="WrapTorus">
            <geom rgba="0.8 0.5 0.4 0" />
        </default>
    </default>
    <asset>
        <texture type="2d" name="texplane" builtin="checker" rgb1="0.2 0.3 0.4" rgb2="0.1 0.15 0.2" width="100" height="100" />
        <material name="MatPlane" texture="texplane" texuniform="true" />
        <mesh name="thorax" file="Geometry/thorax.stl" />
        <mesh name="clavicle" file="Geometry/clavicle.stl" />
        <mesh name="scapula" file="Geometry/scapula.stl" />
        <mesh name="humerus" file="Geometry/humerus.stl" />
        <mesh name="ulna" file="Geometry/ulna.stl" />
        <mesh name="radius" file="Geometry/radius.stl" />
        <mesh name="lunate" file="Geometry/lunate.stl" />
        <mesh name="sdfastSCAPHOIDw" file="Geometry/sdfastSCAPHOIDw.stl" />
        <mesh name="sdfastPISIFORMw" file="Geometry/sdfastPISIFORMw.stl" />
        <mesh name="sdfastTRIQUETRALw" file="Geometry/sdfastTRIQUETRALw.stl" />
        <mesh name="sdfast_1seg_hand_fr_c_5mc" file="Geometry/sdfast_1seg_hand_fr_c_5mc.stl" />
        <mesh name="sdfast_1seg_hand_fr_c_4mc" file="Geometry/sdfast_1seg_hand_fr_c_4mc.stl" />
        <mesh name="sdfast_1seg_hand_fr_c_3mc" file="Geometry/sdfast_1seg_hand_fr_c_3mc.stl" />
        <mesh name="sdfast_1seg_hand_fr_c_2mc" file="Geometry/sdfast_1seg_hand_fr_c_2mc.stl" />
        <mesh name="sdfast_1seg_hand_fr_c_trapezium" file="Geometry/sdfast_1seg_hand_fr_c_trapezium.stl" />
        <mesh name="sdfast_1seg_hand_fr_c_trapezoid" file="Geometry/sdfast_1seg_hand_fr_c_trapezoid.stl" />
        <mesh name="sdfast_1seg_hand_fr_c_hamate" file="Geometry/sdfast_1seg_hand_fr_c_hamate.stl" />
        <mesh name="capitate" file="Geometry/capitate.stl" />
        <mesh name="hand_2proxph" file="Geometry/hand_2proxph_pointing.stl" />
        <mesh name="hand_2midph" file="Geometry/hand_2midph_pointing.stl" />
        <mesh name="hand_2distph" file="Geometry/hand_2distph_pointing.stl" />
        <mesh name="hand_3proxph" file="Geometry/hand_3proxph.stl" />
        <mesh name="hand_3midph" file="Geometry/hand_3midph.stl" />
        <mesh name="hand_3distph" file="Geometry/hand_3distph.stl" />
        <mesh name="hand_4proxph" file="Geometry/hand_4proxph.stl" />
        <mesh name="hand_4midph" file="Geometry/hand_4midph.stl" />
        <mesh name="hand_4distph" file="Geometry/hand_4distph.stl" />
        <mesh name="hand_5proxph" file="Geometry/hand_5proxph.stl" />
        <mesh name="hand_5midph" file="Geometry/hand_5midph.stl" />
        <mesh name="hand_5distph" file="Geometry/hand_5distph.stl" />
        <mesh name="hand_thumbprox" file="Geometry/hand_thumbprox.stl" />
        <mesh name="hand_thumbdist" file="Geometry/hand_thumbdist.stl" />
        <mesh name="hand_1mc" file="Geometry/hand_1mc.stl" />
    </asset>
    <worldbody>
        <geom name="floor" size="10 10 0.125" type="plane" material="MatPlane" />
        <camera name="for_testing" pos="0 0 0" />
        <body name="eye" pos="0 0 1.2" quat="0.652917 0.271992 -0.272209 -0.652397">
            <inertial pos="0 0 0" mass="0.0654498" diaginertia="0.001 0.001 0.001" />
            <joint name="eye-rx" pos="0 0 0" axis="1 0 0" range="-0.5 1.57" />
            <joint name="eye-ry" pos="0 0 0" axis="0 1 0" range="-1.3 1.3" />
            <geom name="eye-ball" size="0.025" />
            <camera name="oculomotor" pos="0 0 0" fovy="90" />
        </body>
        <body name="target" pos="0.5 0 0.8">
            <inertial pos="0 0 0" mass="0.523599" diaginertia="0.001 0.001 0.001" />
            <geom name="target-sphere" size="0.05" rgba="0.1 0.8 0.1 1" />
        </body>
        <body name="thorax" pos="0 0 0">
            <inertial pos="-0.026681 -0.125639 0.0267491" quat="0.980769 -0.00955952 -0.0466248 0.189278" mass="12.8632" diaginertia="0.113786 0.095141 0.0679957" />
            <joint name="r_z" pos="0 0 0" axis="0 0 1" stiffness="0" range="-6.28319 6.28319" armature="0" damping="0" />
            <geom name="thorax" type="mesh" mesh="thorax" />
            <geom name="Thorax" class="WrapEllipsoid" size="0.105" pos="-0.0386 -0.1273 0.0709" quat="0.981923 0.0056728 -0.166468 0.0899048" />
            <site name="PECM1-P3" pos="-7e-05 0.00821 0.10454" />
            <site name="PECM2-P4" pos="0.03091 -0.03922 0.09705" />
            <site name="PECM2-P5" pos="0.02769 -0.04498 0.02271" />
            <site name="PECM2-P3" pos="0.02083 -0.02005 0.11555" />
            <site name="PECM3-P4" pos="0.0525 -0.08417 0.08935" />
            <site name="PECM3-P5" pos="0.05724 -0.11654 0.03787" />
            <site name="PECM3-P3" pos="0.02984 -0.0544459 0.1151" />
            <site name="LAT1-P4" pos="-0.11828 -0.10118 0.03316" />
            <site name="LAT1-P5" pos="-0.09578 -0.11724 0.00882" />
            <site name="LAT2-P4" pos="-0.10992 -0.16908 0.02878" />
            <site name="LAT2-P5" pos="-0.07186 -0.18818 0.00815" />
            <site name="LAT3-P4" pos="-0.11157 -0.19387 0.05532" />
            <site name="LAT3-P5" pos="-0.07117 -0.24858 0.00907" />
            <light pos="0 0 4" dir="0 0 -1" mode="trackcom" />
            <body name="clavicle" pos="0.006325 0.00693 0.025465">
                <inertial pos="-0.011096 0.0063723 0.054168" quat="0.906292 0.0334036 0.164622 -0.387838" mass="0.156" diaginertia="0.001 0.001 0.001" />
                <joint name="sternoclavicular_r2" pos="0 0 0" axis="0.0153 0.989299 -0.1451" limited="false" range="-99999.9 99999.9" />
                <joint name="sternoclavicular_r3" pos="0 0 0" axis="-0.994473 0 -0.104997" limited="false" range="-99999.9 99999.9" />
                <geom name="clavicle" type="mesh" mesh="clavicle" />
                <site name="DELT1-P4" pos="-0.014 0.01106 0.08021" />
                <site name="DELT2-P2" pos="0.0191703 0.0244002 0.162891" />
                <site name="PECM1-P4" pos="0.00321 -0.00013 0.05113" />
                <body name="clavphant" pos="-0.01433 0.02007 0.135535">
                    <inertial pos="0 0 0" mass="0.001" diaginertia="1 1 1" />
                    <joint name="unrotscap_r3" pos="0 0 0" axis="-0.994473 0 -0.104997" limited="false" range="-99999.9 99999.9" />
                    <joint name="unrotscap_r2" pos="0 0 0" axis="0.0153 0.989299 -0.1451" limited="false" range="-99999.9 99999.9" />
                    <body name="scapula" pos="0 0 0">
                        <inertial pos="-0.054694 -0.035032 -0.043734" quat="0.453021 0.77921 0.0744129 0.426692" mass="0.70396" diaginertia="0.00199576 0.00103993 0.001" />
                        <joint name="acromioclavicular_r2" pos="0 0 0" axis="0.157095 0.947269 -0.279291" limited="false" range="-99999.9 99999.9" />
                        <joint name="acromioclavicular_r3" pos="0 0 0" axis="-0.754084 0.297594 0.585487" limited="false" range="-99999.9 99999.9" />
                        <joint name="acromioclavicular_r1" pos="0 0 0" axis="0.6377 0.1186 0.7611" limited="false" range="-99999.9 99999.9" />
                        <geom name="scapula" type="mesh" mesh="scapula" />
                        <geom name="TRIlongglen" class="WrapCylinder" size="0.003 0.015" pos="-0.0359 -0.0309 -0.0132" quat="0.351544 0.11052 -0.628373 0.685091" type="cylinder" />
                        <geom name="Deltoid2" class="WrapEllipsoid" size="0.04" pos="-0.0058 -0.0378 0.0096" quat="-0.423983 0.568355 0.433548 -0.5561" />
                        <geom name="TMIN" class="WrapEllipsoid" size="0.03" pos="-0.0418 -0.0519 -0.0359" quat="0.407551 -0.491839 -0.70683 -0.303953" />
                        <geom name="Delt3" class="WrapTorus" size="0.04" pos="-0.0973 -0.0428 -0.037" quat="0.916498 0.246512 0.233166 -0.211889" />
                        <geom name="INFSP" class="WrapTorus" size="0.008" pos="-0.0561 -0.0199 -0.0112" quat="0.95393 0.0340656 0.288173 0.0762432" />
                        <site name="DELT1-P3" pos="0.04347 -0.03252 0.00099" />
                        <site name="DELT2-P3" pos="5e-05 0.00294 0.02233" />
                        <site name="DELT2-P4" pos="-0.01078 -0.00034 0.0062" />
                        <site name="DELT3-P1" pos="-0.05573 0.00122 -0.02512" />
                        <site name="DELT3-P2" pos="-0.07247 -0.03285 0.01233" />
                        <site name="SUPSP-P2" pos="-0.01918 0.00127 -0.01271" />
                        <site name="SUPSP-P3" pos="-0.044 -0.01512 -0.05855" />
                        <site name="INFSP-P2" pos="-0.07382 -0.05476 -0.04781" />
                        <site name="SUBSC-P2" pos="-0.01831 -0.05223 -0.02457" />
                        <site name="SUBSC-P3" pos="-0.07246 -0.03943 -0.06475" />
                        <site name="TMIN-P2" pos="-0.09473 -0.07991 -0.04737" />
                        <site name="TMIN-P3" pos="-0.09643 -0.08121 -0.05298" />
                        <site name="TMAJ-P2" pos="-0.10264 -0.10319 -0.05829" />
                        <site name="TMAJ-P3" pos="-0.10489 -0.10895 -0.07117" />
                        <site name="LAT1-P2" pos="-0.08052 -0.06821 -0.02908" />
                        <site name="LAT1-P3" pos="-0.10925 -0.07239 -0.07422" />
                        <site name="LAT2-P2" pos="-0.08345 -0.08695 -0.02453" />
                        <site name="LAT2-P3" pos="-0.11524 -0.10749 -0.08863" />
                        <site name="LAT3-P2" pos="-0.08438 -0.11598 -0.02995" />
                        <site name="LAT3-P3" pos="-0.11279 -0.13833 -0.08911" />
                        <site name="CORB-P1" pos="0.0125 -0.04127 -0.02652" />
                        <site name="CORB-P2" pos="0.00483 -0.06958 -0.01563" />
                        <site name="TRIlong-P1" pos="-0.04565 -0.04073 -0.01377" />
                        <site name="BIClong-P1" pos="-0.03123 -0.02353 -0.01305" />
                        <site name="BIClong-P2" pos="-0.02094 -0.01309 -0.00461" />
                        <site name="BICshort-P1" pos="0.01268 -0.03931 -0.02625" />
                        <site name="BICshort-P2" pos="0.00093 -0.06704 -0.01593" />
                        <site name="TRIlongglen-sidesite" pos="-0.0299 -0.0309 -0.0132" />
                        <site name="Deltoid2-sidesite" pos="-0.0058 -0.1178 0.0096" />
                        <site name="TMIN-sidesite" pos="0.0182 -0.0519 -0.0359" />
                        <site name="Delt3-sidesite_torus" pos="-0.0973 -0.0428 -0.037" />
                        <site name="INFSP-sidesite_torus" pos="-0.0561 -0.0199 -0.0112" />
                        <body name="scapphant" pos="-0.00955 -0.034 0.009">
                            <inertial pos="0 0 0" mass="0.001" diaginertia="1 1 1" />
                            <joint name="unrothum_r1" pos="0 0 0" axis="0.6377 0.1186 0.7611" limited="false" range="-99999.9 99999.9" />
                            <joint name="unrothum_r3" pos="0 0 0" axis="-0.754084 0.297594 0.585487" limited="false" range="-99999.9 99999.9" />
                            <joint name="unrothum_r2" pos="0 0 0" axis="0.157095 0.947269 -0.279291" limited="false" range="-99999.9 99999.9" />
                            <body name="humphant" pos="0 0 0">
                                <inertial pos="0 0 0" mass="0.001" diaginertia="1 1 1" />
                                <joint name="elv_angle" pos="0 0 0" axis="0.0048 0.999089 0.0424" range="-0.8 1.8" user="1" />
                                <body name="humphant1" pos="0 0 0">
                                    <inertial pos="0 0 0" mass="0.001" diaginertia="1 1 1" />
                                    <joint name="shoulder_elv" pos="0 0 0" axis="-0.998261 0.0023 0.058898" range="0 2.14" user="1" />
                                    <joint name="shoulder1_r2" pos="0 0 0" axis="0.0048 0.999089 0.0424" limited="false" range="-99999.9 99999.9" />
                                    <body name="humerus" pos="0 0 0">
                                        <inertial pos="0.018064 -0.140141 -0.012746" quat="0.407851 0.343714 -0.567755 0.627034" mass="1.99757" diaginertia="0.0128576 0.0121576 0.00239265" />
                                        <joint name="shoulder_rot" pos="0 0 0" axis="0.0048 0.999089 0.0424" range="-1.57 1.57" user="1" />
                                        <geom name="humerus" type="mesh" mesh="humerus" />
                                        <geom name="delt2hum" class="WrapCylinder" size="0.0109 0.06" pos="0.0017 -0.0958 0.0011" quat="0.713951 0.699489 -0.0280017 0.0143153" type="cylinder" />
                                        <geom name="infsp_new" class="WrapCylinder" size="0.0235 0.0575" pos="-0.0019 -0.019 0.0022" quat="0.634174 0.685305 0.103671 -0.342685" type="cylinder" />
                                        <geom name="TMINhum" class="WrapCylinder" size="0.022 0.0565" pos="0.003 -0.0255 0.0013" quat="-0.0347275 -0.0160551 -0.671713 0.739823" type="cylinder" />
                                        <geom name="TMAJ_LAThum" class="WrapCylinder" size="0.007 0.02" pos="0.0007 -0.0443 -0.0055" quat="0.560829 0.5131 -0.468587 0.45014" type="cylinder" />
                                        <geom name="PEC12hum" class="WrapCylinder" size="0.009 0.035" pos="0.002 -0.0508 -0.0017" quat="0.62367 0.640854 0.289078 -0.341726" type="cylinder" />
                                        <geom name="PEC3hum" class="WrapCylinder" size="0.008 0.05" pos="0.0009 -0.0551 -0.0004" quat="0.49519 0.406008 -0.52011 0.565182" type="cylinder" />
                                        <geom name="LAT_TMAJhh" class="WrapCylinder" size="0.007 0.0225" pos="-0.0224 0.0102 0.0094" quat="0.931142 -0.14003 -0.059673 -0.331369" type="cylinder" />
                                        <geom name="TRI" class="WrapCylinder" size="0.016 0.05" pos="0.0028 -0.2919 -0.0119" quat="0.99453 -0.0700498 0.00229591 0.0774439" type="cylinder" />
                                        <geom name="CORBhum" class="WrapCylinder" size="0.008 0.05" pos="0.0027 -0.1202 -0.0059" quat="0.642258 -0.637511 0.335039 0.262362" type="cylinder" />
                                        <geom name="PEC23hh" class="WrapSphere" size="0.02" pos="-0.0086 0.0021 -0.0004" />
                                        <geom name="LAT_TMAJ2hh" class="WrapSphere" size="0.03" pos="-0.0016 0.0092 0.0052" quat="0.98852 -0.0616124 0.137953 0.000998816" />
                                        <geom name="TMAJ_LAT_PEC_CORBhh" class="WrapSphere" size="0.03" pos="0.0007 0 0.006" />
                                        <geom name="DELT_TMAJ_LAT_PEC_CORBhh" class="WrapSphere" size="0.03" pos="0.0007 0 0.006" />
                                        <geom name="DELT1hh" class="WrapEllipsoid" size="0.05" pos="-0.0139 -0.0127 -0.0262" quat="0.836755 0.159976 0.454596 0.259984" />
                                        <geom name="delt3hum" class="WrapEllipsoid" size="0.01 0.025" pos="0.0019 -0.0592 0.0011" quat="0.156765 0.126187 0.74954 -0.630628" type="cylinder" />
                                        <geom name="SUPSP" class="WrapEllipsoid" size="0.02" pos="0.0002 0.0077 0.0043" quat="0.793941 0.0125061 0.014958 -0.607682" />
                                        <geom name="INFSP_and_TMIN_hum_head" class="WrapEllipsoid" size="0.0216667" pos="-0.0003 0.0026 0.0038" quat="0.989184 -0.142563 -0.00937273 -0.0332033" />
                                        <geom name="SUBSCAP" class="WrapEllipsoid" size="0.0216667" pos="-0.0025 0.0007 -0.0045" quat="0.881835 -0.408889 0.210161 0.104923" />
                                        <geom name="LIGhh_s" class="WrapEllipsoid" size="0.02" pos="-0.001 0.003 0.003" quat="0.923956 -0.382499 0 0" />
                                        <geom name="LIGhh_mi" class="WrapEllipsoid" size="0.02" pos="-0.001 0.004 0.001" quat="0.923956 -0.382499 0 0" />
                                        <geom name="PEC1hh" class="WrapEllipsoid" size="0.02" pos="-0.0037 0.0005 -0.0025" quat="0.916757 -0.323265 -0.0902648 0.216583" />
                                        <geom name="Elbow_BIC_BRD" class="WrapEllipsoid" size="0.015 0.05" pos="0.0019 -0.289 -0.014" quat="0.995524 -0.0630586 0.0695464 0.0108747" type="cylinder" />
                                        <geom name="TRIlonghh" class="WrapEllipsoid" size="0.02" pos="-0.0078 -0.0041 -0.0014" quat="0.4142 0.226399 -0.879896 -0.0544578" />
                                        <geom name="ANC" class="WrapEllipsoid" size="0.02" pos="0.0134 -0.2861 -0.0008" quat="0.861498 -0.045952 -0.0868545 0.498163" />
                                        <geom name="BIClong" class="WrapEllipsoid" size="0.02" pos="0.0033 0.005 0.0003" quat="0.227667 -0.77413 0.117987 0.578766" />
                                        <geom name="Elbow_PT_ECRL" class="WrapEllipsoid" size="0.018" pos="0.003 -0.2872 -0.0069" quat="0.947268 -0.0932711 -0.0283225 0.305257" />
                                        <site name="DELT1-P1" pos="0.00896 -0.11883 0.00585" />
                                        <site name="DELT1-P2" pos="0.01623 -0.11033 0.00412" />
                                        <site name="DELT2-P1" pos="0.00461 -0.13611 0.0056" />
                                        <site name="DELT3-P3" pos="0.00206 -0.07602 0.01045" />
                                        <site name="SUPSP-P1" pos="0.00256 0.01063 0.02593" />
                                        <site name="INFSP-P1" pos="-0.00887 0.00484 0.02448" />
                                        <site name="SUBSC-P1" pos="0.01403 0.0084 -0.01331" />
                                        <site name="TMIN-P1" pos="-0.0011 -0.01264 0.02156" />
                                        <site name="TMAJ-P1" pos="0.00998 -0.05419 -0.00568" />
                                        <site name="PECM1-P1" pos="0.01169 -0.04191 0.0078" />
                                        <site name="PECM1-P2" pos="0.0191 -0.0301 0.00143" />
                                        <site name="PECM2-P1" pos="0.01274 -0.04289 0.00785" />
                                        <site name="PECM2-P2" pos="0.01748 -0.03533 0.00033" />
                                        <site name="PECM3-P1" pos="0.01269 -0.04375 0.0075" />
                                        <site name="PECM3-P2" pos="0.0159185 -0.045833 -0.00378312" />
                                        <site name="LAT1-P1" pos="0.0105 -0.03415 -0.00653" />
                                        <site name="LAT2-P1" pos="0.00968 -0.04071 -0.00611" />
                                        <site name="LAT3-P1" pos="0.01208 -0.03922 -0.00416" />
                                        <site name="CORB-P3" pos="0.00743 -0.15048 -0.00782" />
                                        <site name="TRIlong-P2" pos="-0.02714 -0.11441 -0.00664" />
                                        <site name="TRIlong-P3" pos="-0.03184 -0.22637 -0.01217" />
                                        <site name="TRIlong-P4" pos="-0.01743 -0.26757 -0.01208" />
                                        <site name="TRIlat-P1" pos="-0.00599 -0.12646 0.00428" />
                                        <site name="TRIlat-P2" pos="-0.02344 -0.14528 0.00928" />
                                        <site name="TRIlat-P3" pos="-0.03184 -0.22637 -0.01217" />
                                        <site name="TRIlat-P4" pos="-0.01743 -0.26757 -0.01208" />
                                        <site name="TRImed-P1" pos="-0.00838 -0.13695 -0.00906" />
                                        <site name="TRImed-P2" pos="-0.02601 -0.15139 -0.0108" />
                                        <site name="TRImed-P3" pos="-0.03184 -0.22637 -0.01217" />
                                        <site name="TRImed-P4" pos="-0.01743 -0.26757 -0.01208" />
                                        <site name="ANC-P1" pos="-0.00744 -0.28359 0.00979" />
                                        <site name="BIClong-P3" pos="0.02131 0.01793 0.01028" />
                                        <site name="BIClong-P4" pos="0.02378 -0.00511 0.01201" />
                                        <site name="BIClong-P5" pos="0.01345 -0.02827 0.00136" />
                                        <site name="BIClong-P6" pos="0.01068 -0.07736 -0.00165" />
                                        <site name="BIClong-P7" pos="0.01703 -0.12125 0.00024" />
                                        <site name="BIClong-P8" pos="0.0228 -0.1754 -0.0063" />
                                        <site name="BICshort-P3" pos="0.01117 -0.07576 -0.01101" />
                                        <site name="BICshort-P4" pos="0.01703 -0.12125 -0.01079" />
                                        <site name="BICshort-P5" pos="0.0228 -0.1754 -0.0063" />
                                        <site name="BRA-P1" pos="0.0068 -0.1739 -0.0036" />
                                        <site name="BRA-P2" pos="0.01894 -0.28559 -0.01105" />
                                        <site name="BRD-P1" pos="-0.0098 -0.19963 0.00223" />
                                        <site name="ECRL-P1" pos="-0.0073 -0.2609 0.0091" />
                                        <site name="ECRB-P1" pos="0.01349 -0.29048 0.01698" />
                                        <site name="ECU-P1" pos="0.00083 -0.28955 0.0188" />
                                        <site name="FCR-P1" pos="0.00758 -0.27806 -0.03705" />
                                        <site name="FCU-P1" pos="0.00219 -0.2774 -0.0388" />
                                        <site name="PL-P1" pos="0.00457 -0.27519 -0.03865" />
                                        <site name="PT-P1" pos="0.0036 -0.2759 -0.0365" />
                                        <site name="FDSL-P1" pos="0.00421 -0.27598 -0.03864" />
                                        <site name="FDSR-P1" pos="0.00479 -0.2788 -0.03731" />
                                        <site name="EDCL-P1" pos="-0.0004 -0.28831 0.0187" />
                                        <site name="EDCR-P1" pos="-0.00156 -0.28936 0.01782" />
                                        <site name="EDCM-P1" pos="0.00051 -0.28984 0.01949" />
                                        <site name="EDCI-P1" pos="0.00065 -0.28898 0.01869" />
                                        <site name="EDM-P1" pos="0.00089 -0.28919 0.01847" />
                                        <site name="infsp_new-sidesite" pos="-0.0489 -0.019 0.0022" />
                                        <site name="TMINhum-sidesite" pos="0.047 -0.0255 0.0013" />
                                        <site name="TMAJ_LAThum-sidesite" pos="-0.0133 -0.0443 -0.0055" />
                                        <site name="PEC12hum-sidesite" pos="0.02 -0.0508 -0.0017" />
                                        <site name="PEC3hum-sidesite" pos="-0.0151 -0.0551 -0.0004" />
                                        <site name="LAT_TMAJhh-sidesite" pos="-0.0224 -0.0038 0.0094" />
                                        <site name="CORBhum-sidesite" pos="0.0187 -0.1202 -0.0059" />
                                        <site name="DELT1hh-sidesite" pos="-0.0139 -0.0127 0.0738" />
                                        <site name="delt3hum-sidesite" pos="0.0219 -0.0592 0.0011" />
                                        <site name="PEC1hh-sidesite" pos="-0.0037 0.0005 -0.0425" />
                                        <site name="Elbow_BIC_BRD-sidesite" pos="0.0319 -0.289 -0.014" />
                                        <site name="TRIlonghh-sidesite" pos="-0.0078 -0.0041 0.0386" />
                                        <site name="ANC-sidesite" pos="-0.0266 -0.2861 -0.0008" />
                                        <site name="BIClong-sidesite" pos="0.0033 -0.035 0.0003" />
                                        <site name="Elbow_PT_ECRL-sidesite" pos="0.039 -0.2872 -0.0069" />
                                        <body name="ulna" pos="0.0061 -0.2904 -0.0123">
                                            <inertial pos="0.00971783 -0.0959509 0.024286" quat="0.792048 0.609078 0.0156735 0.0379256" mass="1.1053" diaginertia="0.00543663 0.00523521 0.001" />
                                            <joint name="elbow_flexion" pos="0 0 0" axis="0.0494 0.0366 0.998108" range="0 2.26893" user="1" />
                                            <geom name="ulna" type="mesh" mesh="ulna" />
                                            <geom name="PQ2" class="WrapCylinder" size="0.007 0.05" pos="-0.0012 -0.2092 0.0428" quat="0.540178 0.48199 -0.422694 0.545182" type="cylinder" />
                                            <site name="TRIlong-P5" pos="-0.0219 0.01046 -0.00078" />
                                            <site name="TRIlat-P5" pos="-0.0219 0.01046 -0.00078" />
                                            <site name="TRImed-P5" pos="-0.0219 0.01046 -0.00078" />
                                            <site name="ANC-P2" pos="-0.02532 -0.00124 0.006" />
                                            <site name="SUP-P3" pos="-0.0136 -0.03384 0.02013" />
                                            <site name="BRA-P4" pos="-0.0032 -0.0239 0.0009" />
                                            <site name="BRA-P3" pos="0.00498 -0.01463 0.00128" />
                                            <site name="ECU-P2" pos="-0.01391 -0.03201 0.02947" />
                                            <site name="ECU-P3" pos="-0.01705 -0.05428 0.02868" />
                                            <site name="ECU-P4" pos="-0.01793 -0.09573 0.03278" />
                                            <site name="PT-P2" pos="0.00846 -0.03373 -0.01432" />
                                            <site name="PT-P3" pos="0.01219 -0.06516 -0.00219" />
                                            <site name="PQ-P2" pos="0.00193 -0.20972 0.03632" />
                                            <site name="FDSM-P1" pos="-0.00669 -0.02713 -0.00191" />
                                            <site name="FDSI-P1" pos="-0.00676 -0.02819 -0.00137" />
                                            <site name="FDPL-P1" pos="-0.00628 -0.03214 0.00254" />
                                            <site name="FDPR-P1" pos="-0.00502 -0.03374 0.00273" />
                                            <site name="FDPM-P1" pos="-0.00522 -0.03327 0.0021" />
                                            <site name="FDPI-P1" pos="-0.00647 -0.03176 0.0028" />
                                            <site name="EDM-P2" pos="-0.00977 -0.03907 0.03085" />
                                            <site name="EDM-P3" pos="-0.00755 -0.08267 0.03646" />
                                            <site name="EIP-P1" pos="-0.00394 -0.16652 0.03682" />
                                            <site name="EIP-P2" pos="0.00171 -0.17469 0.04049" />
                                            <site name="EPL-P1" pos="-0.01412 -0.09706 0.02952" />
                                            <body name="radius" pos="0.0004 -0.011503 0.019999">
                                                <inertial pos="0.0336341 -0.181559 0.0156" quat="0.770264 0.63559 0.0119833 0.0507376" mass="0.23359" diaginertia="0.001 0.001 0.001" />
                                                <joint name="pro_sup" pos="0 0 0" axis="-0.017161 0.992666 -0.119668" range="-1.5708 1.5708" user="1" />
                                                <geom name="radius" type="mesh" mesh="radius" />
                                                <geom name="SUP" class="WrapCylinder" size="0.008 0.02" pos="0.0045 -0.0437 0.0059" quat="0.348354 0.118085 0.653837 -0.661213" type="cylinder" />
                                                <geom name="PQ1" class="WrapCylinder" size="0.01 0.05" pos="0.0281 -0.1986 0.0288" quat="0.15975 -0.156797 -0.702724 -0.675332" type="cylinder" />
                                                <geom name="ECU" class="WrapTorus" size="0.006" pos="-0.0163 -0.2417 0.0349" quat="0.868974 -0.476593 -0.0126206 0.132601" />
                                                <site name="SUP-P1" pos="0.00996 -0.06096 0.00075" />
                                                <site name="SUP-P2" pos="0.01201 -0.0517 -0.00107" />
                                                <site name="BIClong-P11" pos="-0.002 -0.0375 -0.002" />
                                                <site name="BIClong-P9" pos="0.00273 -0.0343493 -0.0119845" />
                                                <site name="BICshort-P8" pos="-0.002 -0.0375 -0.002" />
                                                <site name="BICshort-P6" pos="0.00273 -0.0343493 -0.0119845" />
                                                <site name="BRD-P2" pos="0.03577 -0.12742 0.02315" />
                                                <site name="BRD-P3" pos="0.0419 -0.221 0.0224" />
                                                <site name="ECRL-P2" pos="0.03195 -0.13463 0.02779" />
                                                <site name="ECRL-P3" pos="0.04243 -0.23684 0.0362" />
                                                <site name="ECRB-P2" pos="0.02905 -0.13086 0.02385" />
                                                <site name="ECRB-P3" pos="0.03549 -0.22805 0.03937" />
                                                <site name="ECU-P5" pos="-0.01421 -0.22696 0.03481" />
                                                <site name="FCR-P2" pos="0.0211 -0.21943 0.00127" />
                                                <site name="FCU-P3" pos="0.01082 -0.22327 0.00969" />
                                                <site name="FCU-P2" pos="0.0101156 -0.183524 0.00202653" />
                                                <site name="PL-P2" pos="0.02531 -0.23915 -0.00276" />
                                                <site name="PT-P5" pos="0.0254 -0.1088 0.0198" />
                                                <site name="PT-P4" pos="0.0236 -0.0934 0.0094" />
                                                <site name="PQ-P1" pos="0.03245 -0.19998 0.01962" />
                                                <site name="FDSL-P2" pos="0.01377 -0.18718 0.00205" />
                                                <site name="FDSR-P2" pos="0.01571 -0.18666 0.00267" />
                                                <site name="FDSM-P2" pos="0.01899 -0.18706 0.00424" />
                                                <site name="FDSI-P2" pos="0.02145 -0.18623 0.00552" />
                                                <site name="FDPL-P2" pos="0.01409 -0.18516 0.00861" />
                                                <site name="FDPR-P2" pos="0.0158 -0.18629 0.00803" />
                                                <site name="FDPM-P2" pos="0.01906 -0.18644 0.00785" />
                                                <site name="FDPI-P2" pos="0.0208 -0.1856 0.00915" />
                                                <site name="EDCL-P3" pos="0.00993 -0.22304 0.03618" />
                                                <site name="EDCL-P2" pos="0.0013 -0.0382544 0.0129514" />
                                                <site name="EDCR-P3" pos="0.00882 -0.22366 0.04284" />
                                                <site name="EDCR-P2" pos="0.0026 -0.0392844 0.0144214" />
                                                <site name="EDCM-P3" pos="0.0144 -0.22323 0.04223" />
                                                <site name="EDCM-P2" pos="0.00316 -0.0388544 0.0141814" />
                                                <site name="EDCI-P3" pos="0.01533 -0.22314 0.04196" />
                                                <site name="EDCI-P2" pos="0.00228 -0.0385544 0.0137314" />
                                                <site name="EDM-P4" pos="0.00454 -0.22641 0.03678" />
                                                <site name="EIP-P3" pos="0.01076 -0.22783 0.03664" />
                                                <site name="EPL-P2" pos="0.00124 -0.13668 0.0227" />
                                                <site name="EPL-P3" pos="0.02702 -0.21872 0.03828" />
                                                <site name="EPL-P4" pos="0.03382 -0.22754 0.04607" />
                                                <site name="EPL-P5" pos="0.04234 -0.23771 0.04173" />
                                                <site name="EPB-P1" pos="0.01924 -0.14695 0.02114" />
                                                <site name="EPB-P2" pos="0.02276 -0.15857 0.02665" />
                                                <site name="EPB-P3" pos="0.03831 -0.19722 0.03834" />
                                                <site name="EPB-P4" pos="0.05235 -0.23611 0.02699" />
                                                <site name="FPL-P1" pos="0.00971 -0.09458 0.01769" />
                                                <site name="FPL-P2" pos="0.01658 -0.13525 0.01915" />
                                                <site name="FPL-P3" pos="0.01869 -0.17932 0.01988" />
                                                <site name="FPL-P4" pos="0.038 -0.23171 0.0158" />
                                                <site name="APL-P1" pos="0.01154 -0.09477 0.01681" />
                                                <site name="APL-P2" pos="0.0303 -0.1397 0.03507" />
                                                <site name="APL-P3" pos="0.03993 -0.16072 0.034" />
                                                <site name="APL-P4" pos="0.04397 -0.17845 0.03134" />
                                                <site name="APL-P5" pos="0.05505 -0.23084 0.02368" />
                                                <site name="SUP-sidesite" pos="-0.0115 -0.0437 0.0059" />
                                                <site name="ECU-sidesite_torus" pos="-0.0163 -0.2417 0.0349" />
                                                <body name="proximal_row" pos="0.018 -0.242 0.025">
                                                    <inertial pos="0 0 0" mass="0.001" diaginertia="0.001 0.001 0.001" />
                                                    <geom name="lunate" type="mesh" mesh="lunate" />
                                                    <geom name="sdfastSCAPHOIDw" type="mesh" mesh="sdfastSCAPHOIDw" />
                                                    <geom name="sdfastPISIFORMw" type="mesh" mesh="sdfastPISIFORMw" />
                                                    <geom name="sdfastTRIQUETRALw" type="mesh" mesh="sdfastTRIQUETRALw" />
                                                    <geom name="Extensor_ellipse" class="WrapEllipsoid" size="0.013" pos="0.0007 -0.0135 0.0047" quat="0.977473 -0.106567 0.15459 0.0963908" />
                                                    <geom name="PL" class="WrapEllipsoid" size="0.012" pos="0.0057 -0.018 -0.0041" quat="0.998158 -0.0141897 0.050277 0.0308428" />
                                                    <geom name="FDS" class="WrapEllipsoid" size="0.012" pos="0.0012 -0.0057 -0.0003" quat="0.999119 0.0045343 -0.0407917 -0.00871581" />
                                                    <geom name="FDP" class="WrapEllipsoid" size="0.013" pos="-0.0022 -0.0069 0.0032" quat="0.733834 -0.669637 -0.0314447 0.109931" />
                                                    <geom name="EDM" class="WrapEllipsoid" size="0.008" pos="-0.0167 -0.0022 0.0048" quat="0.0842151 0.991535 -0.0514386 0.084384" />
                                                    <geom name="FPL" class="WrapEllipsoid" size="0.01" pos="0.017 -0.025 -0.0033" quat="0.995273 -0.0816033 -0.043664 -0.0294275" />
                                                    <geom name="ECRL" class="WrapTorus" size="0.008" pos="0.0222 -0.0096 0.0208" quat="0.637341 0.675154 -0.168466 0.331034" />
                                                    <geom name="ECRB" class="WrapTorus" size="0.008" pos="0.0126 -0.0095 0.0186" quat="0.787441 0.610836 -0.0111771 -0.0818019" />
                                                    <geom name="FCR" class="WrapTorus" size="0.001" pos="0.0032 -0.0045 -0.019" quat="0.71204 -0.696183 -0.0894344 0.0181556" />
                                                    <geom name="FCU" class="WrapTorus" size="0.0068" pos="-0.0123 -0.0124 -0.0171" quat="0.686461 -0.699506 0.110312 0.165208" />
                                                    <geom name="EDCL" class="WrapTorus" size="0.008" pos="-0.0128 -0.0133 0.0148" quat="0.386235 0.907674 0.159784 0.0376831" />
                                                    <geom name="EDCR" class="WrapTorus" size="0.0105" pos="-0.0098 -0.0137 0.0166" quat="0.516904 0.814719 -0.189621 0.181899" />
                                                    <geom name="EDCM" class="WrapTorus" size="0.009" pos="-0.0007 -0.0117 0.0191" quat="0.51619 0.831215 -0.100219 0.180516" />
                                                    <geom name="EDCI" class="WrapTorus" size="0.009" pos="0.009 -0.0149 0.0211" quat="0.660055 0.749868 0.0267536 0.0361877" />
                                                    <site name="Extensor_ellipse-sidesite" pos="0.0007 -0.0135 0.0307" />
                                                    <site name="PL-sidesite" pos="0.0057 -0.018 -0.0281" />
                                                    <site name="FDS-sidesite" pos="0.0012 -0.0057 -0.0243" />
                                                    <site name="FDP-sidesite" pos="-0.0022 0.0191 0.0032" />
                                                    <site name="EDM-sidesite" pos="-0.0167 -0.0022 -0.0112" />
                                                    <site name="FPL-sidesite" pos="0.017 -0.025 -0.0233" />
                                                    <site name="ECRL-sidesite_torus" pos="0.0222 -0.0096 0.0208" />
                                                    <site name="ECRB-sidesite_torus" pos="0.0126 -0.0095 0.0186" />
                                                    <site name="FCR-sidesite_torus" pos="0.0032 -0.0045 -0.019" />
                                                    <site name="FCU-sidesite_torus" pos="-0.0123 -0.0124 -0.0171" />
                                                    <site name="EDCL-sidesite_torus" pos="-0.0128 -0.0133 0.0148" />
                                                    <site name="EDCR-sidesite_torus" pos="-0.0098 -0.0137 0.0166" />
                                                    <site name="EDCM-sidesite_torus" pos="-0.0007 -0.0117 0.0191" />
                                                    <site name="EDCI-sidesite_torus" pos="0.009 -0.0149 0.0211" />
                                                    <body name="hand" pos="0.003992 -0.015054 0.002327">
                                                        <inertial pos="-0.00301314 -0.0424993 -0.00112205" quat="0.526799 0.470642 -0.462095 0.536141" mass="0.5819" diaginertia="0.001 0.001 0.001" />
                                                        <geom name="sdfast_1seg_hand_fr_c_5mc" type="mesh" mesh="sdfast_1seg_hand_fr_c_5mc" />
                                                        <geom name="sdfast_1seg_hand_fr_c_4mc" type="mesh" mesh="sdfast_1seg_hand_fr_c_4mc" />
                                                        <geom name="sdfast_1seg_hand_fr_c_3mc" type="mesh" mesh="sdfast_1seg_hand_fr_c_3mc" />
                                                        <geom name="sdfast_1seg_hand_fr_c_trapezium" type="mesh" mesh="sdfast_1seg_hand_fr_c_trapezium" />
                                                        <geom name="sdfast_1seg_hand_fr_c_trapezoid" type="mesh" mesh="sdfast_1seg_hand_fr_c_trapezoid" />
                                                        <geom name="sdfast_1seg_hand_fr_c_hamate" type="mesh" mesh="sdfast_1seg_hand_fr_c_hamate" />
                                                        <geom name="capitate" type="mesh" mesh="capitate" />
                                                        <geom name="hand_3proxph" type="mesh" mesh="hand_3proxph" />
                                                        <geom name="hand_3midph" type="mesh" mesh="hand_3midph" />
                                                        <geom name="hand_3distph" type="mesh" mesh="hand_3distph" />
                                                        <geom name="hand_4proxph" type="mesh" mesh="hand_4proxph" />
                                                        <geom name="hand_4midph" type="mesh" mesh="hand_4midph" />
                                                        <geom name="hand_4distph" type="mesh" mesh="hand_4distph" />
                                                        <geom name="hand_5proxph" type="mesh" mesh="hand_5proxph" />
                                                        <geom name="hand_5midph" type="mesh" mesh="hand_5midph" />
                                                        <geom name="hand_5distph" type="mesh" mesh="hand_5distph" />
                                                        <geom name="hand_thumbprox" type="mesh" mesh="hand_thumbprox" />
                                                        <geom name="hand_thumbdist" type="mesh" mesh="hand_thumbdist" />
                                                        <geom name="hand_1mc" type="mesh" mesh="hand_1mc" />
                                                        <geom name="_2rdmcp_FDS" class="WrapCylinder" size="0.013 0.005" pos="0.0182 -0.0659 0.0087" quat="0.504168 -0.475417 0.494684 -0.524482" type="cylinder" />
                                                        <geom name="_2rdmcp_FDP" class="WrapCylinder" size="0.0105 0.005" pos="0.0182 -0.0659 0.0087" quat="0.485557 -0.492391 0.477792 -0.541756" type="cylinder" />
                                                        <geom name="_2rdmcp_ext" class="WrapCylinder" size="0.01 0.005" pos="0.0182 -0.0659 0.0087" quat="0.54796 -0.430494 0.534236 -0.478545" type="cylinder" />
                                                        <geom name="_3rdmcp_FDS" class="WrapCylinder" size="0.013 0.005" pos="0.0007 -0.0655 0.0092" quat="0.352215 0.613143 0.194726 0.679766" type="cylinder" />
                                                        <geom name="_3rdmcp_FDP" class="WrapCylinder" size="0.0105 0.005" pos="0.0046 -0.0662 0.0099" quat="0.352215 0.613143 0.194726 0.679766" type="cylinder" />
                                                        <geom name="_3rdmcp_ext" class="WrapCylinder" size="0.01 0.005" pos="0.0007 -0.0655 0.0092" quat="0.387309 0.602111 0.226549 0.660401" type="cylinder" />
                                                        <geom name="_4rdmcp_FDS" class="WrapCylinder" size="0.013 0.005" pos="-0.0139 -0.0642 0.0033" quat="0.4559 -0.336226 0.489089 -0.663249" type="cylinder" />
                                                        <geom name="_4rdmcp_FDP" class="WrapCylinder" size="0.0105 0.005" pos="-0.0139 -0.0642 0.0033" quat="0.4559 -0.336226 0.489089 -0.663249" type="cylinder" />
                                                        <geom name="_4rdmcp_ext" class="WrapCylinder" size="0.01 0.005" pos="-0.0139 -0.0642 0.0033" quat="0.235359 -0.467735 0.365349 -0.769643" type="cylinder" />
                                                        <geom name="_5rdmcp_FDS" class="WrapCylinder" size="0.013 0.006" pos="-0.0235 -0.0561 -0.0057" quat="0.514699 -0.297269 0.402214 -0.696377" type="cylinder" />
                                                        <geom name="_5rdmcp_FDP" class="WrapCylinder" size="0.0105 0.005" pos="-0.0235 -0.0561 -0.0057" quat="0.432555 -0.340891 0.365975 -0.750167" type="cylinder" />
                                                        <geom name="_5rdmcp_ext" class="WrapCylinder" size="0.01 0.006" pos="-0.0235 -0.0561 -0.0057" quat="0.653221 -0.203168 0.45702 -0.568469" type="cylinder" />
                                                        <geom name="Secondpm_FDS" class="WrapCylinder" size="0.0075 0.005" pos="0.0307 -0.0924 -0.0222" quat="0.701654 -0.299791 0.641317 -0.0807432" type="cylinder" />
                                                        <geom name="Secondpm_FDP" class="WrapCylinder" size="0.008 0.005" pos="0.0307 -0.0924 -0.0222" quat="0.701654 -0.299791 0.641317 -0.0807432" type="cylinder" />
                                                        <geom name="Secondpm_ext" class="WrapCylinder" size="0.0055 0.006" pos="0.0307 -0.0924 -0.0222" quat="0.701654 -0.299791 0.641317 -0.0807432" type="cylinder" />
                                                        <geom name="Secondmd_flex" class="WrapCylinder" size="0.005 0.005" pos="0.0291 -0.0821 -0.045" quat="0.657978 0.091843 0.706005 0.245331" type="cylinder" />
                                                        <geom name="Secondmd_ext" class="WrapCylinder" size="0.002 0.005" pos="0.0291 -0.0821 -0.045" quat="0.657978 0.091843 0.706005 0.245331" type="cylinder" />
                                                        <geom name="Secondpm" class="WrapCylinder" size="0.004 0.005" pos="0.0306 -0.0911 -0.0223" quat="0.595011 0.428705 -0.615575 -0.288516" type="cylinder" />
                                                        <geom name="Secondmd" class="WrapCylinder" size="0.003 0.005" pos="0.0295 -0.0815 -0.0441" quat="0.466777 0.600823 -0.345164 -0.549539" type="cylinder" />
                                                        <geom name="MPthumb" class="WrapCylinder" size="0.0085 0.01" pos="0.0402 -0.0405 -0.0271" quat="0.904577 0.123988 0.114414 -0.391506" type="cylinder" />
                                                        <geom name="IPthumb" class="WrapCylinder" size="0.0045 0.005" pos="0.0396 -0.0713 -0.0365" quat="0.977705 0.165602 0.00825833 -0.128846" type="cylinder" />
                                                        <geom name="Thirdpm_FDS" class="WrapCylinder" size="0.0075 0.005" pos="0.0122 -0.0934 -0.0238" quat="0.720486 -0.198259 0.637578 -0.187315" type="cylinder" />
                                                        <geom name="Thirdpm_FDP" class="WrapCylinder" size="0.008 0.005" pos="0.0122 -0.0934 -0.0238" quat="0.720486 -0.198259 0.637578 -0.187315" type="cylinder" />
                                                        <geom name="Thirdpm_ext" class="WrapCylinder" size="0.0055 0.005" pos="0.0122 -0.0934 -0.0238" quat="0.720486 -0.198259 0.637578 -0.187315" type="cylinder" />
                                                        <geom name="Thirdmd_flex" class="WrapCylinder" size="0.005 0.005" pos="0.019 -0.0814 -0.0494" quat="0.768057 0.221741 0.586112 0.131877" type="cylinder" />
                                                        <geom name="Thirdmd_ext" class="WrapCylinder" size="0.002 0.005" pos="0.019 -0.0814 -0.0494" quat="0.768057 0.221741 0.586112 0.131877" type="cylinder" />
                                                        <geom name="Fourthpm_FDS" class="WrapCylinder" size="0.0075 0.005" pos="-0.005 -0.0871 -0.0289" quat="0.772303 -0.00545462 0.534112 -0.343863" type="cylinder" />
                                                        <geom name="Fourthpm_FDP" class="WrapCylinder" size="0.008 0.005" pos="-0.005 -0.0871 -0.0289" quat="0.772303 -0.00545462 0.534112 -0.343863" type="cylinder" />
                                                        <geom name="Fourthpm_ext" class="WrapCylinder" size="0.0055 0.005" pos="-0.005 -0.0871 -0.0289" quat="0.772303 -0.00545462 0.534112 -0.343863" type="cylinder" />
                                                        <geom name="Fourthmd_flex" class="WrapCylinder" size="0.005 0.005" pos="0.0094 -0.0778 -0.0469" quat="0.842867 0.293146 0.441348 0.0940923" type="cylinder" />
                                                        <geom name="Fourthmd_ext" class="WrapCylinder" size="0.002 0.005" pos="0.0094 -0.0778 -0.0469" quat="0.842867 0.293146 0.441348 0.0940923" type="cylinder" />
                                                        <geom name="Fifthpm_FDS" class="WrapCylinder" size="0.0075 0.005" pos="-0.0154 -0.0784 -0.0329" quat="0.716647 0.0685597 0.552737 -0.419759" type="cylinder" />
                                                        <geom name="Fifthpm_FDP" class="WrapCylinder" size="0.008 0.005" pos="-0.0153 -0.0786 -0.0329" quat="0.651254 -0.00903294 0.5569 -0.515411" type="cylinder" />
                                                        <geom name="Fifthpm_ext" class="WrapCylinder" size="0.0055 0.005" pos="-0.0152 -0.0785 -0.0328" quat="0.790513 0.186571 0.524796 -0.254696" type="cylinder" />
                                                        <geom name="Fifthmd_flex" class="WrapCylinder" size="0.005 0.005" pos="0.0007 -0.0741 -0.0457" quat="0.842182 0.338265 0.404575 -0.112365" type="cylinder" />
                                                        <geom name="Fifthmd_ext" class="WrapCylinder" size="0.002 0.005" pos="0.007 -0.0741 -0.0457" quat="0.842182 0.338265 0.404575 -0.112365" type="cylinder" />
                                                        <geom name="_2ndmcp" class="WrapEllipsoid" size="0.005 0.015" pos="0.0206 -0.068 0.0044" quat="0.587323 -0.229042 -0.660427 0.407955" type="cylinder" />
                                                        <site name="ECRL-P4" pos="0.01717 -0.02122 0.00583" />
                                                        <site name="ECRB-P4" pos="0.005 -0.01136 0.0085" />
                                                        <site name="ECU-P6" pos="-0.02251 -0.01401 -0.00128" />
                                                        <site name="FCR-P3" pos="0.01124 -0.01844 -0.00418" />
                                                        <site name="FCU-P4" pos="-0.02036 -0.01765 -0.00752" />
                                                        <site name="PL-P3" pos="0.00917 -0.01898 -0.01754" />
                                                        <site name="PL-P4" pos="0.00227 -0.03096 0.00493" />
                                                        <site name="FDSL-P3" pos="-0.00235 -0.01393 -0.01376" />
                                                        <site name="FDSL-P4" pos="-0.01995 -0.04281 -0.00742" />
                                                        <site name="FDSL-P5" pos="-0.02044 -0.05981 -0.01878" />
                                                        <site name="FDSL-P6" pos="-0.01713 -0.07245 -0.02753" />
                                                        <site name="FDSL-P7" pos="-0.01156 -0.07271 -0.03656" />
                                                        <site name="FDSL-P8" pos="-0.01059 -0.07271 -0.03796" />
                                                        <site name="FDSR-P3" pos="-0.00082 -0.01344 -0.01359" />
                                                        <site name="FDSR-P4" pos="-0.00977 -0.05179 4e-05" />
                                                        <site name="FDSR-P5" pos="-0.01323 -0.0667 -0.0102" />
                                                        <site name="FDSR-P6" pos="-0.00788 -0.08027 -0.02503" />
                                                        <site name="FDSR-P7" pos="-0.00299 -0.08125 -0.03395" />
                                                        <site name="FDSR-P8" pos="0.00062 -0.08092 -0.03892" />
                                                        <site name="FDSM-P3" pos="0.0068 -0.01377 -0.01399" />
                                                        <site name="FDSM-P4" pos="0.00471 -0.03332 -0.00132" />
                                                        <site name="FDSM-P5" pos="0.00542 -0.0566 0.0006" />
                                                        <site name="FDSM-P6" pos="0.00555 -0.07224 -0.00338" />
                                                        <site name="FDSM-P7" pos="0.01167 -0.0881 -0.0167" />
                                                        <site name="FDSM-P8" pos="0.01301 -0.0887 -0.02977" />
                                                        <site name="FDSM-P9" pos="0.01568 -0.08577 -0.03765" />
                                                        <site name="FDSI-P3" pos="0.00889 -0.01366 -0.01387" />
                                                        <site name="FDSI-P4" pos="0.01061 -0.03787 0.00024" />
                                                        <site name="FDSI-P5" pos="0.01782 -0.05108 0.00418" />
                                                        <site name="FDSI-P6" pos="0.01849 -0.07297 -0.00375" />
                                                        <site name="FDSI-P7" pos="0.02678 -0.08714 -0.01804" />
                                                        <site name="FDSI-P8" pos="0.02667 -0.0874 -0.02678" />
                                                        <site name="FDSI-P9" pos="0.0266 -0.08633 -0.02903" />
                                                        <site name="FDPL-P3" pos="-0.00088 -0.01027 -0.01188" />
                                                        <site name="FDPL-P4" pos="-0.01855 -0.04646 -0.00733" />
                                                        <site name="FDPL-P5" pos="-0.01808 -0.05841 -0.0156" />
                                                        <site name="FDPL-P6" pos="-0.01428 -0.07289 -0.02683" />
                                                        <site name="FDPL-P7" pos="-0.0092 -0.07483 -0.03684" />
                                                        <site name="FDPL-P8" pos="-0.00312 -0.07405 -0.04165" />
                                                        <site name="FDPL-P9" pos="0.00446 -0.07059 -0.04657" />
                                                        <site name="FDPR-P3" pos="0.00106 -0.01177 -0.01184" />
                                                        <site name="FDPR-P4" pos="-0.00855 -0.05542 0.00088" />
                                                        <site name="FDPR-P5" pos="-0.01079 -0.06588 -0.00817" />
                                                        <site name="FDPR-P6" pos="-0.00547 -0.08154 -0.02256" />
                                                        <site name="FDPR-P7" pos="-0.00056 -0.0823 -0.03367" />
                                                        <site name="FDPR-P8" pos="0.00609 -0.07837 -0.04238" />
                                                        <site name="FDPR-P9" pos="0.01211 -0.0738 -0.04858" />
                                                        <site name="FDPM-P3" pos="0.00335 -0.0128 -0.01144" />
                                                        <site name="FDPM-P4" pos="0.00302 -0.03447 -0.00611" />
                                                        <site name="FDPM-P5" pos="0.00252 -0.05863 0.00122" />
                                                        <site name="FDPM-P6" pos="0.00285 -0.06985 -0.00133" />
                                                        <site name="FDPM-P7" pos="0.00863 -0.08779 -0.01815" />
                                                        <site name="FDPM-P8" pos="0.01002 -0.08766 -0.02964" />
                                                        <site name="FDPM-P9" pos="0.01633 -0.08157 -0.04435" />
                                                        <site name="FDPM-P10" pos="0.01909 -0.07663 -0.05229" />
                                                        <site name="FDPI-P3" pos="0.00896 -0.01168 -0.01212" />
                                                        <site name="FDPI-P4" pos="0.01922 -0.05542 0.00438" />
                                                        <site name="FDPI-P5" pos="0.02073 -0.07021 -0.00286" />
                                                        <site name="FDPI-P6" pos="0.02904 -0.08588 -0.01782" />
                                                        <site name="FDPI-P7" pos="0.02924 -0.08672 -0.02769" />
                                                        <site name="FDPI-P8" pos="0.02914 -0.08235 -0.03979" />
                                                        <site name="FDPI-P9" pos="0.02847 -0.07771 -0.04766" />
                                                        <site name="EDCL-P4" pos="-0.02464 -0.04402 0.00169" />
                                                        <site name="EDCL-P5" pos="-0.02381 -0.04734 0.00077" />
                                                        <site name="EDCL-P6" pos="-0.02395 -0.06613 -0.01001" />
                                                        <site name="EDCL-P7" pos="-0.01798 -0.07847 -0.02711" />
                                                        <site name="EDCL-P8" pos="-0.01178 -0.07877 -0.03779" />
                                                        <site name="EDCL-P9" pos="-0.0015 -0.07586 -0.04586" />
                                                        <site name="EDCL-P10" pos="0.00201 -0.07487 -0.04794" />
                                                        <site name="EDCR-P4" pos="-0.01564 -0.0555 0.00934" />
                                                        <site name="EDCR-P5" pos="-0.01427 -0.05819 0.01161" />
                                                        <site name="EDCR-P6" pos="-0.0158 -0.07216 -0.00421" />
                                                        <site name="EDCR-P7" pos="-0.00825 -0.08735 -0.0226" />
                                                        <site name="EDCR-P8" pos="-0.00272 -0.08806 -0.03409" />
                                                        <site name="EDCR-P9" pos="0.00763 -0.08026 -0.04658" />
                                                        <site name="EDCR-P10" pos="0.01069 -0.07809 -0.04941" />
                                                        <site name="EDCM-P4" pos="0.00039 -0.05274 0.01491" />
                                                        <site name="EDCM-P5" pos="-0.00087 -0.05574 0.01452" />
                                                        <site name="EDCM-P6" pos="0.00186 -0.07718 0.00597" />
                                                        <site name="EDCM-P7" pos="0.01007 -0.09313 -0.01774" />
                                                        <site name="EDCM-P8" pos="0.01321 -0.09558 -0.03056" />
                                                        <site name="EDCM-P9" pos="0.01857 -0.08525 -0.04759" />
                                                        <site name="EDCM-P10" pos="0.02056 -0.07993 -0.05341" />
                                                        <site name="EDCM-P11" pos="0.02195 -0.07701 -0.05663" />
                                                        <site name="EDCI-P4" pos="0.01543 -0.0468 0.01639" />
                                                        <site name="EDCI-P5" pos="0.01897 -0.05654 0.01438" />
                                                        <site name="EDCI-P6" pos="0.01994 -0.07678 0.00594" />
                                                        <site name="EDCI-P7" pos="0.02945 -0.09162 -0.01245" />
                                                        <site name="EDCI-P8" pos="0.03121 -0.09349 -0.02905" />
                                                        <site name="EDCI-P9" pos="0.03013 -0.08487 -0.04268" />
                                                        <site name="EDCI-P10" pos="0.02929 -0.08103 -0.04966" />
                                                        <site name="EDM-P5" pos="-0.02059 -0.01032 0.00372" />
                                                        <site name="EDM-P6" pos="-0.02563 -0.04722 0.00023" />
                                                        <site name="EDM-P7" pos="-0.02549 -0.06511 -0.01098" />
                                                        <site name="EDM-P8" pos="-0.01933 -0.0781 -0.02718" />
                                                        <site name="EDM-P9" pos="-0.01346 -0.07892 -0.03894" />
                                                        <site name="EDM-P10" pos="-0.00216 -0.07521 -0.04589" />
                                                        <site name="EDM-P11" pos="0.00132 -0.07345 -0.04803" />
                                                        <site name="EIP-P4" pos="0.00388 -0.02234 0.01184" />
                                                        <site name="EIP-P5" pos="0.01693 -0.0564 0.01377" />
                                                        <site name="EIP-P6" pos="0.01735 -0.07692 0.00581" />
                                                        <site name="EIP-P7" pos="0.02765 -0.09314 -0.01511" />
                                                        <site name="EIP-P8" pos="0.02879 -0.09437 -0.02823" />
                                                        <site name="EIP-P9" pos="0.0287 -0.08524 -0.04295" />
                                                        <site name="EIP-P10" pos="0.02834 -0.07785 -0.05501" />
                                                        <site name="EPL-P6" pos="0.02428 0.00014 0.00608" />
                                                        <site name="EPL-P7" pos="0.02338 -0.00917 -0.00039" />
                                                        <site name="EPL-P8" pos="0.02905 -0.01427 -0.00489" />
                                                        <site name="EPL-P9" pos="0.04414 -0.03417 -0.01814" />
                                                        <site name="EPL-P10" pos="0.04867 -0.04646 -0.02487" />
                                                        <site name="EPL-P11" pos="0.04751 -0.0701 -0.03774" />
                                                        <site name="EPL-P12" pos="0.04011 -0.07565 -0.04283" />
                                                        <site name="EPB-P5" pos="0.03123 0.00256 -0.00327" />
                                                        <site name="EPB-P6" pos="0.02972 -0.00794 -0.01436" />
                                                        <site name="EPB-P7" pos="0.04422 -0.033 -0.02422" />
                                                        <site name="EPB-P8" pos="0.04528 -0.04785 -0.03186" />
                                                        <site name="FPL-P6" pos="0.01244 -0.02207 -0.02089" />
                                                        <site name="FPL-P7" pos="0.01641 -0.02621 -0.02221" />
                                                        <site name="FPL-P8" pos="0.02457 -0.03294 -0.02237" />
                                                        <site name="FPL-P9" pos="0.02827 -0.05482 -0.03055" />
                                                        <site name="FPL-P10" pos="0.03511 -0.06519 -0.03749" />
                                                        <site name="FPL-P11" pos="0.03533 -0.07656 -0.04118" />
                                                        <site name="FPL-P5" pos="0.0178892 0.0064176 -0.0168214" />
                                                        <site name="APL-P7" pos="0.02587 0.00205 -0.0165" />
                                                        <site name="APL-P8" pos="0.02878 -0.00674 -0.0187" />
                                                        <site name="APL-P9" pos="0.03076 -0.01583 -0.01885" />
                                                        <site name="APL-P6" pos="0.0332244 0.00608975 -0.00870125" />
                                                        <site name="_2rdmcp_FDS-sidesite" pos="0.0182 -0.0399 0.0087" />
                                                        <site name="_2rdmcp_FDP-sidesite" pos="0.0182 -0.0449 0.0087" />
                                                        <site name="_2rdmcp_ext-sidesite" pos="0.0182 -0.0859 0.0087" />
                                                        <site name="_3rdmcp_FDS-sidesite" pos="-0.0253 -0.0655 0.0092" />
                                                        <site name="_3rdmcp_FDP-sidesite" pos="-0.0164 -0.0662 0.0099" />
                                                        <site name="_3rdmcp_ext-sidesite" pos="0.0007 -0.0455 0.0092" />
                                                        <site name="_4rdmcp_FDS-sidesite" pos="-0.0139 -0.0382 0.0033" />
                                                        <site name="_4rdmcp_FDP-sidesite" pos="-0.0139 -0.0432 0.0033" />
                                                        <site name="_4rdmcp_ext-sidesite" pos="0.0061 -0.0642 0.0033" />
                                                        <site name="_5rdmcp_FDS-sidesite" pos="-0.0235 -0.0301 -0.0057" />
                                                        <site name="_5rdmcp_FDP-sidesite" pos="-0.0235 -0.0351 -0.0057" />
                                                        <site name="_5rdmcp_ext-sidesite" pos="-0.0235 -0.0761 -0.0057" />
                                                        <site name="Secondpm_FDS-sidesite" pos="0.0307 -0.0774 -0.0222" />
                                                        <site name="Secondpm_FDP-sidesite" pos="0.0307 -0.0764 -0.0222" />
                                                        <site name="Secondpm_ext-sidesite" pos="0.0307 -0.1034 -0.0222" />
                                                        <site name="Secondmd_flex-sidesite" pos="0.0291 -0.0721 -0.045" />
                                                        <site name="Secondmd_ext-sidesite" pos="0.0291 -0.0861 -0.045" />
                                                        <site name="Secondmd-sidesite" pos="0.0355 -0.0815 -0.0441" />
                                                        <site name="IPthumb-sidesite" pos="0.0306 -0.0713 -0.0365" />
                                                        <site name="Thirdpm_FDS-sidesite" pos="0.0122 -0.0784 -0.0238" />
                                                        <site name="Thirdpm_FDP-sidesite" pos="0.0122 -0.0774 -0.0238" />
                                                        <site name="Thirdpm_ext-sidesite" pos="0.0122 -0.1044 -0.0238" />
                                                        <site name="Thirdmd_flex-sidesite" pos="0.019 -0.0714 -0.0494" />
                                                        <site name="Thirdmd_ext-sidesite" pos="0.019 -0.0854 -0.0494" />
                                                        <site name="Fourthpm_FDS-sidesite" pos="-0.005 -0.0721 -0.0289" />
                                                        <site name="Fourthpm_FDP-sidesite" pos="-0.005 -0.0711 -0.0289" />
                                                        <site name="Fourthpm_ext-sidesite" pos="-0.005 -0.0981 -0.0289" />
                                                        <site name="Fourthmd_flex-sidesite" pos="0.0094 -0.0678 -0.0469" />
                                                        <site name="Fourthmd_ext-sidesite" pos="0.0094 -0.0818 -0.0469" />
                                                        <site name="Fifthpm_FDS-sidesite" pos="-0.0154 -0.0634 -0.0329" />
                                                        <site name="Fifthpm_FDP-sidesite" pos="-0.0153 -0.0626 -0.0329" />
                                                        <site name="Fifthpm_ext-sidesite" pos="-0.0152 -0.0895 -0.0328" />
                                                        <site name="Fifthmd_flex-sidesite" pos="0.0007 -0.0641 -0.0457" />
                                                        <site name="Fifthmd_ext-sidesite" pos="0.007 -0.0781 -0.0457" />
                                                        <site name="_2ndmcp-sidesite" pos="0.0106 -0.068 0.0044" />
                                                        <body name="index0" pos="0 0 0">
                                                            <inertial pos="0 0 0" mass="0.001" diaginertia="0.001 0.001 0.001" />
                                                            <geom name="sdfast_1seg_hand_fr_c_2mc" type="mesh" mesh="sdfast_1seg_hand_fr_c_2mc" />
                                                            <body name="index1" pos="0 0 0">
                                                                <inertial pos="0 0 0" mass="0.001" diaginertia="0.001 0.001 0.001" />
                                                                <geom name="hand_2proxph" type="mesh" mesh="hand_2proxph" />
                                                                <body name="index2" pos="0 0 0">
                                                                    <inertial pos="0 0 0" mass="0.001" diaginertia="0.001 0.001 0.001" />
                                                                    <geom name="hand_2midph" type="mesh" mesh="hand_2midph" />
                                                                    <body name="index3" pos="0 0 0">
                                                                        <inertial pos="0 0 0" mass="0.001" diaginertia="0.001 0.001 0.001" />
                                                                        <geom name="hand_2distph" type="mesh" mesh="hand_2distph" />
                                                                    </body>
                                                                </body>
                                                            </body>
                                                        </body>
                                                    </body>
                                                </body>
                                            </body>
                                        </body>
                                    </body>
                                </body>
                            </body>
                        </body>
                    </body>
                </body>
            </body>
        </body>
    </worldbody>
    <equality>
        <joint name="sternoclavicular_r2_con" joint1="sternoclavicular_r2" joint2="shoulder_elv" polycoef="0 -0.242001 0 0 0" solimp="0.9999 0.9999 0.001 0.5 2" />
        <joint name="sternoclavicular_r3_con" joint1="sternoclavicular_r3" joint2="shoulder_elv" polycoef="0 0.1025 0 0 0" solimp="0.9999 0.9999 0.001 0.5 2" />
        <joint name="unrotscap_r2_con" joint1="unrotscap_r2" joint2="shoulder_elv" polycoef="0 0.242001 0 0 0" solimp="0.9999 0.9999 0.001 0.5 2" />
        <joint name="unrotscap_r3_con" joint1="unrotscap_r3" joint2="shoulder_elv" polycoef="0 -0.1025 0 0 0" solimp="0.9999 0.9999 0.001 0.5 2" />
        <joint name="acromioclavicular_r1_con" joint1="acromioclavicular_r1" joint2="shoulder_elv" polycoef="0 0.178 0 0 0" solimp="0.9999 0.9999 0.001 0.5 2" />
        <joint name="acromioclavicular_r2_con" joint1="acromioclavicular_r2" joint2="shoulder_elv" polycoef="0 -0.0490002 0 0 0" solimp="0.9999 0.9999 0.001 0.5 2" />
        <joint name="acromioclavicular_r3_con" joint1="acromioclavicular_r3" joint2="shoulder_elv" polycoef="0 0.396002 0 0 0" solimp="0.9999 0.9999 0.001 0.5 2" />
        <joint name="unrothum_r1_con" joint1="unrothum_r1" joint2="shoulder_elv" polycoef="0 -0.178 0 0 0" solimp="0.9999 0.9999 0.001 0.5 2" />
        <joint name="unrothum_r2_con" joint1="unrothum_r2" joint2="shoulder_elv" polycoef="0 0.0490002 0 0 0" solimp="0.9999 0.9999 0.001 0.5 2" />
        <joint name="unrothum_r3_con" joint1="unrothum_r3" joint2="shoulder_elv" polycoef="0 -0.396002 0 0 0" solimp="0.9999 0.9999 0.001 0.5 2" />
        <joint name="shoulder1_r2_con" joint1="shoulder1_r2" joint2="elv_angle" polycoef="0 -1 0 0 0" solimp="0.9999 0.9999 0.001 0.5 2" />
        <joint name="r_z_constraint" joint1="r_z" polycoef="0 0 0 0 0" />
        <weld name="origin_to_worldbody" body1="thorax" relpose="0 0 0 1 0 0 0" active="false" />
    </equality>
    <tendon>
        <spatial name="DELT1_tendon">
            <site site="DELT1-P1" />
            <geom geom="delt2hum" />
            <site site="DELT1-P2" />
            <geom geom="DELT1hh" sidesite="DELT1hh-sidesite" />
            <site site="DELT1-P3" />
            <geom geom="delt2hum" />
            <site site="DELT1-P4" />
        </spatial>
        <spatial name="DELT2_tendon">
            <site site="DELT2-P1" />
            <geom geom="Deltoid2" sidesite="Deltoid2-sidesite" />
            <site site="DELT2-P2" />
            <geom geom="Deltoid2" sidesite="Deltoid2-sidesite" />
            <site site="DELT2-P3" />
            <geom geom="Deltoid2" sidesite="Deltoid2-sidesite" />
            <site site="DELT2-P4" />
        </spatial>
        <spatial name="DELT3_tendon">
            <site site="DELT3-P1" />
            <geom geom="Delt3" sidesite="Delt3-sidesite_torus" />
            <site site="DELT3-P2" />
            <geom geom="DELT_TMAJ_LAT_PEC_CORBhh" />
            <site site="DELT3-P3" />
        </spatial>
        <spatial name="SUPSP_tendon">
            <site site="SUPSP-P1" />
            <geom geom="SUPSP" />
            <site site="SUPSP-P2" />
            <geom geom="SUPSP" />
            <site site="SUPSP-P3" />
        </spatial>
        <spatial name="INFSP_tendon">
            <site site="INFSP-P1" />
            <geom geom="infsp_new" sidesite="infsp_new-sidesite" />
            <site site="INFSP-P2" />
        </spatial>
        <spatial name="SUBSC_tendon">
            <site site="SUBSC-P1" />
            <geom geom="SUBSCAP" />
            <site site="SUBSC-P2" />
            <geom geom="SUBSCAP" />
            <site site="SUBSC-P3" />
        </spatial>
        <spatial name="TMIN_tendon">
            <site site="TMIN-P1" />
            <geom geom="TMIN" sidesite="TMIN-sidesite" />
            <site site="TMIN-P2" />
            <site site="TMIN-P3" />
        </spatial>
        <spatial name="TMAJ_tendon">
            <site site="TMAJ-P1" />
            <geom geom="LAT_TMAJ2hh" />
            <site site="TMAJ-P2" />
            <geom geom="LAT_TMAJ2hh" />
            <site site="TMAJ-P3" />
        </spatial>
        <spatial name="PECM1_tendon">
            <site site="PECM1-P1" />
            <geom geom="Thorax" />
            <site site="PECM1-P2" />
            <geom geom="Thorax" />
            <site site="PECM1-P3" />
            <geom geom="Thorax" />
            <site site="PECM1-P4" />
        </spatial>
        <spatial name="PECM2_tendon">
            <site site="PECM2-P1" />
            <geom geom="Thorax" />
            <site site="PECM2-P2" />
            <geom geom="Thorax" />
            <site site="PECM2-P3" />
            <geom geom="Thorax" />
            <site site="PECM2-P4" />
            <geom geom="Thorax" />
            <site site="PECM2-P5" />
        </spatial>
        <spatial name="PECM3_tendon">
            <site site="PECM3-P1" />
            <geom geom="Thorax" />
            <site site="PECM3-P2" />
            <geom geom="Thorax" />
            <site site="PECM3-P3" />
            <geom geom="Thorax" />
            <site site="PECM3-P4" />
            <geom geom="Thorax" />
            <site site="PECM3-P5" />
        </spatial>
        <spatial name="LAT1_tendon">
            <site site="LAT1-P1" />
            <geom geom="LAT_TMAJ2hh" />
            <site site="LAT1-P2" />
            <geom geom="LAT_TMAJ2hh" />
            <site site="LAT1-P3" />
            <geom geom="LAT_TMAJ2hh" />
            <site site="LAT1-P4" />
            <geom geom="LAT_TMAJ2hh" />
            <site site="LAT1-P5" />
        </spatial>
        <spatial name="LAT2_tendon">
            <site site="LAT2-P1" />
            <geom geom="LAT_TMAJ2hh" />
            <site site="LAT2-P2" />
            <geom geom="LAT_TMAJ2hh" />
            <site site="LAT2-P3" />
            <geom geom="LAT_TMAJ2hh" />
            <site site="LAT2-P4" />
            <geom geom="LAT_TMAJ2hh" />
            <site site="LAT2-P5" />
        </spatial>
        <spatial name="LAT3_tendon">
            <site site="LAT3-P1" />
            <geom geom="LAT_TMAJ2hh" />
            <site site="LAT3-P2" />
            <geom geom="LAT_TMAJ2hh" />
            <site site="LAT3-P3" />
            <geom geom="LAT_TMAJ2hh" />
            <site site="LAT3-P4" />
            <geom geom="LAT_TMAJ2hh" />
            <site site="LAT3-P5" />
        </spatial>
        <spatial name="CORB_tendon">
            <site site="CORB-P1" />
            <geom geom="TMAJ_LAT_PEC_CORBhh" />
            <site site="CORB-P2" />
            <geom geom="TMAJ_LAT_PEC_CORBhh" />
            <site site="CORB-P3" />
        </spatial>
        <spatial name="TRIlong_tendon">
            <site site="TRIlong-P1" />
            <geom geom="TRIlonghh" sidesite="TRIlonghh-sidesite" />
            <site site="TRIlong-P2" />
            <geom geom="TRIlonghh" sidesite="TRIlonghh-sidesite" />
            <site site="TRIlong-P3" />
            <geom geom="TRIlonghh" sidesite="TRIlonghh-sidesite" />
            <site site="TRIlong-P4" />
            <geom geom="TRIlonghh" sidesite="TRIlonghh-sidesite" />
            <site site="TRIlong-P5" />
        </spatial>
        <spatial name="TRIlat_tendon">
            <site site="TRIlat-P1" />
            <geom geom="TRI" />
            <site site="TRIlat-P2" />
            <geom geom="TRI" />
            <site site="TRIlat-P3" />
            <geom geom="TRI" />
            <site site="TRIlat-P4" />
            <geom geom="TRI" />
            <site site="TRIlat-P5" />
        </spatial>
        <spatial name="TRImed_tendon">
            <site site="TRImed-P1" />
            <geom geom="TRI" />
            <site site="TRImed-P2" />
            <geom geom="TRI" />
            <site site="TRImed-P3" />
            <geom geom="TRI" />
            <site site="TRImed-P4" />
            <geom geom="TRI" />
            <site site="TRImed-P5" />
        </spatial>
        <spatial name="ANC_tendon">
            <site site="ANC-P1" />
            <geom geom="ANC" sidesite="ANC-sidesite" />
            <site site="ANC-P2" />
        </spatial>
        <spatial name="SUP_tendon">
            <site site="SUP-P1" />
            <geom geom="SUP" sidesite="SUP-sidesite" />
            <site site="SUP-P2" />
            <geom geom="SUP" sidesite="SUP-sidesite" />
            <site site="SUP-P3" />
        </spatial>
        <spatial name="BIClong_tendon">
            <site site="BIClong-P1" />
            <geom geom="Elbow_BIC_BRD" sidesite="Elbow_BIC_BRD-sidesite" />
            <site site="BIClong-P2" />
            <geom geom="BIClong" sidesite="BIClong-sidesite" />
            <site site="BIClong-P3" />
            <geom geom="BIClong" sidesite="BIClong-sidesite" />
            <site site="BIClong-P4" />
            <geom geom="BIClong" sidesite="BIClong-sidesite" />
            <site site="BIClong-P5" />
            <geom geom="Elbow_BIC_BRD" sidesite="Elbow_BIC_BRD-sidesite" />
            <site site="BIClong-P6" />
            <geom geom="Elbow_BIC_BRD" sidesite="Elbow_BIC_BRD-sidesite" />
            <site site="BIClong-P7" />
            <geom geom="Elbow_BIC_BRD" sidesite="Elbow_BIC_BRD-sidesite" />
            <site site="BIClong-P8" />
            <geom geom="Elbow_BIC_BRD" sidesite="Elbow_BIC_BRD-sidesite" />
            <site site="BIClong-P9" />
            <geom geom="Elbow_BIC_BRD" sidesite="Elbow_BIC_BRD-sidesite" />
            <site site="BIClong-P11" />
        </spatial>
        <spatial name="BICshort_tendon">
            <site site="BICshort-P1" />
            <geom geom="Elbow_BIC_BRD" sidesite="Elbow_BIC_BRD-sidesite" />
            <site site="BICshort-P2" />
            <geom geom="Elbow_BIC_BRD" sidesite="Elbow_BIC_BRD-sidesite" />
            <site site="BICshort-P3" />
            <geom geom="Elbow_BIC_BRD" sidesite="Elbow_BIC_BRD-sidesite" />
            <site site="BICshort-P4" />
            <geom geom="Elbow_BIC_BRD" sidesite="Elbow_BIC_BRD-sidesite" />
            <site site="BICshort-P5" />
            <geom geom="Elbow_BIC_BRD" sidesite="Elbow_BIC_BRD-sidesite" />
            <site site="BICshort-P6" />
            <geom geom="Elbow_BIC_BRD" sidesite="Elbow_BIC_BRD-sidesite" />
            <site site="BICshort-P8" />
        </spatial>
        <spatial name="BRA_tendon">
            <site site="BRA-P1" />
            <site site="BRA-P2" />
            <site site="BRA-P3" />
            <site site="BRA-P4" />
        </spatial>
        <spatial name="BRD_tendon">
            <site site="BRD-P1" />
            <geom geom="Elbow_BIC_BRD" sidesite="Elbow_BIC_BRD-sidesite" />
            <site site="BRD-P2" />
            <geom geom="Elbow_BIC_BRD" sidesite="Elbow_BIC_BRD-sidesite" />
            <site site="BRD-P3" />
        </spatial>
        <spatial name="ECRL_tendon">
            <site site="ECRL-P1" />
            <geom geom="Elbow_PT_ECRL" sidesite="Elbow_PT_ECRL-sidesite" />
            <site site="ECRL-P2" />
            <geom geom="Elbow_PT_ECRL" sidesite="Elbow_PT_ECRL-sidesite" />
            <site site="ECRL-P3" />
            <geom geom="Elbow_PT_ECRL" sidesite="Elbow_PT_ECRL-sidesite" />
            <site site="ECRL-P4" />
        </spatial>
        <spatial name="ECRB_tendon">
            <site site="ECRB-P1" />
            <geom geom="ECRB" sidesite="ECRB-sidesite_torus" />
            <site site="ECRB-P2" />
            <geom geom="ECRB" sidesite="ECRB-sidesite_torus" />
            <site site="ECRB-P3" />
            <geom geom="ECRB" sidesite="ECRB-sidesite_torus" />
            <site site="ECRB-P4" />
        </spatial>
        <spatial name="ECU_tendon">
            <site site="ECU-P1" />
            <geom geom="ECU" sidesite="ECU-sidesite_torus" />
            <site site="ECU-P2" />
            <geom geom="ECU" sidesite="ECU-sidesite_torus" />
            <site site="ECU-P3" />
            <geom geom="ECU" sidesite="ECU-sidesite_torus" />
            <site site="ECU-P4" />
            <geom geom="ECU" sidesite="ECU-sidesite_torus" />
            <site site="ECU-P5" />
            <geom geom="ECU" sidesite="ECU-sidesite_torus" />
            <site site="ECU-P6" />
        </spatial>
        <spatial name="FCR_tendon">
            <site site="FCR-P1" />
            <geom geom="Elbow_PT_ECRL" sidesite="Elbow_PT_ECRL-sidesite" />
            <site site="FCR-P2" />
            <geom geom="Elbow_PT_ECRL" sidesite="Elbow_PT_ECRL-sidesite" />
            <site site="FCR-P3" />
        </spatial>
        <spatial name="FCU_tendon">
            <site site="FCU-P1" />
            <geom geom="Elbow_PT_ECRL" sidesite="Elbow_PT_ECRL-sidesite" />
            <site site="FCU-P2" />
            <geom geom="Elbow_PT_ECRL" sidesite="Elbow_PT_ECRL-sidesite" />
            <site site="FCU-P3" />
            <geom geom="Elbow_PT_ECRL" sidesite="Elbow_PT_ECRL-sidesite" />
            <site site="FCU-P4" />
        </spatial>
        <spatial name="PL_tendon">
            <site site="PL-P1" />
            <geom geom="Elbow_PT_ECRL" sidesite="Elbow_PT_ECRL-sidesite" />
            <site site="PL-P2" />
            <geom geom="Elbow_PT_ECRL" sidesite="Elbow_PT_ECRL-sidesite" />
            <site site="PL-P3" />
            <geom geom="Elbow_PT_ECRL" sidesite="Elbow_PT_ECRL-sidesite" />
            <site site="PL-P4" />
        </spatial>
        <spatial name="PT_tendon">
            <site site="PT-P1" />
            <geom geom="Elbow_PT_ECRL" sidesite="Elbow_PT_ECRL-sidesite" />
            <site site="PT-P2" />
            <geom geom="Elbow_PT_ECRL" sidesite="Elbow_PT_ECRL-sidesite" />
            <site site="PT-P3" />
            <geom geom="Elbow_PT_ECRL" sidesite="Elbow_PT_ECRL-sidesite" />
            <site site="PT-P4" />
            <geom geom="Elbow_PT_ECRL" sidesite="Elbow_PT_ECRL-sidesite" />
            <site site="PT-P5" />
        </spatial>
        <spatial name="PQ_tendon">
            <site site="PQ-P1" />
            <geom geom="PQ1" />
            <site site="PQ-P2" />
        </spatial>
        <spatial name="FDSL_tendon">
            <site site="FDSL-P1" />
            <geom geom="Elbow_PT_ECRL" sidesite="Elbow_PT_ECRL-sidesite" />
            <site site="FDSL-P2" />
            <geom geom="Elbow_PT_ECRL" sidesite="Elbow_PT_ECRL-sidesite" />
            <site site="FDSL-P3" />
            <geom geom="Elbow_PT_ECRL" sidesite="Elbow_PT_ECRL-sidesite" />
            <site site="FDSL-P4" />
            <geom geom="Elbow_PT_ECRL" sidesite="Elbow_PT_ECRL-sidesite" />
            <site site="FDSL-P5" />
            <geom geom="Elbow_PT_ECRL" sidesite="Elbow_PT_ECRL-sidesite" />
            <site site="FDSL-P6" />
            <geom geom="Elbow_PT_ECRL" sidesite="Elbow_PT_ECRL-sidesite" />
            <site site="FDSL-P7" />
            <geom geom="Elbow_PT_ECRL" sidesite="Elbow_PT_ECRL-sidesite" />
            <site site="FDSL-P8" />
        </spatial>
        <spatial name="FDSR_tendon">
            <site site="FDSR-P1" />
            <geom geom="Elbow_PT_ECRL" sidesite="Elbow_PT_ECRL-sidesite" />
            <site site="FDSR-P2" />
            <geom geom="Elbow_PT_ECRL" sidesite="Elbow_PT_ECRL-sidesite" />
            <site site="FDSR-P3" />
            <geom geom="Elbow_PT_ECRL" sidesite="Elbow_PT_ECRL-sidesite" />
            <site site="FDSR-P4" />
            <geom geom="Elbow_PT_ECRL" sidesite="Elbow_PT_ECRL-sidesite" />
            <site site="FDSR-P5" />
            <geom geom="Elbow_PT_ECRL" sidesite="Elbow_PT_ECRL-sidesite" />
            <site site="FDSR-P6" />
            <geom geom="Elbow_PT_ECRL" sidesite="Elbow_PT_ECRL-sidesite" />
            <site site="FDSR-P7" />
            <geom geom="Elbow_PT_ECRL" sidesite="Elbow_PT_ECRL-sidesite" />
            <site site="FDSR-P8" />
        </spatial>
        <spatial name="FDSM_tendon">
            <site site="FDSM-P1" />
            <geom geom="FDS" sidesite="FDS-sidesite" />
            <site site="FDSM-P2" />
            <geom geom="FDS" sidesite="FDS-sidesite" />
            <site site="FDSM-P3" />
            <geom geom="FDS" sidesite="FDS-sidesite" />
            <site site="FDSM-P4" />
            <geom geom="FDS" sidesite="FDS-sidesite" />
            <site site="FDSM-P5" />
            <geom geom="_3rdmcp_FDS" sidesite="_3rdmcp_FDS-sidesite" />
            <site site="FDSM-P6" />
            <geom geom="FDS" sidesite="FDS-sidesite" />
            <site site="FDSM-P7" />
            <geom geom="FDS" sidesite="FDS-sidesite" />
            <site site="FDSM-P8" />
            <geom geom="FDS" sidesite="FDS-sidesite" />
            <site site="FDSM-P9" />
        </spatial>
        <spatial name="FDSI_tendon">
            <site site="FDSI-P1" />
            <geom geom="FDS" sidesite="FDS-sidesite" />
            <site site="FDSI-P2" />
            <geom geom="FDS" sidesite="FDS-sidesite" />
            <site site="FDSI-P3" />
            <geom geom="FDS" sidesite="FDS-sidesite" />
            <site site="FDSI-P4" />
            <geom geom="FDS" sidesite="FDS-sidesite" />
            <site site="FDSI-P5" />
            <geom geom="_2rdmcp_FDS" sidesite="_2rdmcp_FDS-sidesite" />
            <site site="FDSI-P6" />
            <geom geom="FDS" sidesite="FDS-sidesite" />
            <site site="FDSI-P7" />
            <geom geom="FDS" sidesite="FDS-sidesite" />
            <site site="FDSI-P8" />
            <geom geom="FDS" sidesite="FDS-sidesite" />
            <site site="FDSI-P9" />
        </spatial>
        <spatial name="FDPL_tendon">
            <site site="FDPL-P1" />
            <geom geom="FDP" sidesite="FDP-sidesite" />
            <site site="FDPL-P2" />
            <geom geom="FDP" sidesite="FDP-sidesite" />
            <site site="FDPL-P3" />
            <geom geom="FDP" sidesite="FDP-sidesite" />
            <site site="FDPL-P4" />
            <geom geom="FDP" sidesite="FDP-sidesite" />
            <site site="FDPL-P5" />
            <geom geom="FDP" sidesite="FDP-sidesite" />
            <site site="FDPL-P6" />
            <geom geom="FDP" sidesite="FDP-sidesite" />
            <site site="FDPL-P7" />
            <geom geom="FDP" sidesite="FDP-sidesite" />
            <site site="FDPL-P8" />
            <geom geom="FDP" sidesite="FDP-sidesite" />
            <site site="FDPL-P9" />
        </spatial>
        <spatial name="FDPR_tendon">
            <site site="FDPR-P1" />
            <geom geom="FDP" sidesite="FDP-sidesite" />
            <site site="FDPR-P2" />
            <geom geom="FDP" sidesite="FDP-sidesite" />
            <site site="FDPR-P3" />
            <geom geom="FDP" sidesite="FDP-sidesite" />
            <site site="FDPR-P4" />
            <geom geom="FDP" sidesite="FDP-sidesite" />
            <site site="FDPR-P5" />
            <geom geom="FDP" sidesite="FDP-sidesite" />
            <site site="FDPR-P6" />
            <geom geom="FDP" sidesite="FDP-sidesite" />
            <site site="FDPR-P7" />
            <geom geom="FDP" sidesite="FDP-sidesite" />
            <site site="FDPR-P8" />
            <geom geom="FDP" sidesite="FDP-sidesite" />
            <site site="FDPR-P9" />
        </spatial>
        <spatial name="FDPM_tendon">
            <site site="FDPM-P1" />
            <geom geom="FDP" sidesite="FDP-sidesite" />
            <site site="FDPM-P2" />
            <geom geom="FDP" sidesite="FDP-sidesite" />
            <site site="FDPM-P3" />
            <geom geom="FDP" sidesite="FDP-sidesite" />
            <site site="FDPM-P4" />
            <geom geom="FDP" sidesite="FDP-sidesite" />
            <site site="FDPM-P5" />
            <geom geom="FDP" sidesite="FDP-sidesite" />
            <site site="FDPM-P6" />
            <geom geom="FDP" sidesite="FDP-sidesite" />
            <site site="FDPM-P7" />
            <geom geom="FDP" sidesite="FDP-sidesite" />
            <site site="FDPM-P8" />
            <geom geom="FDP" sidesite="FDP-sidesite" />
            <site site="FDPM-P9" />
            <geom geom="FDP" sidesite="FDP-sidesite" />
            <site site="FDPM-P10" />
        </spatial>
        <spatial name="FDPI_tendon">
            <site site="FDPI-P1" />
            <geom geom="FDP" sidesite="FDP-sidesite" />
            <site site="FDPI-P2" />
            <geom geom="FDP" sidesite="FDP-sidesite" />
            <site site="FDPI-P3" />
            <geom geom="FDP" sidesite="FDP-sidesite" />
            <site site="FDPI-P4" />
            <geom geom="FDP" sidesite="FDP-sidesite" />
            <site site="FDPI-P5" />
            <geom geom="FDP" sidesite="FDP-sidesite" />
            <site site="FDPI-P6" />
            <geom geom="FDP" sidesite="FDP-sidesite" />
            <site site="FDPI-P7" />
            <geom geom="FDP" sidesite="FDP-sidesite" />
            <site site="FDPI-P8" />
            <geom geom="FDP" sidesite="FDP-sidesite" />
            <site site="FDPI-P9" />
        </spatial>
        <spatial name="EDCL_tendon">
            <site site="EDCL-P1" />
            <site site="EDCL-P2" />
            <site site="EDCL-P3" />
            <geom geom="EDCL" sidesite="EDCL-sidesite_torus" />
            <site site="EDCL-P4" />
            <site site="EDCL-P5" />
            <geom geom="_5rdmcp_ext" sidesite="_5rdmcp_ext-sidesite" />
            <site site="EDCL-P6" />
            <site site="EDCL-P7" />
            <geom geom="Fifthpm_ext" sidesite="Fifthpm_ext-sidesite" />
            <site site="EDCL-P8" />
            <site site="EDCL-P9" />
            <geom geom="Fifthmd_ext" sidesite="Fifthmd_ext-sidesite" />
            <site site="EDCL-P10" />
        </spatial>
        <spatial name="EDCR_tendon">
            <site site="EDCR-P1" />
            <geom geom="EDCR" sidesite="EDCR-sidesite_torus" />
            <site site="EDCR-P2" />
            <geom geom="EDCR" sidesite="EDCR-sidesite_torus" />
            <site site="EDCR-P3" />
            <geom geom="EDCR" sidesite="EDCR-sidesite_torus" />
            <site site="EDCR-P4" />
            <geom geom="EDCR" sidesite="EDCR-sidesite_torus" />
            <site site="EDCR-P5" />
            <geom geom="EDCR" sidesite="EDCR-sidesite_torus" />
            <site site="EDCR-P6" />
            <geom geom="EDCR" sidesite="EDCR-sidesite_torus" />
            <site site="EDCR-P7" />
            <geom geom="EDCR" sidesite="EDCR-sidesite_torus" />
            <site site="EDCR-P8" />
            <geom geom="EDCR" sidesite="EDCR-sidesite_torus" />
            <site site="EDCR-P9" />
            <geom geom="EDCR" sidesite="EDCR-sidesite_torus" />
            <site site="EDCR-P10" />
        </spatial>
        <spatial name="EDCM_tendon">
            <site site="EDCM-P1" />
            <geom geom="EDCM" sidesite="EDCM-sidesite_torus" />
            <site site="EDCM-P2" />
            <geom geom="EDCM" sidesite="EDCM-sidesite_torus" />
            <site site="EDCM-P3" />
            <geom geom="EDCM" sidesite="EDCM-sidesite_torus" />
            <site site="EDCM-P4" />
            <site site="EDCM-P5" />
            <geom geom="_3rdmcp_ext" sidesite="_3rdmcp_ext-sidesite" />
            <site site="EDCM-P6" />
            <site site="EDCM-P7" />
            <geom geom="Thirdpm_ext" sidesite="Thirdpm_ext-sidesite" />
            <site site="EDCM-P8" />
            <site site="EDCM-P9" />
            <geom geom="Thirdmd_ext" sidesite="Thirdmd_ext-sidesite" />
            <site site="EDCM-P10" />
            <site site="EDCM-P11" />
        </spatial>
        <spatial name="EDCI_tendon">
            <site site="EDCI-P1" />
            <site site="EDCI-P2" />
            <site site="EDCI-P3" />
            <geom geom="EDCI" sidesite="EDCI-sidesite_torus" />
            <site site="EDCI-P4" />
            <site site="EDCI-P5" />
            <geom geom="_2rdmcp_ext" sidesite="_2rdmcp_ext-sidesite" />
            <site site="EDCI-P6" />
            <site site="EDCI-P7" />
            <geom geom="Secondpm_ext" sidesite="Secondpm_ext-sidesite" />
            <site site="EDCI-P8" />
            <site site="EDCI-P9" />
            <geom geom="Secondmd_ext" sidesite="Secondmd_ext-sidesite" />
            <site site="EDCI-P10" />
        </spatial>
        <spatial name="EDM_tendon">
            <site site="EDM-P1" />
            <site site="EDM-P2" />
            <site site="EDM-P3" />
            <site site="EDM-P4" />
            <geom geom="EDM" sidesite="EDM-sidesite" />
            <site site="EDM-P5" />
            <site site="EDM-P6" />
            <geom geom="_5rdmcp_ext" sidesite="_5rdmcp_ext-sidesite" />
            <site site="EDM-P7" />
            <site site="EDM-P8" />
            <geom geom="Fifthpm_ext" sidesite="Fifthpm_ext-sidesite" />
            <site site="EDM-P9" />
            <site site="EDM-P10" />
            <geom geom="Fifthmd_ext" sidesite="Fifthmd_ext-sidesite" />
            <site site="EDM-P11" />
        </spatial>
        <spatial name="EIP_tendon">
            <site site="EIP-P1" />
            <geom geom="Extensor_ellipse" sidesite="Extensor_ellipse-sidesite" />
            <site site="EIP-P2" />
            <geom geom="Extensor_ellipse" sidesite="Extensor_ellipse-sidesite" />
            <site site="EIP-P3" />
            <geom geom="Extensor_ellipse" sidesite="Extensor_ellipse-sidesite" />
            <site site="EIP-P4" />
            <geom geom="Extensor_ellipse" sidesite="Extensor_ellipse-sidesite" />
            <site site="EIP-P5" />
            <geom geom="Extensor_ellipse" sidesite="Extensor_ellipse-sidesite" />
            <site site="EIP-P6" />
            <geom geom="Extensor_ellipse" sidesite="Extensor_ellipse-sidesite" />
            <site site="EIP-P7" />
            <geom geom="Extensor_ellipse" sidesite="Extensor_ellipse-sidesite" />
            <site site="EIP-P8" />
            <geom geom="Extensor_ellipse" sidesite="Extensor_ellipse-sidesite" />
            <site site="EIP-P9" />
            <geom geom="Extensor_ellipse" sidesite="Extensor_ellipse-sidesite" />
            <site site="EIP-P10" />
        </spatial>
        <spatial name="EPL_tendon">
            <site site="EPL-P1" />
            <geom geom="MPthumb" />
            <site site="EPL-P2" />
            <geom geom="MPthumb" />
            <site site="EPL-P3" />
            <geom geom="MPthumb" />
            <site site="EPL-P4" />
            <geom geom="MPthumb" />
            <site site="EPL-P5" />
            <geom geom="MPthumb" />
            <site site="EPL-P6" />
            <geom geom="MPthumb" />
            <site site="EPL-P7" />
            <geom geom="MPthumb" />
            <site site="EPL-P8" />
            <geom geom="MPthumb" />
            <site site="EPL-P9" />
            <geom geom="MPthumb" />
            <site site="EPL-P10" />
            <geom geom="MPthumb" />
            <site site="EPL-P11" />
            <geom geom="MPthumb" />
            <site site="EPL-P12" />
        </spatial>
        <spatial name="EPB_tendon">
            <site site="EPB-P1" />
            <geom geom="MPthumb" />
            <site site="EPB-P2" />
            <geom geom="MPthumb" />
            <site site="EPB-P3" />
            <geom geom="MPthumb" />
            <site site="EPB-P4" />
            <geom geom="MPthumb" />
            <site site="EPB-P5" />
            <geom geom="MPthumb" />
            <site site="EPB-P6" />
            <geom geom="MPthumb" />
            <site site="EPB-P7" />
            <geom geom="MPthumb" />
            <site site="EPB-P8" />
        </spatial>
        <spatial name="FPL_tendon">
            <site site="FPL-P1" />
            <geom geom="FPL" sidesite="FPL-sidesite" />
            <site site="FPL-P2" />
            <geom geom="FPL" sidesite="FPL-sidesite" />
            <site site="FPL-P3" />
            <geom geom="FPL" sidesite="FPL-sidesite" />
            <site site="FPL-P4" />
            <geom geom="FPL" sidesite="FPL-sidesite" />
            <site site="FPL-P5" />
            <geom geom="FPL" sidesite="FPL-sidesite" />
            <site site="FPL-P6" />
            <geom geom="FPL" sidesite="FPL-sidesite" />
            <site site="FPL-P7" />
            <geom geom="FPL" sidesite="FPL-sidesite" />
            <site site="FPL-P8" />
            <geom geom="FPL" sidesite="FPL-sidesite" />
            <site site="FPL-P9" />
            <geom geom="FPL" sidesite="FPL-sidesite" />
            <site site="FPL-P10" />
            <geom geom="FPL" sidesite="FPL-sidesite" />
            <site site="FPL-P11" />
        </spatial>
        <spatial name="APL_tendon">
            <site site="APL-P1" />
            <site site="APL-P2" />
            <site site="APL-P3" />
            <site site="APL-P4" />
            <site site="APL-P5" />
            <site site="APL-P6" />
            <site site="APL-P7" />
            <site site="APL-P8" />
            <site site="APL-P9" />
        </spatial>
    </tendon>
    <actuator>
        <general name="oculomotor-rx" class="oculomotor" joint="eye-rx" gainprm="0.5 1.5 0 0 0 0 0 0 0 0" />
        <general name="oculomotor-ry" class="oculomotor" joint="eye-ry" gainprm="0.5 1.5 0 0 0 0 0 0 0 0" />
        <general name="DELT1" class="muscle" tendon="DELT1_tendon" lengthrange="0.138246 0.22874" gainprm="0.5 1.5 1218.9 2000 0.4327 1.595 10 0.725016 1.4 0" biasprm="0.75 1.05 1218.9 2000 0.5 1.6 1.5 1.3 1.2 0" />
        <general name="DELT2" class="muscle" tendon="DELT2_tendon" lengthrange="0.161563 0.26569" gainprm="0.5 1.5 1103.5 2000 0.4327 1.595 10 0.725016 1.4 0" biasprm="0.75 1.05 1103.5 2000 0.5 1.6 1.5 1.3 1.2 0" />
        <general name="DELT3" class="muscle" tendon="DELT3_tendon" lengthrange="0.103005 0.233014" gainprm="0.5 1.5 201.6 2000 0.4327 1.595 10 0.725016 1.4 0" biasprm="0.75 1.05 201.6 2000 0.5 1.6 1.5 1.3 1.2 0" />
        <general name="SUPSP" class="muscle" tendon="SUPSP_tendon" lengthrange="0.0733455 0.141038" gainprm="0.5 1.5 499.2 2000 0.4327 1.595 10 0.725016 1.4 0" biasprm="0.75 1.05 499.2 2000 0.5 1.6 1.5 1.3 1.2 0" />
        <general name="INFSP" class="muscle" tendon="INFSP_tendon" lengthrange="0.0664931 0.13788" gainprm="0.5 1.5 1075.8 2000 0.4327 1.595 10 0.725016 1.4 0" biasprm="0.75 1.05 1075.8 2000 0.5 1.6 1.5 1.3 1.2 0" />
        <general name="SUBSC" class="muscle" tendon="SUBSC_tendon" lengthrange="0.0740172 0.156053" gainprm="0.5 1.5 1306.9 2000 0.4327 1.595 10 0.725016 1.4 0" biasprm="0.75 1.05 1306.9 2000 0.5 1.6 1.5 1.3 1.2 0" />
        <general name="TMIN" class="muscle" tendon="TMIN_tendon" lengthrange="0.105146 0.172841" gainprm="0.5 1.5 269.5 2000 0.4327 1.595 10 0.725016 1.4 0" biasprm="0.75 1.05 269.5 2000 0.5 1.6 1.5 1.3 1.2 0" />
        <general name="TMAJ" class="muscle" tendon="TMAJ_tendon" lengthrange="0.098054 0.254163" gainprm="0.5 1.5 144 2000 0.4327 1.595 10 0.725016 1.4 0" biasprm="0.75 1.05 144 2000 0.5 1.6 1.5 1.3 1.2 0" />
        <general name="PECM1" class="muscle" tendon="PECM1_tendon" lengthrange="0.0717493 0.209649" gainprm="0.5 1.5 444.3 2000 0.4327 1.595 10 0.725016 1.4 0" biasprm="0.75 1.05 444.3 2000 0.5 1.6 1.5 1.3 1.2 0" />
        <general name="PECM2" class="muscle" tendon="PECM2_tendon" lengthrange="0.151241 0.275724" gainprm="0.5 1.5 658.3 2000 0.4327 1.595 10 0.725016 1.4 0" biasprm="0.75 1.05 658.3 2000 0.5 1.6 1.5 1.3 1.2 0" />
        <general name="PECM3" class="muscle" tendon="PECM3_tendon" lengthrange="0.194762 0.320285" gainprm="0.5 1.5 498.1 2000 0.4327 1.595 10 0.725016 1.4 0" biasprm="0.75 1.05 498.1 2000 0.5 1.6 1.5 1.3 1.2 0" />
        <general name="LAT1" class="muscle" tendon="LAT1_tendon" lengthrange="0.235101 0.465303" gainprm="0.5 1.5 290.5 2000 0.4327 1.595 10 0.725016 1.4 0" biasprm="0.75 1.05 290.5 2000 0.5 1.6 1.5 1.3 1.2 0" />
        <general name="LAT2" class="muscle" tendon="LAT2_tendon" lengthrange="0.286369 0.506108" gainprm="0.5 1.5 317.5 2000 0.4327 1.595 10 0.725016 1.4 0" biasprm="0.75 1.05 317.5 2000 0.5 1.6 1.5 1.3 1.2 0" />
        <general name="LAT3" class="muscle" tendon="LAT3_tendon" lengthrange="0.270487 0.530864" gainprm="0.5 1.5 189 2000 0.4327 1.595 10 0.725016 1.4 0" biasprm="0.75 1.05 189 2000 0.5 1.6 1.5 1.3 1.2 0" />
        <general name="CORB" class="muscle" tendon="CORB_tendon" lengthrange="0.138521 0.221563" gainprm="0.5 1.5 208.2 2000 0.4327 1.595 10 0.725016 1.4 0" biasprm="0.75 1.05 208.2 2000 0.5 1.6 1.5 1.3 1.2 0" />
        <general name="TRIlong" class="muscle" tendon="TRIlong_tendon" lengthrange="0.208536 0.339608" gainprm="0.5 1.5 771.8 2000 0.4327 1.595 10 0.725016 1.4 0" biasprm="0.75 1.05 771.8 2000 0.5 1.6 1.5 1.3 1.2 0" />
        <general name="TRIlat" class="muscle" tendon="TRIlat_tendon" lengthrange="0.154199 0.266598" gainprm="0.5 1.5 717.5 2000 0.4327 1.595 10 0.725016 1.4 0" biasprm="0.75 1.05 717.5 2000 0.5 1.6 1.5 1.3 1.2 0" />
        <general name="TRImed" class="muscle" tendon="TRImed_tendon" lengthrange="0.146999 0.259398" gainprm="0.5 1.5 717.5 2000 0.4327 1.595 10 0.725016 1.4 0" biasprm="0.75 1.05 717.5 2000 0.5 1.6 1.5 1.3 1.2 0" />
        <general name="ANC" class="muscle" tendon="ANC_tendon" lengthrange="0.0314998 0.0585" gainprm="0.5 1.5 283.2 2000 0.4327 1.595 10 0.725016 1.4 0" biasprm="0.75 1.05 283.2 2000 0.5 1.6 1.5 1.3 1.2 0" />
        <general name="SUP" class="muscle" tendon="SUP_tendon" lengthrange="0.0444997 0.0775001" gainprm="0.5 1.5 379.6 2000 0.4327 1.595 10 0.725016 1.4 0" biasprm="0.75 1.05 379.6 2000 0.5 1.6 1.5 1.3 1.2 0" />
        <general name="BIClong" class="muscle" tendon="BIClong_tendon" lengthrange="0.33015 0.44585" gainprm="0.5 1.5 525.1 2000 0.4327 1.595 10 0.725016 1.4 0" biasprm="0.75 1.05 525.1 2000 0.5 1.6 1.5 1.3 1.2 0" />
        <general name="BICshort" class="muscle" tendon="BICshort_tendon" lengthrange="0.25835 0.39045" gainprm="0.5 1.5 316.8 2000 0.4327 1.595 10 0.725016 1.4 0" biasprm="0.75 1.05 316.8 2000 0.5 1.6 1.5 1.3 1.2 0" />
        <general name="BRA" class="muscle" tendon="BRA_tendon" lengthrange="0.0963997 0.1822" gainprm="0.5 1.5 1177.37 2000 0.4327 1.595 10 0.725016 1.4 0" biasprm="0.75 1.05 1177.37 2000 0.5 1.6 1.5 1.3 1.2 0" />
        <general name="BRD" class="muscle" tendon="BRD_tendon" lengthrange="0.2193 0.3919" gainprm="0.5 1.5 276 2000 0.4327 1.595 10 0.725016 1.4 0" biasprm="0.75 1.05 276 2000 0.5 1.6 1.5 1.3 1.2 0" />
        <general name="ECRL" class="muscle" tendon="ECRL_tendon" lengthrange="0.2845 0.3655" gainprm="0.5 1.5 337.3 2000 0.4327 1.595 10 0.725016 1.4 0" />
        <general name="ECRB" class="muscle" tendon="ECRB_tendon" lengthrange="0.25119 0.30897" gainprm="0.5 1.5 252.5 2000 0.4327 1.595 10 0.725016 1.4 0" />
        <general name="ECU" class="muscle" tendon="ECU_tendon" lengthrange="0.259524 0.321573" gainprm="0.5 1.5 192.9 2000 0.4327 1.595 10 0.725016 1.4 0" />
        <general name="FCR" class="muscle" tendon="FCR_tendon" lengthrange="0.275357 0.338071" gainprm="0.5 1.5 407.9 2000 0.4327 1.595 10 0.725016 1.4 0" />
        <general name="FCU" class="muscle" tendon="FCU_tendon" lengthrange="0.289894 0.339682" gainprm="0.5 1.5 479.8 2000 0.4327 1.595 10 0.725016 1.4 0" />
        <general name="PL" class="muscle" tendon="PL_tendon" lengthrange="0.301222 0.364867" gainprm="0.5 1.5 101 2000 0.4327 1.595 10 0.725016 1.4 0" />
        <general name="PT" class="muscle" tendon="PT_tendon" lengthrange="0.122226 0.170679" gainprm="0.5 1.5 557.2 2000 0.4327 1.595 10 0.725016 1.4 0" biasprm="0.75 1.05 557.2 2000 0.5 1.6 1.5 1.3 1.2 0" />
        <general name="PQ" class="muscle" tendon="PQ_tendon" lengthrange="0.0188857 0.0466573" gainprm="0.5 1.5 284.7 2000 0.4327 1.595 10 0.725016 1.4 0" biasprm="0.75 1.05 284.7 2000 0.5 1.6 1.5 1.3 1.2 0" />
        <general name="FDSL" class="muscle" tendon="FDSL_tendon" lengthrange="0.364252 0.415556" gainprm="0.5 1.5 75.3 2000 0.4327 1.595 10 0.725016 1.4 0" />
        <general name="FDSR" class="muscle" tendon="FDSR_tendon" lengthrange="0.364711 0.438131" gainprm="0.5 1.5 171.2 2000 0.4327 1.595 10 0.725016 1.4 0" />
        <general name="FDSM" class="muscle" tendon="FDSM_tendon" lengthrange="0.332171 0.406513" gainprm="0.5 1.5 258.8 2000 0.4327 1.595 10 0.725016 1.4 0" />
        <general name="FDSI" class="muscle" tendon="FDSI_tendon" lengthrange="0.316521 0.399564" gainprm="0.5 1.5 162.5 2000 0.4327 1.595 10 0.725016 1.4 0" />
        <general name="FDPL" class="muscle" tendon="FDPL_tendon" lengthrange="0.318985 0.393157" gainprm="0.5 1.5 236.8 2000 0.4327 1.595 10 0.725016 1.4 0" />
        <general name="FDPR" class="muscle" tendon="FDPR_tendon" lengthrange="0.331103 0.410307" gainprm="0.5 1.5 172.9 2000 0.4327 1.595 10 0.725016 1.4 0" />
        <general name="FDPM" class="muscle" tendon="FDPM_tendon" lengthrange="0.344521 0.427564" gainprm="0.5 1.5 212.4 2000 0.4327 1.595 10 0.725016 1.4 0" />
        <general name="FDPI" class="muscle" tendon="FDPI_tendon" lengthrange="0.338671 0.413013" gainprm="0.5 1.5 197.3 2000 0.4327 1.595 10 0.725016 1.4 0" />
        <general name="EDCL" class="muscle" tendon="EDCL_tendon" lengthrange="0.36748 0.432441" gainprm="0.5 1.5 39.4 2000 0.4327 1.595 10 0.725016 1.4 0" />
        <general name="EDCR" class="muscle" tendon="EDCR_tendon" lengthrange="0.396258 0.458771" gainprm="0.5 1.5 109.2 2000 0.4327 1.595 10 0.725016 1.4 0" />
        <general name="EDCM" class="muscle" tendon="EDCM_tendon" lengthrange="0.401151 0.473451" gainprm="0.5 1.5 94.4 2000 0.4327 1.595 10 0.725016 1.4 0" />
        <general name="EDCI" class="muscle" tendon="EDCI_tendon" lengthrange="0.399953 0.469856" gainprm="0.5 1.5 48.8 2000 0.4327 1.595 10 0.725016 1.4 0" />
        <general name="EDM" class="muscle" tendon="EDM_tendon" lengthrange="0.368703 0.436111" gainprm="0.5 1.5 72.4 2000 0.4327 1.595 10 0.725016 1.4 0" />
        <general name="EIP" class="muscle" tendon="EIP_tendon" lengthrange="0.239288 0.297866" gainprm="0.5 1.5 47.3 2000 0.4327 1.595 10 0.725016 1.4 0" />
        <general name="EPL" class="muscle" tendon="EPL_tendon" lengthrange="0.257352 0.311056" gainprm="0.5 1.5 88.3 2000 0.4327 1.595 10 0.725016 1.4 0" />
        <general name="EPB" class="muscle" tendon="EPB_tendon" lengthrange="0.148999 0.215995" gainprm="0.5 1.5 46 2000 0.4327 1.595 10 0.725016 1.4 0" />
        <general name="FPL" class="muscle" tendon="FPL_tendon" lengthrange="0.224394 0.279183" gainprm="0.5 1.5 201 2000 0.4327 1.595 10 0.725016 1.4 0" />
        <general name="APL" class="muscle" tendon="APL_tendon" lengthrange="0.164803 0.235409" gainprm="0.5 1.5 116.7 2000 0.4327 1.595 10 0.725016 1.4 0" />
    </actuator>
</mujoco>
